Workbook

Sheet Analysis
B1: Design Department _ KPI build
E2: Week | I2: 21
C4: The power BI reports will be sent by email each Monday
C5: Update the Relevent Green Tab with the data
C6: Check the week number formula in the last row goes to the bottom
C7: Refresh the pivot Table on the relevant Pink Tab
C8: The data should pull through into the Design KPI tab - you will need to update the week number in cell E2 to drive the formulas
B11: Weekly Closed Proposal Request - Power BI Report - saved on tab of the same name
C12: This shows the close date of the designs
C13: This feeds the productivity and Cost KPI
C14: This needs the exchange rate table updating - the current month will need to use last months data until the month end exchange rate is set.
B16: Design Days between estimate - Power BI Report - Saved on tab of the same name
C17: This shows the design proposals their close data and the completed on time %
C18: This feeds the delivery KPI
B21: The data for the quality KPI continues to be sent in by Andy Skitt
B23: Once Updated curculate the data back to Andy for his records
B25: The data originally supplied by Andy Skitt differs from the pivoted table
C26: At the bottom of the design KPI tab ive shown a comparison between these two sets of data in row 22 down
C27: These differences have been discussed with Andy and he is ok with the Data built from the sales force report

Sheet Design KPI
B1: Owner | C1: Andrew Skitt | Y1: Please note the weeks below changed values post submission
D2: Completed up to week | E2: 42 | F2: update | Y2: Looks like certain projects has a closed date that was subsequently changed - i.e. project 3531 was 05/06 then amended to 13/06
B3: Status | D3: Current Week
B4: =IF(E2<(E3),"Overdue","Current") -> Current | D4: Submission | E4: Weekly | I4: =IF(I6>$E$3,"Future",IF(I6>$E$2,"OD",IF($E$2>=I6,"Calc"))) -> Future | J4: =IF(J6>$E$3,"Future",IF(J6>$E$2,"OD",IF($E$2>=J6,"Calc"))) -> Future | K4: =IF(K6>$E$3,"Future",IF(K6>$E$2,"OD",IF($E$2>=K6,"Calc"))) -> Future | L4: =IF(L6>$E$3,"Future",IF(L6>$E$2,"OD",IF($E$2>=L6,"Calc"))) -> Future | M4: =IF(M6>$E$3,"Future",IF(M6>$E$2,"OD",IF($E$2>=M6,"Calc"))) -> Future | N4: =IF(N6>$E$3,"Future",IF(N6>$E$2,"OD",IF($E$2>=N6,"Calc"))) -> Future | O4: =IF(O6>$E$3,"Future",IF(O6>$E$2,"OD",IF($E$2>=O6,"Calc"))) -> Future | P4: =IF(P6>$E$3,"Future",IF(P6>$E$2,"OD",IF($E$2>=P6,"Calc"))) -> Future | ... BI4: =IF(BI6>$E$3,"Future",IF(BI6>$E$2,"OD",IF($E$2>=BI6,"Calc"))) -> Future | BJ4: =IF($E$2>=BJ6,"Calc",IF(BJ6>$E$2,IF(BJ12>0,"Not Calc yet","Future"))) -> Not Calc yet
AA5: 35 | AB5: 40 | AE5: 34
B6: Department: | C6: Design & R&D | G6: Commentary [in relation to current week, trend and outlook] | H6: Week | I6: 1 | J6: =I6+1 -> 2 | K6: =J6+1 -> 3 | L6: =K6+1 -> 4 | M6: =L6+1 -> 5 | N6: =M6+1 -> 6 | O6: =N6+1 -> 7 | P6: =O6+1 -> 8 | Q6: =P6+1 -> 9 | ... BI6: =BH6+1 -> 53 | BJ6: YTD
B7: Category | C7: KPI | D7: Measure | E7: UOM | F7: Sign | H7: Date (Fri) | I7: 45660 | J7: =I7+7 -> 45667 | K7: =J7+7 -> 45674 | L7: =K7+7 -> 45681 | M7: =L7+7 -> 45688 | N7: =M7+7 -> 45695 | O7: =N7+7 -> 45702 | P7: =O7+7 -> 45709 | Q7: =P7+7 -> 45716 | ... BI7: =BH7+7 -> 46024
B8: Productivity | C8: Volume Completed | D8: Number of Approx. Design requests closed weekly | E8: Count | F8: Under Breach | G8: Sales Force - https://sasinternational.lightning.force.com/lightning/r/Report/00OP3000005K1gDMAS/view | H8: Target | J8: =IF(J$6<=$E$2,35,"") -> 35 | K8: =IF(K$6<=$E$2,35,"") -> 35 | L8: =IF(L$6<=$E$2,35,"") -> 35 | M8: =IF(M$6<=$E$2,35,"") -> 35 | N8: =IF(N$6<=$E$2,35,"") -> 35 | O8: =IF(O$6<=$E$2,35,"") -> 35 | P8: =IF(P$6<=$E$2,35,"") -> 35 | Q8: =IF(Q$6<=$E$2,35,"") -> 35 | ... BJ8: =IF(BJ$6<=$E$2,35,"")
H9: Actual | I9: Blank | J9: =IF(J$6>$E$2,"",IFERROR(+GETPIVOTDATA("Count of Proposal Request No.",'Pivot Weekly close'!$A$4,"week No",J6),"no Data")) -> 33 | K9: =IF(K$6>$E$2,"",IFERROR(+GETPIVOTDATA("Count of Proposal Request No.",'Pivot Weekly close'!$A$4,"week No",K6),"no Data")) -> 30 | L9: =IF(L$6>$E$2,"",IFERROR(+GETPIVOTDATA("Count of Proposal Request No.",'Pivot Weekly close'!$A$4,"week No",L6),"no Data")) -> 34 | M9: =IF(M$6>$E$2,"",IFERROR(+GETPIVOTDATA("Count of Proposal Request No.",'Pivot Weekly close'!$A$4,"week No",M6),"no Data")) -> 32 | N9: =IF(N$6>$E$2,"",IFERROR(+GETPIVOTDATA("Count of Proposal Request No.",'Pivot Weekly close'!$A$4,"week No",N6),"no Data")) -> 35 | O9: =IF(O$6>$E$2,"",IFERROR(+GETPIVOTDATA("Count of Proposal Request No.",'Pivot Weekly close'!$A$4,"week No",O6),"no Data")) -> 35 | P9: =IF(P$6>$E$2,"",IFERROR(+GETPIVOTDATA("Count of Proposal Request No.",'Pivot Weekly close'!$A$4,"week No",P6),"no Data")) -> 31 | Q9: =IF(Q$6>$E$2,"",IFERROR(+GETPIVOTDATA("Count of Proposal Request No.",'Pivot Weekly close'!$A$4,"week No",Q6),"no Data")) -> 33 | ... BJ9: =IF(BJ$6>$E$2,"",IFERROR(+GETPIVOTDATA("Count of Proposal Request No.",'Pivot Weekly close'!$A$4,"week No",BJ6),"no Data"))
H10: Variance | I10: =IF(I$6>$E$2,"",IF(I9="Blank","Blank",IF(I9="TBC","TBC",IF((I9-I8)>=0,"G",IF((I9-(I8*0.95))>=0,"A","R"))))) -> Blank | J10: =IF(J4="OD","OD",IF(J$6>$E$2,"",IF(J9="Blank","Blank",IF(J9="TBC","TBC",IF(J9="","OD",IF((J9-J8)>=0,"G",IF((J9-(J8*0.95))>=0,"A","R"))))))) -> R | K10: =IF(K4="OD","OD",IF(K$6>$E$2,"",IF(K9="Blank","Blank",IF(K9="TBC","TBC",IF(K9="","OD",IF((K9-K8)>=0,"G",IF((K9-(K8*0.95))>=0,"A","R"))))))) -> R | L10: =IF(L4="OD","OD",IF(L$6>$E$2,"",IF(L9="Blank","Blank",IF(L9="TBC","TBC",IF(L9="","OD",IF((L9-L8)>=0,"G",IF((L9-(L8*0.95))>=0,"A","R"))))))) -> A | M10: =IF(M4="OD","OD",IF(M$6>$E$2,"",IF(M9="Blank","Blank",IF(M9="TBC","TBC",IF(M9="","OD",IF((M9-M8)>=0,"G",IF((M9-(M8*0.95))>=0,"A","R"))))))) -> R | N10: =IF(N4="OD","OD",IF(N$6>$E$2,"",IF(N9="Blank","Blank",IF(N9="TBC","TBC",IF(N9="","OD",IF((N9-N8)>=0,"G",IF((N9-(N8*0.95))>=0,"A","R"))))))) -> G | O10: =IF(O4="OD","OD",IF(O$6>$E$2,"",IF(O9="Blank","Blank",IF(O9="TBC","TBC",IF(O9="","OD",IF((O9-O8)>=0,"G",IF((O9-(O8*0.95))>=0,"A","R"))))))) -> G | P10: =IF(P4="OD","OD",IF(P$6>$E$2,"",IF(P9="Blank","Blank",IF(P9="TBC","TBC",IF(P9="","OD",IF((P9-P8)>=0,"G",IF((P9-(P8*0.95))>=0,"A","R"))))))) -> R | Q10: =IF(Q4="OD","OD",IF(Q$6>$E$2,"",IF(Q9="Blank","Blank",IF(Q9="TBC","TBC",IF(Q9="","OD",IF((Q9-Q8)>=0,"G",IF((Q9-(Q8*0.95))>=0,"A","R"))))))) -> R | ... AB10: =IF(AB4="OD","OD",IF(AB$6>$E$2,"",IF(AB9="Blank","Blank",IF(AB9="TBC","TBC",IF(AB9="","OD",IF((AB9-AB8)>=0,"G",IF((AB9-(AB8*0.95))>=0,"A","R"))))))) -> G | AC10: =IF(AC4="OD","OD",IF(AC$6>$E$2,"",IF(AC9="Blank","Blank",IF(AC9="No Data","No Data",IF(AC9="TBC","TBC",IF(AC9="","OD",IF((AC9-AC8)>=0,"G",IF((AC9-(AC8*0.95))>=0,"A","R")))))))) -> G | AD10: =IF(AD4="OD","OD",IF(AD$6>$E$2,"",IF(AD9="Blank","Blank",IF(AD9="No Data","No Data",IF(AD9="TBC","TBC",IF(AD9="","OD",IF((AD9-AD8)>=0,"G",IF((AD9-(AD8*0.95))>=0,"A","R")))))))) -> R | AE10: =IF(AE4="OD","OD",IF(AE$6>$E$2,"",IF(AE9="Blank","Blank",IF(AE9="No Data","No Data",IF(AE9="TBC","TBC",IF(AE9="","OD",IF((AE9-AE8)>=0,"G",IF((AE9-(AE8*0.95))>=0,"A","R")))))))) -> R | AF10: =IF(AF4="OD","OD",IF(AF$6>$E$2,"",IF(AF9="Blank","Blank",IF(AF9="No Data","No Data",IF(AF9="TBC","TBC",IF(AF9="","OD",IF((AF9-AF8)>=0,"G",IF((AF9-(AF8*0.95))>=0,"A","R")))))))) -> R | AG10: =IF(AG4="OD","OD",IF(AG$6>$E$2,"",IF(AG9="Blank","Blank",IF(AG9="No Data","No Data",IF(AG9="TBC","TBC",IF(AG9="","OD",IF((AG9-AG8)>=0,"G",IF((AG9-(AG8*0.95))>=0,"A","R")))))))) -> R | AH10: =IF(AH4="OD","OD",IF(AH$6>$E$2,"",IF(AH9="Blank","Blank",IF(AH9="No Data","No Data",IF(AH9="TBC","TBC",IF(AH9="","OD",IF((AH9-AH8)>=0,"G",IF((AH9-(AH8*0.95))>=0,"A","R")))))))) -> G | AI10: =IF(AI4="OD","OD",IF(AI$6>$E$2,"",IF(AI9="Blank","Blank",IF(AI9="No Data","No Data",IF(AI9="TBC","TBC",IF(AI9="","OD",IF((AI9-AI8)>=0,"G",IF((AI9-(AI8*0.95))>=0,"A","R")))))))) -> A | AJ10: =IF(AJ4="OD","OD",IF(AJ$6>$E$2,"",IF(AJ9="Blank","Blank",IF(AJ9="No Data","No Data",IF(AJ9="TBC","TBC",IF(AJ9="","OD",IF((AJ9-AJ8)>=0,"G",IF((AJ9-(AJ8*0.95))>=0,"A","R")))))))) -> R | ... BJ10: =IF(BJ4="OD","OD",IF(BJ$6>$E$2,"",IF(BJ9="Blank","Blank",IF(BJ9="No Data","No Data",IF(BJ9="TBC","TBC",IF(BJ9="","OD",IF((BJ9-BJ8)>=0,"G",IF((BJ9-(BJ8*0.95))>=0,"A","R"))))))))
B11: Delivery | C11: OTIF | D11: % of Designs closed that were completed by the Internal Date | E11: Percentage | F11: Under Breach | G11: Sales Force - https://sasinternational.lightning.force.com/lightning/r/Report/00OP3000003GHJJMA4/view | H11: Target | J11: =IF(J$6<=$E$2,100,"") -> 100 | K11: =IF(K$6<=$E$2,100,"") -> 100 | L11: =IF(L$6<=$E$2,100,"") -> 100 | M11: =IF(M$6<=$E$2,100,"") -> 100 | N11: =IF(N$6<=$E$2,100,"") -> 100 | O11: =IF(O$6<=$E$2,100,"") -> 100 | P11: =IF(P$6<=$E$2,100,"") -> 100 | Q11: =IF(Q$6<=$E$2,100,"") -> 100 | ... BJ11: =IF(BJ$6<=$E$2,100,"")
H12: Actual | I12: Blank | J12: =IF(J$6>$E$2,"",IFERROR(+GETPIVOTDATA("Average of On Time?",'Pivot Of Design Days'!$A$6,"week No",J6),"no Data")) -> 87.878788 | K12: =IF(K$6>$E$2,"",IFERROR(+GETPIVOTDATA("Average of On Time?",'Pivot Of Design Days'!$A$6,"week No",K6),"no Data")) -> 100 | L12: =IF(L$6>$E$2,"",IFERROR(+GETPIVOTDATA("Average of On Time?",'Pivot Of Design Days'!$A$6,"week No",L6),"no Data")) -> 88.235294 | M12: =IF(M$6>$E$2,"",IFERROR(+GETPIVOTDATA("Average of On Time?",'Pivot Of Design Days'!$A$6,"week No",M6),"no Data")) -> 96.875 | N12: =IF(N$6>$E$2,"",IFERROR(+GETPIVOTDATA("Average of On Time?",'Pivot Of Design Days'!$A$6,"week No",N6),"no Data")) -> 88.571429 | O12: =IF(O$6>$E$2,"",IFERROR(+GETPIVOTDATA("Average of On Time?",'Pivot Of Design Days'!$A$6,"week No",O6),"no Data")) -> 88.571429 | P12: =IF(P$6>$E$2,"",IFERROR(+GETPIVOTDATA("Average of On Time?",'Pivot Of Design Days'!$A$6,"week No",P6),"no Data")) -> 93.548387 | Q12: =IF(Q$6>$E$2,"",IFERROR(+GETPIVOTDATA("Average of On Time?",'Pivot Of Design Days'!$A$6,"week No",Q6),"no Data")) -> 84.848485 | ... BJ12: =IF(BJ$6>$E$2,"",IFERROR(+GETPIVOTDATA("Average of On Time?",'Pivot Of Design Days'!$A$6,"week No",BJ6),"no Data"))
H13: Variance | I13: =IF(I$6>$E$2,"",IF(I9="Blank","Blank",IF(I9="TBC","TBC",IF((I12-I11)>=0,"G",IF((I12-(I11*0.95))>=0,"A","R"))))) -> Blank | J13: =IF(J4="OD","OD",IF(J$6>$E$2,"",IF(J12="Blank","Blank",IF(J12="TBC","TBC",IF(J4="OD","OD",IF(J12="","OD",IF((J12-J11)>=0,"G",IF((J12-(J11*0.95))>=0,"A","R")))))))) -> R | K13: =IF(K4="OD","OD",IF(K$6>$E$2,"",IF(K12="Blank","Blank",IF(K12="TBC","TBC",IF(K4="OD","OD",IF(K12="","OD",IF((K12-K11)>=0,"G",IF((K12-(K11*0.95))>=0,"A","R")))))))) -> G | L13: =IF(L4="OD","OD",IF(L$6>$E$2,"",IF(L12="Blank","Blank",IF(L12="TBC","TBC",IF(L4="OD","OD",IF(L12="","OD",IF((L12-L11)>=0,"G",IF((L12-(L11*0.95))>=0,"A","R")))))))) -> R | M13: =IF(M4="OD","OD",IF(M$6>$E$2,"",IF(M12="Blank","Blank",IF(M12="TBC","TBC",IF(M4="OD","OD",IF(M12="","OD",IF((M12-M11)>=0,"G",IF((M12-(M11*0.95))>=0,"A","R")))))))) -> A | N13: =IF(N4="OD","OD",IF(N$6>$E$2,"",IF(N12="Blank","Blank",IF(N12="TBC","TBC",IF(N4="OD","OD",IF(N12="","OD",IF((N12-N11)>=0,"G",IF((N12-(N11*0.95))>=0,"A","R")))))))) -> R | O13: =IF(O4="OD","OD",IF(O$6>$E$2,"",IF(O12="Blank","Blank",IF(O12="TBC","TBC",IF(O4="OD","OD",IF(O12="","OD",IF((O12-O11)>=0,"G",IF((O12-(O11*0.95))>=0,"A","R")))))))) -> R | P13: =IF(P4="OD","OD",IF(P$6>$E$2,"",IF(P12="Blank","Blank",IF(P12="TBC","TBC",IF(P4="OD","OD",IF(P12="","OD",IF((P12-P11)>=0,"G",IF((P12-(P11*0.95))>=0,"A","R")))))))) -> R | Q13: =IF(Q4="OD","OD",IF(Q$6>$E$2,"",IF(Q12="Blank","Blank",IF(Q12="TBC","TBC",IF(Q4="OD","OD",IF(Q12="","OD",IF((Q12-Q11)>=0,"G",IF((Q12-(Q11*0.95))>=0,"A","R")))))))) -> R | ... AB13: =IF(AB4="OD","OD",IF(AB$6>$E$2,"",IF(AB12="Blank","Blank",IF(AB12="TBC","TBC",IF(AB4="OD","OD",IF(AB12="","OD",IF((AB12-AB11)>=0,"G",IF((AB12-(AB11*0.95))>=0,"A","R")))))))) -> R | AC13: =IF(AC4="OD","OD",IF(AC$6>$E$2,"",IF(AC12="Blank","Blank",IF(AC12="TBC","TBC",IF(AC4="OD","OD",IF(AC12="No Data","No Data",IF(AC12="","OD",IF((AC12-AC11)>=0,"G",IF((AC12-(AC11*0.95))>=0,"A","R"))))))))) -> R | AD13: =IF(AD4="OD","OD",IF(AD$6>$E$2,"",IF(AD12="Blank","Blank",IF(AD12="TBC","TBC",IF(AD4="OD","OD",IF(AD12="No Data","No Data",IF(AD12="","OD",IF((AD12-AD11)>=0,"G",IF((AD12-(AD11*0.95))>=0,"A","R"))))))))) -> R | AE13: =IF(AE4="OD","OD",IF(AE$6>$E$2,"",IF(AE12="Blank","Blank",IF(AE12="TBC","TBC",IF(AE4="OD","OD",IF(AE12="No Data","No Data",IF(AE12="","OD",IF((AE12-AE11)>=0,"G",IF((AE12-(AE11*0.95))>=0,"A","R"))))))))) -> R | AF13: =IF(AF4="OD","OD",IF(AF$6>$E$2,"",IF(AF12="Blank","Blank",IF(AF12="TBC","TBC",IF(AF4="OD","OD",IF(AF12="No Data","No Data",IF(AF12="","OD",IF((AF12-AF11)>=0,"G",IF((AF12-(AF11*0.95))>=0,"A","R"))))))))) -> R | AG13: =IF(AG4="OD","OD",IF(AG$6>$E$2,"",IF(AG12="Blank","Blank",IF(AG12="TBC","TBC",IF(AG4="OD","OD",IF(AG12="No Data","No Data",IF(AG12="","OD",IF((AG12-AG11)>=0,"G",IF((AG12-(AG11*0.95))>=0,"A","R"))))))))) -> R | AH13: =IF(AH4="OD","OD",IF(AH$6>$E$2,"",IF(AH12="Blank","Blank",IF(AH12="TBC","TBC",IF(AH4="OD","OD",IF(AH12="No Data","No Data",IF(AH12="","OD",IF((AH12-AH11)>=0,"G",IF((AH12-(AH11*0.95))>=0,"A","R"))))))))) -> R | AI13: =IF(AI4="OD","OD",IF(AI$6>$E$2,"",IF(AI12="Blank","Blank",IF(AI12="TBC","TBC",IF(AI4="OD","OD",IF(AI12="No Data","No Data",IF(AI12="","OD",IF((AI12-AI11)>=0,"G",IF((AI12-(AI11*0.95))>=0,"A","R"))))))))) -> R | AJ13: =IF(AJ4="OD","OD",IF(AJ$6>$E$2,"",IF(AJ12="Blank","Blank",IF(AJ12="TBC","TBC",IF(AJ4="OD","OD",IF(AJ12="No Data","No Data",IF(AJ12="","OD",IF((AJ12-AJ11)>=0,"G",IF((AJ12-(AJ11*0.95))>=0,"A","R"))))))))) -> R | ... BJ13: =IF(BJ4="OD","OD",IF(BJ$6>$E$2,"",IF(BJ12="Blank","Blank",IF(BJ12="TBC","TBC",IF(BJ4="OD","OD",IF(BJ12="No Data","No Data",IF(BJ12="","OD",IF((BJ12-BJ11)>=0,"G",IF((BJ12-(BJ11*0.95))>=0,"A","R")))))))))
B14: Quality | C14: Design Rejections | D14: Number of rejected designs (internal to Design team) | E14: Count | F14: Over Breach | G14: Not in a system | H14: Target | J14: 0 | K14: 0 | L14: 0 | M14: 0 | N14: 0 | O14: 0 | P14: 0 | Q14: 0 | R14: 0 | S14: 0 | T14: 0 | U14: 0 | V14: 0 | W14: 0 | X14: 0 | Y14: 0 | Z14: 0 | AA14: 0 | AB14: 0 | AC14: =IF(AC$6<=$E$2,0,"") -> 0 | AD14: =IF(AD$6<=$E$2,0,"") -> 0 | AE14: =IF(AE$6<=$E$2,0,"") -> 0 | AF14: =IF(AF$6<=$E$2,0,"") -> 0 | AG14: =IF(AG$6<=$E$2,0,"") -> 0 | AH14: =IF(AH$6<=$E$2,0,"") -> 0 | AI14: =IF(AI$6<=$E$2,0,"") -> 0 | AJ14: =IF(AJ$6<=$E$2,0,"") -> 0 | ... BJ14: =IF(BJ$6<=$E$2,0,"")
H15: Actual | I15: Blank | J15: 0 | K15: 0 | L15: 0 | M15: 0 | N15: 0 | O15: 0 | P15: 0 | Q15: 0 | R15: 0 | S15: 0 | T15: 0 | U15: 0 | V15: 0 | W15: 0 | X15: 0 | Y15: 0 | Z15: 0 | AA15: 0 | AB15: 0 | AC15: 2 | AD15: 1 | AE15: 0 | AF15: 3 | AG15: 2 | AH15: 4 | AI15: 4 | AJ15: 2 | AK15: 4 | AL15: 1 | AM15: 3 | AN15: 0 | AO15: 2 | AP15: 3 | AQ15: 0 | AR15: 4 | AS15: 2 | AT15: 3 | AU15: OD | AV15: OD | AW15: OD | AX15: =IF(AX$6>$E$2,"",IFERROR(+GETPIVOTDATA("Count of Proposal Request No.",'Pivot Weekly close'!$A$4,"week No",AX12),"no Data")) -> no Data | AY15: =IF(AY$6>$E$2,"",IFERROR(+GETPIVOTDATA("Count of Proposal Request No.",'Pivot Weekly close'!$A$4,"week No",AY12),"no Data")) | AZ15: =IF(AZ$6>$E$2,"",IFERROR(+GETPIVOTDATA("Count of Proposal Request No.",'Pivot Weekly close'!$A$4,"week No",AZ12),"no Data")) | BA15: =IF(BA$6>$E$2,"",IFERROR(+GETPIVOTDATA("Count of Proposal Request No.",'Pivot Weekly close'!$A$4,"week No",BA12),"no Data")) | BB15: =IF(BB$6>$E$2,"",IFERROR(+GETPIVOTDATA("Count of Proposal Request No.",'Pivot Weekly close'!$A$4,"week No",BB12),"no Data")) | BC15: =IF(BC$6>$E$2,"",IFERROR(+GETPIVOTDATA("Count of Proposal Request No.",'Pivot Weekly close'!$A$4,"week No",BC12),"no Data")) | BD15: =IF(BD$6>$E$2,"",IFERROR(+GETPIVOTDATA("Count of Proposal Request No.",'Pivot Weekly close'!$A$4,"week No",BD12),"no Data")) | BE15: =IF(BE$6>$E$2,"",IFERROR(+GETPIVOTDATA("Count of Proposal Request No.",'Pivot Weekly close'!$A$4,"week No",BE12),"no Data")) | ... BJ15: =IF(BJ$6>$E$2,"",IFERROR(+GETPIVOTDATA("Count of Proposal Request No.",'Pivot Weekly close'!$A$4,"week No",BJ12),"no Data"))
H16: Variance | I16: =IF(I$6>$E$2,"",IF(I15="Blank","Blank",IF(I15="TBC","TBC",IF((I15-I14)<=0,"G",IF((I15-(I14*0.95))<=0,"A","R"))))) -> Blank | J16: =IF(J4="OD","OD",IF(J$6>$E$2,"",IF(J15="Blank","Blank",IF(J15="TBC","TBC",IF(J4="OD","OD",IF(J15="","OD",IF((J15-J14)<=0,"G",IF((J15-(J14*0.95))<=0,"A","R")))))))) -> G | K16: =IF(K4="OD","OD",IF(K$6>$E$2,"",IF(K15="Blank","Blank",IF(K15="TBC","TBC",IF(K4="OD","OD",IF(K15="","OD",IF((K15-K14)<=0,"G",IF((K15-(K14*0.95))<=0,"A","R")))))))) -> G | L16: =IF(L4="OD","OD",IF(L$6>$E$2,"",IF(L15="Blank","Blank",IF(L15="TBC","TBC",IF(L4="OD","OD",IF(L15="","OD",IF((L15-L14)<=0,"G",IF((L15-(L14*0.95))<=0,"A","R")))))))) -> G | M16: =IF(M4="OD","OD",IF(M$6>$E$2,"",IF(M15="Blank","Blank",IF(M15="TBC","TBC",IF(M4="OD","OD",IF(M15="","OD",IF((M15-M14)<=0,"G",IF((M15-(M14*0.95))<=0,"A","R")))))))) -> G | N16: =IF(N4="OD","OD",IF(N$6>$E$2,"",IF(N15="Blank","Blank",IF(N15="TBC","TBC",IF(N4="OD","OD",IF(N15="","OD",IF((N15-N14)<=0,"G",IF((N15-(N14*0.95))<=0,"A","R")))))))) -> G | O16: =IF(O4="OD","OD",IF(O$6>$E$2,"",IF(O15="Blank","Blank",IF(O15="TBC","TBC",IF(O4="OD","OD",IF(O15="","OD",IF((O15-O14)<=0,"G",IF((O15-(O14*0.95))<=0,"A","R")))))))) -> G | P16: =IF(P4="OD","OD",IF(P$6>$E$2,"",IF(P15="Blank","Blank",IF(P15="TBC","TBC",IF(P4="OD","OD",IF(P15="","OD",IF((P15-P14)<=0,"G",IF((P15-(P14*0.95))<=0,"A","R")))))))) -> G | Q16: =IF(Q4="OD","OD",IF(Q$6>$E$2,"",IF(Q15="Blank","Blank",IF(Q15="TBC","TBC",IF(Q4="OD","OD",IF(Q15="","OD",IF((Q15-Q14)<=0,"G",IF((Q15-(Q14*0.95))<=0,"A","R")))))))) -> G | ... AB16: =IF(AB4="OD","OD",IF(AB$6>$E$2,"",IF(AB15="Blank","Blank",IF(AB15="TBC","TBC",IF(AB4="OD","OD",IF(AB15="","OD",IF((AB15-AB14)<=0,"G",IF((AB15-(AB14*0.95))<=0,"A","R")))))))) -> G | AC16: =IF(AC4="OD","OD",IF(AC$6>$E$2,"",IF(AC15="Blank","Blank",IF(AC15="TBC","TBC",IF(AC15="No Data","No Data",IF(AC4="OD","OD",IF(AC15="","OD",IF((AC15-AC14)<=0,"G",IF((AC15-(AC14*0.95))<=0,"A","R"))))))))) -> R | AD16: =IF(AD4="OD","OD",IF(AD$6>$E$2,"",IF(AD15="Blank","Blank",IF(AD15="TBC","TBC",IF(AD15="No Data","No Data",IF(AD4="OD","OD",IF(AD15="","OD",IF((AD15-AD14)<=0,"G",IF((AD15-(AD14*0.95))<=0,"A","R"))))))))) -> R | AE16: =IF(AE4="OD","OD",IF(AE$6>$E$2,"",IF(AE15="Blank","Blank",IF(AE15="TBC","TBC",IF(AE15="No Data","No Data",IF(AE4="OD","OD",IF(AE15="","OD",IF((AE15-AE14)<=0,"G",IF((AE15-(AE14*0.95))<=0,"A","R"))))))))) -> G | AF16: =IF(AF4="OD","OD",IF(AF$6>$E$2,"",IF(AF15="Blank","Blank",IF(AF15="TBC","TBC",IF(AF15="No Data","No Data",IF(AF4="OD","OD",IF(AF15="","OD",IF((AF15-AF14)<=0,"G",IF((AF15-(AF14*0.95))<=0,"A","R"))))))))) -> R | AG16: =IF(AG4="OD","OD",IF(AG$6>$E$2,"",IF(AG15="Blank","Blank",IF(AG15="TBC","TBC",IF(AG15="No Data","No Data",IF(AG4="OD","OD",IF(AG15="","OD",IF((AG15-AG14)<=0,"G",IF((AG15-(AG14*0.95))<=0,"A","R"))))))))) -> R | AH16: =IF(AH4="OD","OD",IF(AH$6>$E$2,"",IF(AH15="Blank","Blank",IF(AH15="TBC","TBC",IF(AH15="No Data","No Data",IF(AH4="OD","OD",IF(AH15="","OD",IF((AH15-AH14)<=0,"G",IF((AH15-(AH14*0.95))<=0,"A","R"))))))))) -> R | AI16: =IF(AI4="OD","OD",IF(AI$6>$E$2,"",IF(AI15="Blank","Blank",IF(AI15="TBC","TBC",IF(AI15="No Data","No Data",IF(AI4="OD","OD",IF(AI15="","OD",IF((AI15-AI14)<=0,"G",IF((AI15-(AI14*0.95))<=0,"A","R"))))))))) -> R | AJ16: =IF(AJ4="OD","OD",IF(AJ$6>$E$2,"",IF(AJ15="Blank","Blank",IF(AJ15="TBC","TBC",IF(AJ15="No Data","No Data",IF(AJ4="OD","OD",IF(AJ15="","OD",IF((AJ15-AJ14)<=0,"G",IF((AJ15-(AJ14*0.95))<=0,"A","R"))))))))) -> R | ... AS16: =IF(AS4="OD","OD",IF(AS$6>$E$2,"",IF(AS15="Blank","Blank",IF(AS15="TBC","TBC",IF(AS15="No Data","No Data",IF(AS4="OD","OD",IF(AS15="","OD",IF((AS15-AS14)<=0,"G",IF((AS15-(AS14*0.95))<=0,"A","R"))))))))) -> R | AT16: =IF(AT15="OD","OD",IF(AT$6>$E$2,"",IF(AT15="Blank","Blank",IF(AT15="TBC","TBC",IF(AT15="No Data","No Data",IF(AT4="OD","OD",IF(AT15="","OD",IF((AT15-AT14)<=0,"G",IF((AT15-(AT14*0.95))<=0,"A","R"))))))))) -> R | AU16: =IF(AU15="OD","OD",IF(AU$6>$E$2,"",IF(AU15="Blank","Blank",IF(AU15="TBC","TBC",IF(AU15="No Data","No Data",IF(AU4="OD","OD",IF(AU15="","OD",IF((AU15-AU14)<=0,"G",IF((AU15-(AU14*0.95))<=0,"A","R"))))))))) -> OD | AV16: =IF(AV15="OD","OD",IF(AV$6>$E$2,"",IF(AV15="Blank","Blank",IF(AV15="TBC","TBC",IF(AV15="No Data","No Data",IF(AV4="OD","OD",IF(AV15="","OD",IF((AV15-AV14)<=0,"G",IF((AV15-(AV14*0.95))<=0,"A","R"))))))))) -> OD | AW16: =IF(AW15="OD","OD",IF(AW$6>$E$2,"",IF(AW15="Blank","Blank",IF(AW15="TBC","TBC",IF(AW15="No Data","No Data",IF(AW4="OD","OD",IF(AW15="","OD",IF((AW15-AW14)<=0,"G",IF((AW15-(AW14*0.95))<=0,"A","R"))))))))) -> OD | AX16: =IF(AX4="OD","OD",IF(AX$6>$E$2,"",IF(AX15="Blank","Blank",IF(AX15="TBC","TBC",IF(AX15="No Data","No Data",IF(AX4="OD","OD",IF(AX15="","OD",IF((AX15-AX14)<=0,"G",IF((AX15-(AX14*0.95))<=0,"A","R"))))))))) -> No Data | AY16: =IF(AY4="OD","OD",IF(AY$6>$E$2,"",IF(AY15="Blank","Blank",IF(AY15="TBC","TBC",IF(AY15="No Data","No Data",IF(AY4="OD","OD",IF(AY15="","OD",IF((AY15-AY14)<=0,"G",IF((AY15-(AY14*0.95))<=0,"A","R"))))))))) | AZ16: =IF(AZ4="OD","OD",IF(AZ$6>$E$2,"",IF(AZ15="Blank","Blank",IF(AZ15="TBC","TBC",IF(AZ15="No Data","No Data",IF(AZ4="OD","OD",IF(AZ15="","OD",IF((AZ15-AZ14)<=0,"G",IF((AZ15-(AZ14*0.95))<=0,"A","R"))))))))) | BA16: =IF(BA4="OD","OD",IF(BA$6>$E$2,"",IF(BA15="Blank","Blank",IF(BA15="TBC","TBC",IF(BA15="No Data","No Data",IF(BA4="OD","OD",IF(BA15="","OD",IF((BA15-BA14)<=0,"G",IF((BA15-(BA14*0.95))<=0,"A","R"))))))))) | BB16: =IF(BB4="OD","OD",IF(BB$6>$E$2,"",IF(BB15="Blank","Blank",IF(BB15="TBC","TBC",IF(BB15="No Data","No Data",IF(BB4="OD","OD",IF(BB15="","OD",IF((BB15-BB14)<=0,"G",IF((BB15-(BB14*0.95))<=0,"A","R"))))))))) | BC16: =IF(BC4="OD","OD",IF(BC$6>$E$2,"",IF(BC15="Blank","Blank",IF(BC15="TBC","TBC",IF(BC15="No Data","No Data",IF(BC4="OD","OD",IF(BC15="","OD",IF((BC15-BC14)<=0,"G",IF((BC15-(BC14*0.95))<=0,"A","R"))))))))) | BD16: =IF(BD4="OD","OD",IF(BD$6>$E$2,"",IF(BD15="Blank","Blank",IF(BD15="TBC","TBC",IF(BD15="No Data","No Data",IF(BD4="OD","OD",IF(BD15="","OD",IF((BD15-BD14)<=0,"G",IF((BD15-(BD14*0.95))<=0,"A","R"))))))))) | BE16: =IF(BE4="OD","OD",IF(BE$6>$E$2,"",IF(BE15="Blank","Blank",IF(BE15="TBC","TBC",IF(BE15="No Data","No Data",IF(BE4="OD","OD",IF(BE15="","OD",IF((BE15-BE14)<=0,"G",IF((BE15-(BE14*0.95))<=0,"A","R"))))))))) | ... BJ16: =IF(BJ4="OD","OD",IF(BJ$6>$E$2,"",IF(BJ15="Blank","Blank",IF(BJ15="TBC","TBC",IF(BJ15="No Data","No Data",IF(BJ4="OD","OD",IF(BJ15="","OD",IF((BJ15-BJ14)<=0,"G",IF((BJ15-(BJ14*0.95))<=0,"A","R")))))))))
B17: Cost | C17: Opportunity Value per proposal | D17: Expected Opportunity value / No of proposals collated | E17: £'s | F17: Under Breach | G17: Never reported on before | H17: Target | J17: =IF(J$6<=$E$2,171000,"") -> 171000 | K17: =IF(K$6<=$E$2,171000,"") -> 171000 | L17: =IF(L$6<=$E$2,171000,"") -> 171000 | M17: =IF(M$6<=$E$2,171000,"") -> 171000 | N17: =IF(N$6<=$E$2,171000,"") -> 171000 | O17: =IF(O$6<=$E$2,171000,"") -> 171000 | P17: =IF(P$6<=$E$2,171000,"") -> 171000 | Q17: =IF(Q$6<=$E$2,171000,"") -> 171000 | ... BI17: =IF(BI$6<=$E$2,171000,"") | BJ17: =IF(BJ$6<=$E$2,205000,"")
H18: Actual | I18: Blank | J18: =IF(J$6>$E$2,"",IFERROR(+GETPIVOTDATA("Sum of Estimate £",'Pivot Weekly close'!$A$4,"week No",J6)/GETPIVOTDATA("Count of Proposal Request No.",'Pivot Weekly close'!$A$4,"week No",J6),"no Data")) -> 131542.71 | K18: =IF(K$6>$E$2,"",IFERROR(+GETPIVOTDATA("Sum of Estimate £",'Pivot Weekly close'!$A$4,"week No",K6)/GETPIVOTDATA("Count of Proposal Request No.",'Pivot Weekly close'!$A$4,"week No",K6),"no Data")) -> 95420.927 | L18: =IF(L$6>$E$2,"",IFERROR(+GETPIVOTDATA("Sum of Estimate £",'Pivot Weekly close'!$A$4,"week No",L6)/GETPIVOTDATA("Count of Proposal Request No.",'Pivot Weekly close'!$A$4,"week No",L6),"no Data")) -> 252447.13 | M18: =IF(M$6>$E$2,"",IFERROR(+GETPIVOTDATA("Sum of Estimate £",'Pivot Weekly close'!$A$4,"week No",M6)/GETPIVOTDATA("Count of Proposal Request No.",'Pivot Weekly close'!$A$4,"week No",M6),"no Data")) -> 143566.15 | N18: =IF(N$6>$E$2,"",IFERROR(+GETPIVOTDATA("Sum of Estimate £",'Pivot Weekly close'!$A$4,"week No",N6)/GETPIVOTDATA("Count of Proposal Request No.",'Pivot Weekly close'!$A$4,"week No",N6),"no Data")) -> 135645.71 | O18: =IF(O$6>$E$2,"",IFERROR(+GETPIVOTDATA("Sum of Estimate £",'Pivot Weekly close'!$A$4,"week No",O6)/GETPIVOTDATA("Count of Proposal Request No.",'Pivot Weekly close'!$A$4,"week No",O6),"no Data")) -> 77657.027 | P18: =IF(P$6>$E$2,"",IFERROR(+GETPIVOTDATA("Sum of Estimate £",'Pivot Weekly close'!$A$4,"week No",P6)/GETPIVOTDATA("Count of Proposal Request No.",'Pivot Weekly close'!$A$4,"week No",P6),"no Data")) -> 211434.48 | Q18: =IF(Q$6>$E$2,"",IFERROR(+GETPIVOTDATA("Sum of Estimate £",'Pivot Weekly close'!$A$4,"week No",Q6)/GETPIVOTDATA("Count of Proposal Request No.",'Pivot Weekly close'!$A$4,"week No",Q6),"no Data")) -> 161039.43 | ... BI18: =IF(BI$6>$E$2,"",IFERROR(+GETPIVOTDATA("Sum of Estimate £",'Pivot Weekly close'!$A$4,"week No",BI6)/GETPIVOTDATA("Count of Proposal Request No.",'Pivot Weekly close'!$A$4,"week No",BI6),"no Data")) | BJ18: =IF(BJ$6>$E$2,"",IFERROR(+GETPIVOTDATA("Count of Proposal Request No.",'Pivot Weekly close'!$A$4,"week No",BJ15),"no Data"))
H19: Variance | I19: =IF(I$6>$E$2,"",IF(I18="Blank","Blank",IF(I18="TBC","TBC",IF((I18-I17)>=0,"G",IF((I18-(I17*0.95))>=0,"A","R"))))) -> Blank | J19: =IF(J4="OD","OD",IF(J$6>$E$2,"",IF(J18="Blank","Blank",IF(J18="TBC","TBC",IF(J18="Missed","Missed",IF(J18="","OD",IF((J18-J17)>=0,"G",IF((J18-(J17*0.95))>=0,"A","R")))))))) -> R | K19: =IF(K4="OD","OD",IF(K$6>$E$2,"",IF(K18="Blank","Blank",IF(K18="TBC","TBC",IF(K18="Missed","Missed",IF(K18="","OD",IF((K18-K17)>=0,"G",IF((K18-(K17*0.95))>=0,"A","R")))))))) -> R | L19: =IF(L4="OD","OD",IF(L$6>$E$2,"",IF(L18="Blank","Blank",IF(L18="TBC","TBC",IF(L18="Missed","Missed",IF(L18="","OD",IF((L18-L17)>=0,"G",IF((L18-(L17*0.95))>=0,"A","R")))))))) -> G | M19: =IF(M4="OD","OD",IF(M$6>$E$2,"",IF(M18="Blank","Blank",IF(M18="TBC","TBC",IF(M18="Missed","Missed",IF(M18="","OD",IF((M18-M17)>=0,"G",IF((M18-(M17*0.95))>=0,"A","R")))))))) -> R | N19: =IF(N4="OD","OD",IF(N$6>$E$2,"",IF(N18="Blank","Blank",IF(N18="TBC","TBC",IF(N18="Missed","Missed",IF(N18="","OD",IF((N18-N17)>=0,"G",IF((N18-(N17*0.95))>=0,"A","R")))))))) -> R | O19: =IF(O4="OD","OD",IF(O$6>$E$2,"",IF(O18="Blank","Blank",IF(O18="TBC","TBC",IF(O18="Missed","Missed",IF(O18="","OD",IF((O18-O17)>=0,"G",IF((O18-(O17*0.95))>=0,"A","R")))))))) -> R | P19: =IF(P4="OD","OD",IF(P$6>$E$2,"",IF(P18="Blank","Blank",IF(P18="TBC","TBC",IF(P18="Missed","Missed",IF(P18="","OD",IF((P18-P17)>=0,"G",IF((P18-(P17*0.95))>=0,"A","R")))))))) -> G | Q19: =IF(Q4="OD","OD",IF(Q$6>$E$2,"",IF(Q18="Blank","Blank",IF(Q18="TBC","TBC",IF(Q18="Missed","Missed",IF(Q18="","OD",IF((Q18-Q17)>=0,"G",IF((Q18-(Q17*0.95))>=0,"A","R")))))))) -> R | ... AB19: =IF(AB4="OD","OD",IF(AB$6>$E$2,"",IF(AB18="Blank","Blank",IF(AB18="TBC","TBC",IF(AB18="Missed","Missed",IF(AB18="","OD",IF((AB18-AB17)>=0,"G",IF((AB18-(AB17*0.95))>=0,"A","R")))))))) -> G | AC19: =IF(AC4="OD","OD",IF(AC$6>$E$2,"",IF(AC18="Blank","Blank",IF(AC18="TBC","TBC",IF(AC18="No Data","No Data",IF(AC18="Missed","Missed",IF(AC18="","OD",IF((AC18-AC17)>=0,"G",IF((AC18-(AC17*0.95))>=0,"A","R"))))))))) -> R | AD19: =IF(AD4="OD","OD",IF(AD$6>$E$2,"",IF(AD18="Blank","Blank",IF(AD18="TBC","TBC",IF(AD18="Missed","Missed",IF(AD18="No Data","No Data",IF(AD18="","OD",IF((AD18-AD17)>=0,"G",IF((AD18-(AD17*0.95))>=0,"A","R"))))))))) -> G | AE19: =IF(AE4="OD","OD",IF(AE$6>$E$2,"",IF(AE18="Blank","Blank",IF(AE18="TBC","TBC",IF(AE18="No Data","No Data",IF(AE18="Missed","Missed",IF(AE18="","OD",IF((AE18-AE17)>=0,"G",IF((AE18-(AE17*0.95))>=0,"A","R"))))))))) -> G | AF19: =IF(AF4="OD","OD",IF(AF$6>$E$2,"",IF(AF18="Blank","Blank",IF(AF18="TBC","TBC",IF(AF18="Missed","Missed",IF(AF18="No Data","No Data",IF(AF18="","OD",IF((AF18-AF17)>=0,"G",IF((AF18-(AF17*0.95))>=0,"A","R"))))))))) -> A | AG19: =IF(AG4="OD","OD",IF(AG$6>$E$2,"",IF(AG18="Blank","Blank",IF(AG18="TBC","TBC",IF(AG18="No Data","No Data",IF(AG18="Missed","Missed",IF(AG18="","OD",IF((AG18-AG17)>=0,"G",IF((AG18-(AG17*0.95))>=0,"A","R"))))))))) -> G | AH19: =IF(AH4="OD","OD",IF(AH$6>$E$2,"",IF(AH18="Blank","Blank",IF(AH18="TBC","TBC",IF(AH18="Missed","Missed",IF(AH18="No Data","No Data",IF(AH18="","OD",IF((AH18-AH17)>=0,"G",IF((AH18-(AH17*0.95))>=0,"A","R"))))))))) -> G | AI19: =IF(AI4="OD","OD",IF(AI$6>$E$2,"",IF(AI18="Blank","Blank",IF(AI18="TBC","TBC",IF(AI18="No Data","No Data",IF(AI18="Missed","Missed",IF(AI18="","OD",IF((AI18-AI17)>=0,"G",IF((AI18-(AI17*0.95))>=0,"A","R"))))))))) -> G | AJ19: =IF(AJ4="OD","OD",IF(AJ$6>$E$2,"",IF(AJ18="Blank","Blank",IF(AJ18="TBC","TBC",IF(AJ18="Missed","Missed",IF(AJ18="No Data","No Data",IF(AJ18="","OD",IF((AJ18-AJ17)>=0,"G",IF((AJ18-(AJ17*0.95))>=0,"A","R"))))))))) -> G | AK19: =IF(AK4="OD","OD",IF(AK$6>$E$2,"",IF(AK18="Blank","Blank",IF(AK18="TBC","TBC",IF(AK18="No Data","No Data",IF(AK18="Missed","Missed",IF(AK18="","OD",IF((AK18-AK17)>=0,"G",IF((AK18-(AK17*0.95))>=0,"A","R"))))))))) -> R | AL19: =IF(AL4="OD","OD",IF(AL$6>$E$2,"",IF(AL18="Blank","Blank",IF(AL18="TBC","TBC",IF(AL18="Missed","Missed",IF(AL18="No Data","No Data",IF(AL18="","OD",IF((AL18-AL17)>=0,"G",IF((AL18-(AL17*0.95))>=0,"A","R"))))))))) -> G | AM19: =IF(AM4="OD","OD",IF(AM$6>$E$2,"",IF(AM18="Blank","Blank",IF(AM18="TBC","TBC",IF(AM18="No Data","No Data",IF(AM18="Missed","Missed",IF(AM18="","OD",IF((AM18-AM17)>=0,"G",IF((AM18-(AM17*0.95))>=0,"A","R"))))))))) -> R | AN19: =IF(AN4="OD","OD",IF(AN$6>$E$2,"",IF(AN18="Blank","Blank",IF(AN18="TBC","TBC",IF(AN18="Missed","Missed",IF(AN18="No Data","No Data",IF(AN18="","OD",IF((AN18-AN17)>=0,"G",IF((AN18-(AN17*0.95))>=0,"A","R"))))))))) -> R | AO19: =IF(AO4="OD","OD",IF(AO$6>$E$2,"",IF(AO18="Blank","Blank",IF(AO18="TBC","TBC",IF(AO18="No Data","No Data",IF(AO18="Missed","Missed",IF(AO18="","OD",IF((AO18-AO17)>=0,"G",IF((AO18-(AO17*0.95))>=0,"A","R"))))))))) -> R | AP19: =IF(AP4="OD","OD",IF(AP$6>$E$2,"",IF(AP18="Blank","Blank",IF(AP18="TBC","TBC",IF(AP18="Missed","Missed",IF(AP18="No Data","No Data",IF(AP18="","OD",IF((AP18-AP17)>=0,"G",IF((AP18-(AP17*0.95))>=0,"A","R"))))))))) -> R | AQ19: =IF(AQ4="OD","OD",IF(AQ$6>$E$2,"",IF(AQ18="Blank","Blank",IF(AQ18="TBC","TBC",IF(AQ18="No Data","No Data",IF(AQ18="Missed","Missed",IF(AQ18="","OD",IF((AQ18-AQ17)>=0,"G",IF((AQ18-(AQ17*0.95))>=0,"A","R"))))))))) -> R | AR19: =IF(AR4="OD","OD",IF(AR$6>$E$2,"",IF(AR18="Blank","Blank",IF(AR18="TBC","TBC",IF(AR18="Missed","Missed",IF(AR18="No Data","No Data",IF(AR18="","OD",IF((AR18-AR17)>=0,"G",IF((AR18-(AR17*0.95))>=0,"A","R"))))))))) -> G | AS19: =IF(AS4="OD","OD",IF(AS$6>$E$2,"",IF(AS18="Blank","Blank",IF(AS18="TBC","TBC",IF(AS18="No Data","No Data",IF(AS18="Missed","Missed",IF(AS18="","OD",IF((AS18-AS17)>=0,"G",IF((AS18-(AS17*0.95))>=0,"A","R"))))))))) -> G | AT19: =IF(AT4="OD","OD",IF(AT$6>$E$2,"",IF(AT18="Blank","Blank",IF(AT18="TBC","TBC",IF(AT18="Missed","Missed",IF(AT18="No Data","No Data",IF(AT18="","OD",IF((AT18-AT17)>=0,"G",IF((AT18-(AT17*0.95))>=0,"A","R"))))))))) -> R | AU19: =IF(AU4="OD","OD",IF(AU$6>$E$2,"",IF(AU18="Blank","Blank",IF(AU18="TBC","TBC",IF(AU18="No Data","No Data",IF(AU18="Missed","Missed",IF(AU18="","OD",IF((AU18-AU17)>=0,"G",IF((AU18-(AU17*0.95))>=0,"A","R"))))))))) -> R | AV19: =IF(AV4="OD","OD",IF(AV$6>$E$2,"",IF(AV18="Blank","Blank",IF(AV18="TBC","TBC",IF(AV18="Missed","Missed",IF(AV18="No Data","No Data",IF(AV18="","OD",IF((AV18-AV17)>=0,"G",IF((AV18-(AV17*0.95))>=0,"A","R"))))))))) -> G | AW19: =IF(AW4="OD","OD",IF(AW$6>$E$2,"",IF(AW18="Blank","Blank",IF(AW18="TBC","TBC",IF(AW18="No Data","No Data",IF(AW18="Missed","Missed",IF(AW18="","OD",IF((AW18-AW17)>=0,"G",IF((AW18-(AW17*0.95))>=0,"A","R"))))))))) -> G | AX19: =IF(AX4="OD","OD",IF(AX$6>$E$2,"",IF(AX18="Blank","Blank",IF(AX18="TBC","TBC",IF(AX18="Missed","Missed",IF(AX18="No Data","No Data",IF(AX18="","OD",IF((AX18-AX17)>=0,"G",IF((AX18-(AX17*0.95))>=0,"A","R"))))))))) -> G | AY19: =IF(AY4="OD","OD",IF(AY$6>$E$2,"",IF(AY18="Blank","Blank",IF(AY18="TBC","TBC",IF(AY18="No Data","No Data",IF(AY18="Missed","Missed",IF(AY18="","OD",IF((AY18-AY17)>=0,"G",IF((AY18-(AY17*0.95))>=0,"A","R"))))))))) | AZ19: =IF(AZ4="OD","OD",IF(AZ$6>$E$2,"",IF(AZ18="Blank","Blank",IF(AZ18="TBC","TBC",IF(AZ18="Missed","Missed",IF(AZ18="No Data","No Data",IF(AZ18="","OD",IF((AZ18-AZ17)>=0,"G",IF((AZ18-(AZ17*0.95))>=0,"A","R"))))))))) | BA19: =IF(BA4="OD","OD",IF(BA$6>$E$2,"",IF(BA18="Blank","Blank",IF(BA18="TBC","TBC",IF(BA18="No Data","No Data",IF(BA18="Missed","Missed",IF(BA18="","OD",IF((BA18-BA17)>=0,"G",IF((BA18-(BA17*0.95))>=0,"A","R"))))))))) | BB19: =IF(BB4="OD","OD",IF(BB$6>$E$2,"",IF(BB18="Blank","Blank",IF(BB18="TBC","TBC",IF(BB18="Missed","Missed",IF(BB18="No Data","No Data",IF(BB18="","OD",IF((BB18-BB17)>=0,"G",IF((BB18-(BB17*0.95))>=0,"A","R"))))))))) | BC19: =IF(BC4="OD","OD",IF(BC$6>$E$2,"",IF(BC18="Blank","Blank",IF(BC18="TBC","TBC",IF(BC18="No Data","No Data",IF(BC18="Missed","Missed",IF(BC18="","OD",IF((BC18-BC17)>=0,"G",IF((BC18-(BC17*0.95))>=0,"A","R"))))))))) | BD19: =IF(BD4="OD","OD",IF(BD$6>$E$2,"",IF(BD18="Blank","Blank",IF(BD18="TBC","TBC",IF(BD18="Missed","Missed",IF(BD18="No Data","No Data",IF(BD18="","OD",IF((BD18-BD17)>=0,"G",IF((BD18-(BD17*0.95))>=0,"A","R"))))))))) | BE19: =IF(BE4="OD","OD",IF(BE$6>$E$2,"",IF(BE18="Blank","Blank",IF(BE18="TBC","TBC",IF(BE18="No Data","No Data",IF(BE18="Missed","Missed",IF(BE18="","OD",IF((BE18-BE17)>=0,"G",IF((BE18-(BE17*0.95))>=0,"A","R"))))))))) | BF19: =IF(BF4="OD","OD",IF(BF$6>$E$2,"",IF(BF18="Blank","Blank",IF(BF18="TBC","TBC",IF(BF18="Missed","Missed",IF(BF18="No Data","No Data",IF(BF18="","OD",IF((BF18-BF17)>=0,"G",IF((BF18-(BF17*0.95))>=0,"A","R"))))))))) | BG19: =IF(BG4="OD","OD",IF(BG$6>$E$2,"",IF(BG18="Blank","Blank",IF(BG18="TBC","TBC",IF(BG18="No Data","No Data",IF(BG18="Missed","Missed",IF(BG18="","OD",IF((BG18-BG17)>=0,"G",IF((BG18-(BG17*0.95))>=0,"A","R"))))))))) | BH19: =IF(BH4="OD","OD",IF(BH$6>$E$2,"",IF(BH18="Blank","Blank",IF(BH18="TBC","TBC",IF(BH18="Missed","Missed",IF(BH18="No Data","No Data",IF(BH18="","OD",IF((BH18-BH17)>=0,"G",IF((BH18-(BH17*0.95))>=0,"A","R"))))))))) | BI19: =IF(BI4="OD","OD",IF(BI$6>$E$2,"",IF(BI18="Blank","Blank",IF(BI18="TBC","TBC",IF(BI18="No Data","No Data",IF(BI18="Missed","Missed",IF(BI18="","OD",IF((BI18-BI17)>=0,"G",IF((BI18-(BI17*0.95))>=0,"A","R"))))))))) | BJ19: =IF(BJ4="OD","OD",IF(BJ$6>$E$2,"",IF(BJ18="Blank","Blank",IF(BJ18="TBC","TBC",IF(BJ18="Missed","Missed",IF(BJ18="No Data","No Data",IF(BJ18="","OD",IF((BJ18-BJ17)>=0,"G",IF((BJ18-(BJ17*0.95))>=0,"A","R")))))))))
B21: Historic Comparisons - Reference only discussed with Andy Skitt
B22: Productivity | C22: Volume Completed | D22: Number of Approx. Design requests closed weekly | E22: As above | G22: From Power BI Pivot | H22: Actual | I22: Blank | J22: =+J9 -> 33 | K22: =+K9 -> 30 | L22: =+L9 -> 34 | M22: =+M9 -> 32 | N22: =+N9 -> 35 | O22: =+O9 -> 35 | P22: =+P9 -> 31 | Q22: =+Q9 -> 33 | ... BJ22: =+BJ9
E23: As per KPI Data | G23: Reported by Submission | H23: Actual | I23: Blank | J23: 33 | K23: 30 | L23: 33 | M23: 36 | N23: 36 | O23: 38 | P23: 32 | Q23: 31 | R23: 25 | S23: 38 | T23: 33 | U23: 37 | V23: 36 | W23: 39 | X23: 20 | Y23: 16 | Z23: 33 | AA23: 35 | AB23: 40 | AC23: =IF(AC$6>$E$2,"",IFERROR(+GETPIVOTDATA("Count of Proposal Request No.",'Pivot Weekly close'!$A$4,"week No",AC20),"no Data")) -> no Data | AD23: =IF(AD$6>$E$2,"",IFERROR(+GETPIVOTDATA("Count of Proposal Request No.",'Pivot Weekly close'!$A$4,"week No",AD20),"no Data")) -> no Data | AE23: =IF(AE$6>$E$2,"",IFERROR(+GETPIVOTDATA("Count of Proposal Request No.",'Pivot Weekly close'!$A$4,"week No",AE20),"no Data")) -> no Data | AF23: =IF(AF$6>$E$2,"",IFERROR(+GETPIVOTDATA("Count of Proposal Request No.",'Pivot Weekly close'!$A$4,"week No",AF20),"no Data")) -> no Data | AG23: =IF(AG$6>$E$2,"",IFERROR(+GETPIVOTDATA("Count of Proposal Request No.",'Pivot Weekly close'!$A$4,"week No",AG20),"no Data")) -> no Data | AH23: =IF(AH$6>$E$2,"",IFERROR(+GETPIVOTDATA("Count of Proposal Request No.",'Pivot Weekly close'!$A$4,"week No",AH20),"no Data")) -> no Data | AI23: =IF(AI$6>$E$2,"",IFERROR(+GETPIVOTDATA("Count of Proposal Request No.",'Pivot Weekly close'!$A$4,"week No",AI20),"no Data")) -> no Data | AJ23: =IF(AJ$6>$E$2,"",IFERROR(+GETPIVOTDATA("Count of Proposal Request No.",'Pivot Weekly close'!$A$4,"week No",AJ20),"no Data")) -> no Data | ... BJ23: =IF(BJ$6>$E$2,"",IFERROR(+GETPIVOTDATA("Count of Proposal Request No.",'Pivot Weekly close'!$A$4,"week No",BJ20),"no Data"))
E24: Reviewed with Andy Skitt | G24: Difference +ve power BI Higher | H24: Actual | I24: Blank | J24: =IF(J6>$E$2,"",IFERROR(+J22-J23,0)) -> 0 | K24: =IF(K6>$E$2,"",IFERROR(+K22-K23,0)) -> 0 | L24: =IF(L6>$E$2,"",IFERROR(+L22-L23,0)) -> 1 | M24: =IF(M6>$E$2,"",IFERROR(+M22-M23,0)) -> -4 | N24: =IF(N6>$E$2,"",IFERROR(+N22-N23,0)) -> -1 | O24: =IF(O6>$E$2,"",IFERROR(+O22-O23,0)) -> -3 | P24: =IF(P6>$E$2,"",IFERROR(+P22-P23,0)) -> -1 | Q24: =IF(Q6>$E$2,"",IFERROR(+Q22-Q23,0)) -> 2 | ... BJ24: =IF(BJ6>$E$2,"",IFERROR(+BJ22-BJ23,0))
B26: Delivery | C26: OTIF | D26: % of Designs closed that were completed by the Internal Date | G26: From Power BI Pivot | H26: Actual | I26: Blank | J26: =+J12 -> 87.878788 | K26: =+K12 -> 100 | L26: =+L12 -> 88.235294 | M26: =+M12 -> 96.875 | N26: =+N12 -> 88.571429 | O26: =+O12 -> 88.571429 | P26: =+P12 -> 93.548387 | Q26: =+Q12 -> 84.848485 | ... BI26: =+BI12 | BJ26: =IF(BJ$6>$E$2,"",IFERROR(+GETPIVOTDATA("Count of Proposal Request No.",'Pivot Weekly close'!$A$4,"week No",BJ22),"no Data"))
G27: Reported by Submission | H27: Actual | I27: Blank | J27: 87 | K27: 77 | L27: 94 | M27: 89 | N27: 89 | O27: 87 | P27: 90 | Q27: 86 | R27: 84 | S27: 90 | T27: 82 | U27: 92 | V27: 86 | W27: 86 | X27: 80 | Y27: 81 | Z27: 91 | AA27: 71 | AB27: 81 | AC27: =IF(AC$6>$E$2,"",IFERROR(+GETPIVOTDATA("Count of Proposal Request No.",'Pivot Weekly close'!$A$4,"week No",AC23),"no Data")) -> no Data | AD27: =IF(AD$6>$E$2,"",IFERROR(+GETPIVOTDATA("Count of Proposal Request No.",'Pivot Weekly close'!$A$4,"week No",AD23),"no Data")) -> no Data | AE27: =IF(AE$6>$E$2,"",IFERROR(+GETPIVOTDATA("Count of Proposal Request No.",'Pivot Weekly close'!$A$4,"week No",AE23),"no Data")) -> no Data | AF27: =IF(AF$6>$E$2,"",IFERROR(+GETPIVOTDATA("Count of Proposal Request No.",'Pivot Weekly close'!$A$4,"week No",AF23),"no Data")) -> no Data | AG27: =IF(AG$6>$E$2,"",IFERROR(+GETPIVOTDATA("Count of Proposal Request No.",'Pivot Weekly close'!$A$4,"week No",AG23),"no Data")) -> no Data | AH27: =IF(AH$6>$E$2,"",IFERROR(+GETPIVOTDATA("Count of Proposal Request No.",'Pivot Weekly close'!$A$4,"week No",AH23),"no Data")) -> no Data | AI27: =IF(AI$6>$E$2,"",IFERROR(+GETPIVOTDATA("Count of Proposal Request No.",'Pivot Weekly close'!$A$4,"week No",AI23),"no Data")) -> no Data | AJ27: =IF(AJ$6>$E$2,"",IFERROR(+GETPIVOTDATA("Count of Proposal Request No.",'Pivot Weekly close'!$A$4,"week No",AJ23),"no Data")) -> no Data | ... BJ27: =IF(BJ$6>$E$2,"",IFERROR(+GETPIVOTDATA("Count of Proposal Request No.",'Pivot Weekly close'!$A$4,"week No",BJ23),"no Data"))
E28: Reviewed with Andy Skitt | G28: Difference +ve power BI Higher | H28: Actual | I28: Blank | J28: =IF(J6>$E$2,"",IFERROR(+J26-J27,0)) -> 0.87878788 | K28: =IF(K6>$E$2,"",IFERROR(+K26-K27,0)) -> 23 | L28: =IF(L6>$E$2,"",IFERROR(+L26-L27,0)) -> -5.7647059 | M28: =IF(M6>$E$2,"",IFERROR(+M26-M27,0)) -> 7.875 | N28: =IF(N6>$E$2,"",IFERROR(+N26-N27,0)) -> -0.42857143 | O28: =IF(O6>$E$2,"",IFERROR(+O26-O27,0)) -> 1.5714286 | P28: =IF(P6>$E$2,"",IFERROR(+P26-P27,0)) -> 3.5483871 | Q28: =IF(Q6>$E$2,"",IFERROR(+Q26-Q27,0)) -> -1.1515152 | ... BJ28: =IF(BJ6>$E$2,"",IFERROR(+BJ26-BJ27,0))
B33: R | C33: KPI is worse than Target
B34: A | C34: KPI is <5% worse than Target | G34: Sales Force - https://sasinternational.lightning.force.com/lightning/r/Report/00OP3000005K1gDMAS/view
B35: G | C35: KPI is better than Target | G35: Sales Force - https://sasinternational.lightning.force.com/lightning/r/Report/00OP3000003GHJJMA4/view
B36: TBC | C36: Missing Submission | G36: Sales Force - https://sasinternational.lightning.force.com/lightning/r/Report/00OP3000005cl33MAA/view?queryScope=userFolders
B37: Blank | C37: No Submission
F42: =39/5 -> 7.8

Sheet Pivot Weekly close
J3: KPI Data
A4: Row Labels | B4: Count of Proposal Request No. | C4: Sum of estimate £
A5: (blank)
A6: 2 | B6: 33 | C6: 4340909.3
A7: 3 | B7: 30 | C7: 2862627.8
A8: 4 | B8: 34 | C8: 8583202.6
A9: 5 | B9: 32 | C9: 4594116.9
A10: 6 | B10: 35 | C10: 4747599.8
A11: 7 | B11: 35 | C11: 2717995.9
A12: 8 | B12: 31 | C12: 6554469
A13: 9 | B13: 33 | C13: 5314301.1
A14: 10 | B14: 27 | C14: 3595658.5
A15: 11 | B15: 39 | C15: 3503751.9
A16: 12 | B16: 34 | C16: 8177118.3
A17: 13 | B17: 36 | C17: 13792512
... A30: 26 | B30: 36 | C30: 28856386
A31: 27 | B31: 34 | C31: 12028214 | W31: 84463.4 | X31: 170179.05 | Y31: 208558.87 | Z31: 169775.56 | AA31: 373601.16 | AB31: 212772.49
A32: 28 | B32: 29 | C32: 31220720
A33: 29 | B33: 25 | C33: 3238852.8
A34: 30 | B34: 41 | C34: 8139404.6
A35: 31 | B35: 32 | C35: 3537025.7
A36: 32 | B36: 33 | C36: 3483633.6
A37: 33 | B37: 10 | C37: 495382.07
A38: 34 | B38: 7 | C38: 198299.22
A39: 35 | B39: 61 | C39: 8114471
A40: 36 | B40: 14 | C40: 2440946.3
A41: 37 | B41: 28 | C41: 5886069
A42: 38 | B42: 25 | C42: 3106702.4
A43: 39 | B43: 22 | C43: 3386443.4
... A46: 42 | B46: 24 | C46: 6883366.3
A47: Grand Total | B47: 1217 | C47: 2.8073743e+08

Sheet Pivot Of Design Days
A4: Record Type | B4: (All)
A6: Row Labels | B6: Average of On Time? | C6: Count of Proposal Request No.
A7: (blank)
A8: 2 | B8: 87.878788 | C8: 33
A9: 3 | B9: 100 | C9: 30
A10: 4 | B10: 88.235294 | C10: 34
A11: 5 | B11: 96.875 | C11: 32
A12: 6 | B12: 88.571429 | C12: 35
A13: 7 | B13: 88.571429 | C13: 35
A14: 8 | B14: 93.548387 | C14: 31
A15: 9 | B15: 84.848485 | C15: 33
A16: 10 | B16: 88.888889 | C16: 27
A17: 11 | B17: 89.74359 | C17: 39
A18: 12 | B18: 82.352941 | C18: 34
A19: 13 | B19: 94.444444 | C19: 36
... A48: 42 | B48: 76.190476 | C48: 21
A49: Grand Total | B49: 81.136738 | C49: 1214

Sheet Weekly Closed Proposal Requests
A1: Opened Date | B1: Proposal Request No. | C1: Project Name: Project Name | D1: Estimated Value Currency | E1: Estimated Value | F1: Closed Date | G1: Sales Division | H1: Record Type | I1: week No | J1: Ex Rate | K1: estimate £ | L1: Mth
A2: 45645 | B2: PRO-000002800 | C2: DARLING PARK - LEVEL 17 & 18 | D2: AUD | E2: 5000 | F2: 45662 | G2: Australia | H2: CAD Sketch | I2: =_xlfn.XLOOKUP(F2,'Wk no''s'!B:B,'Wk no''s'!C:C,FALSE) -> 2 | J2: =IF(D2="GBP",1,SUMIFS('Ex Rates'!I:I,'Ex Rates'!K:K,'Weekly Closed Proposal Requests'!L2,'Ex Rates'!G:G,'Weekly Closed Proposal Requests'!D2)) -> 0.50125313 | K2: =+E2*J2 -> 2506.2657 | L2: =_xlfn.XLOOKUP(I2,'Wk no''s'!C:C,'Wk no''s'!E:E,0) -> Jan
A3: 45506 | B3: PRO-000002171 | C3: SYDNEY FISH MARKET | D3: GBP | E3: 250000 | F3: 45663 | G3: Australia | H3: Shop Drawing | I3: =_xlfn.XLOOKUP(F3,'Wk no''s'!B:B,'Wk no''s'!C:C,FALSE) -> 2 | J3: =IF(D3="GBP",1,SUMIFS('Ex Rates'!I:I,'Ex Rates'!K:K,'Weekly Closed Proposal Requests'!L3,'Ex Rates'!G:G,'Weekly Closed Proposal Requests'!D3)) -> 1 | K3: =+E3*J3 -> 250000 | L3: =_xlfn.XLOOKUP(I3,'Wk no''s'!C:C,'Wk no''s'!E:E,0) -> Jan
A4: 45636 | B4: PRO-000002756 | C4: SYDNEY FISH MARKET INTERNAL FIT OUT | D4: AUD | E4: 250000 | F4: 45663 | G4: Australia | H4: Shop Drawing | I4: =_xlfn.XLOOKUP(F4,'Wk no''s'!B:B,'Wk no''s'!C:C,FALSE) -> 2 | J4: =IF(D4="GBP",1,SUMIFS('Ex Rates'!I:I,'Ex Rates'!K:K,'Weekly Closed Proposal Requests'!L4,'Ex Rates'!G:G,'Weekly Closed Proposal Requests'!D4)) -> 0.50125313 | K4: =+E4*J4 -> 125313.28 | L4: =_xlfn.XLOOKUP(I4,'Wk no''s'!C:C,'Wk no''s'!E:E,0) -> Jan
A5: 45638 | B5: PRO-000002769 | C5: WEST 31ST ST NO 401 DE SHAW FIT OUT FLRS 48-56 NEW YORK | D5: GBP | E5: 0 | F5: 45663 | G5: USA | H5: Shop Drawing | I5: =_xlfn.XLOOKUP(F5,'Wk no''s'!B:B,'Wk no''s'!C:C,FALSE) -> 2 | J5: =IF(D5="GBP",1,SUMIFS('Ex Rates'!I:I,'Ex Rates'!K:K,'Weekly Closed Proposal Requests'!L5,'Ex Rates'!G:G,'Weekly Closed Proposal Requests'!D5)) -> 1 | K5: =+E5*J5 -> 0 | L5: =_xlfn.XLOOKUP(I5,'Wk no''s'!C:C,'Wk no''s'!E:E,0) -> Jan
A6: 45643 | B6: PRO-000002780 | C6: SYDNEY FISH MARKET INTERNAL FIT OUT | D6: AUD | E6: 250000 | F6: 45663 | G6: Australia | H6: Shop Drawing | I6: =_xlfn.XLOOKUP(F6,'Wk no''s'!B:B,'Wk no''s'!C:C,FALSE) -> 2 | J6: =IF(D6="GBP",1,SUMIFS('Ex Rates'!I:I,'Ex Rates'!K:K,'Weekly Closed Proposal Requests'!L6,'Ex Rates'!G:G,'Weekly Closed Proposal Requests'!D6)) -> 0.50125313 | K6: =+E6*J6 -> 125313.28 | L6: =_xlfn.XLOOKUP(I6,'Wk no''s'!C:C,'Wk no''s'!E:E,0) -> Jan
A7: 45643 | B7: PRO-000002784 | C7: WEST ONE DEVELOPMENT OXFORD STREET LONDON | D7: GBP | E7: 100000 | F7: 45663 | G7: UK | H7: Proposal | I7: =_xlfn.XLOOKUP(F7,'Wk no''s'!B:B,'Wk no''s'!C:C,FALSE) -> 2 | J7: =IF(D7="GBP",1,SUMIFS('Ex Rates'!I:I,'Ex Rates'!K:K,'Weekly Closed Proposal Requests'!L7,'Ex Rates'!G:G,'Weekly Closed Proposal Requests'!D7)) -> 1 | K7: =+E7*J7 -> 100000 | L7: =_xlfn.XLOOKUP(I7,'Wk no''s'!C:C,'Wk no''s'!E:E,0) -> Jan
A8: 45644 | B8: PRO-000002795 | C8: HOLDING SAINT MICHEL PARIS | D8: EUR | E8: 50000 | F8: 45663 | G8: France | H8: Proposal | I8: =_xlfn.XLOOKUP(F8,'Wk no''s'!B:B,'Wk no''s'!C:C,FALSE) -> 2 | J8: =IF(D8="GBP",1,SUMIFS('Ex Rates'!I:I,'Ex Rates'!K:K,'Weekly Closed Proposal Requests'!L8,'Ex Rates'!G:G,'Weekly Closed Proposal Requests'!D8)) -> 0.83682008 | K8: =+E8*J8 -> 41841.004 | L8: =_xlfn.XLOOKUP(I8,'Wk no''s'!C:C,'Wk no''s'!E:E,0) -> Jan
A9: 45645 | B9: PRO-000002804 | C9: OCASO FUENCARRAL 107 MADRID | D9: GBP | E9: 50000 | F9: 45663 | G9: Rest of the World | H9: Proposal | I9: =_xlfn.XLOOKUP(F9,'Wk no''s'!B:B,'Wk no''s'!C:C,FALSE) -> 2 | J9: =IF(D9="GBP",1,SUMIFS('Ex Rates'!I:I,'Ex Rates'!K:K,'Weekly Closed Proposal Requests'!L9,'Ex Rates'!G:G,'Weekly Closed Proposal Requests'!D9)) -> 1 | K9: =+E9*J9 -> 50000 | L9: =_xlfn.XLOOKUP(I9,'Wk no''s'!C:C,'Wk no''s'!E:E,0) -> Jan
A10: 45646 | B10: PRO-000002807 | C10: MOORGATE NO 25 CAT B WATSON FARLEY LONDON | D10: GBP | E10: 250000 | F10: 45663 | G10: UK | H10: Proposal | I10: =_xlfn.XLOOKUP(F10,'Wk no''s'!B:B,'Wk no''s'!C:C,FALSE) -> 2 | J10: =IF(D10="GBP",1,SUMIFS('Ex Rates'!I:I,'Ex Rates'!K:K,'Weekly Closed Proposal Requests'!L10,'Ex Rates'!G:G,'Weekly Closed Proposal Requests'!D10)) -> 1 | K10: =+E10*J10 -> 250000 | L10: =_xlfn.XLOOKUP(I10,'Wk no''s'!C:C,'Wk no''s'!E:E,0) -> Jan
A11: 45646 | B11: PRO-000002810 | C11: METRO MANILA SUBWAY 17 STATIONS | D11: GBP | E11: 180000 | F11: 45663 | G11: Rest of the World | H11: Proposal | I11: =_xlfn.XLOOKUP(F11,'Wk no''s'!B:B,'Wk no''s'!C:C,FALSE) -> 2 | J11: =IF(D11="GBP",1,SUMIFS('Ex Rates'!I:I,'Ex Rates'!K:K,'Weekly Closed Proposal Requests'!L11,'Ex Rates'!G:G,'Weekly Closed Proposal Requests'!D11)) -> 1 | K11: =+E11*J11 -> 180000 | L11: =_xlfn.XLOOKUP(I11,'Wk no''s'!C:C,'Wk no''s'!E:E,0) -> Jan
A12: 45636 | B12: PRO-000002749 | C12: PASO INFERIOR INFANTA LEONOR | D12: GBP | E12: 300000 | F12: 45664 | G12: Rest of the World | H12: Proposal | I12: =_xlfn.XLOOKUP(F12,'Wk no''s'!B:B,'Wk no''s'!C:C,FALSE) -> 2 | J12: =IF(D12="GBP",1,SUMIFS('Ex Rates'!I:I,'Ex Rates'!K:K,'Weekly Closed Proposal Requests'!L12,'Ex Rates'!G:G,'Weekly Closed Proposal Requests'!D12)) -> 1 | K12: =+E12*J12 -> 300000 | L12: =_xlfn.XLOOKUP(I12,'Wk no''s'!C:C,'Wk no''s'!E:E,0) -> Jan
A13: 45642 | B13: PRO-000002776 | C13: HERON TOWER NO 110 BISHOPSGATE TRADITION FLOORS 8-10 LONDON | D13: GBP | E13: 15000 | F13: 45664 | G13: UK | H13: Proposal | I13: =_xlfn.XLOOKUP(F13,'Wk no''s'!B:B,'Wk no''s'!C:C,FALSE) -> 2 | J13: =IF(D13="GBP",1,SUMIFS('Ex Rates'!I:I,'Ex Rates'!K:K,'Weekly Closed Proposal Requests'!L13,'Ex Rates'!G:G,'Weekly Closed Proposal Requests'!D13)) -> 1 | K13: =+E13*J13 -> 15000 | L13: =_xlfn.XLOOKUP(I13,'Wk no''s'!C:C,'Wk no''s'!E:E,0) -> Jan
... A1218: 45943 | B1218: PRO-000004091 | C1218: BMW RENOVATION MISSISSAUGA ONTARIO | D1218: GBP | E1218: 20000 | F1218: 45945 | G1218: Rest of the World | H1218: Shop Drawing | I1218: =_xlfn.XLOOKUP(F1218,'Wk no''s'!B:B,'Wk no''s'!C:C,FALSE) -> 42 | J1218: =IF(D1218="GBP",1,SUMIFS('Ex Rates'!I:I,'Ex Rates'!K:K,'Weekly Closed Proposal Requests'!L1218,'Ex Rates'!G:G,'Weekly Closed Proposal Requests'!D1218)) -> 1 | K1218: =+E1218*J1218 -> 20000 | L1218: =_xlfn.XLOOKUP(I1218,'Wk no''s'!C:C,'Wk no''s'!E:E,0) -> Oct

Sheet Ex Rates
A1: Estimated Value Currency | F1: K:\Finance\Financial accounts\2025\SAS Holdings consolidation\4. Apr 2025\April 2025 Holdings consolidation DRAFTv2.xlsx
A2: AUD | B2: 0.48
A3: GBP | B3: 1 | F3: GBP | G3: AED | H3: 4.895 | I3: =1/H3 -> 0.20429009 | J3: 45748 | K3: =TEXT(J3,"MMM") -> Apr
A4: EUR | B4: 0.84 | F4: GBP | G4: AUD | H4: 2.081 | I4: =1/H4 -> 0.4805382 | J4: 45748 | K4: =TEXT(J4,"MMM") -> Apr
A5: USD | B5: 0.74 | F5: GBP | G5: CAD | H5: 1.838 | I5: =1/H5 -> 0.54406964 | J5: 45748 | K5: =TEXT(J5,"MMM") -> Apr
F6: GBP | G6: CHF | H6: 1.102 | I6: =1/H6 -> 0.90744102 | J6: 45748 | K6: =TEXT(J6,"MMM") -> Apr
F7: GBP | G7: EUR | H7: 1.177 | I7: =1/H7 -> 0.84961767 | J7: 45748 | K7: =TEXT(J7,"MMM") -> Apr
F8: GBP | G8: HKD | H8: 10.339 | I8: =1/H8 -> 0.096721153 | J8: 45748 | K8: =TEXT(J8,"MMM") -> Apr
F9: GBP | G9: NZD | H9: 2.245 | I9: =1/H9 -> 0.4454343 | J9: 45748 | K9: =TEXT(J9,"MMM") -> Apr
F10: GBP | G10: USD | H10: 1.333 | I10: =1/H10 -> 0.75018755 | J10: 45748 | K10: =TEXT(J10,"MMM") -> Apr
F11: GBP | G11: AED | H11: 4.745 | I11: =1/H11 -> 0.21074816 | J11: 45717 | K11: =TEXT(J11,"MMM") -> Mar
F12: GBP | G12: AUD | H12: 2.067 | I12: =1/H12 -> 0.48379294 | J12: 45717 | K12: =TEXT(J12,"MMM") -> Mar
F13: GBP | G13: CAD | H13: 1.859 | I13: =1/H13 -> 0.53792361 | J13: 45717 | K13: =TEXT(J13,"MMM") -> Mar
F14: GBP | G14: CHF | H14: 1.142 | I14: =1/H14 -> 0.87565674 | J14: 45717 | K14: =TEXT(J14,"MMM") -> Mar
F15: GBP | G15: EUR | H15: 1.194 | I15: =1/H15 -> 0.83752094 | J15: 45717 | K15: =TEXT(J15,"MMM") -> Mar
F16: GBP | G16: HKD | H16: 10.054 | I16: =1/H16 -> 0.0994629 | J16: 45717 | K16: =TEXT(J16,"MMM") -> Mar
F17: GBP | G17: NZD | H17: 2.274 | I17: =1/H17 -> 0.43975374 | J17: 45717 | K17: =TEXT(J17,"MMM") -> Mar
... F82: GBP | G82: USD | H82: 1.353 | I82: =1/H82 -> 0.7390983 | J82: 45931 | K82: =TEXT(J82,"MMM") -> Oct

Sheet Design Days between estimate by
A1: Proposal Request No. | B1: Estimated Completion Date | C1: On Time? | D1: Record Type | E1: Closed Date | F1: Sales Division | G1: week No
A2: PRO-000002800 | C2: 100 | D2: CAD Sketch | E2: 45662 | F2: Australia | G2: =_xlfn.XLOOKUP(E2,'Wk no''s'!B:B,'Wk no''s'!C:C,FALSE) -> 2
A3: PRO-000002784 | B3: 45663 | C3: 100 | D3: Proposal | E3: 45663 | F3: UK | G3: =_xlfn.XLOOKUP(E3,'Wk no''s'!B:B,'Wk no''s'!C:C,FALSE) -> 2
A4: PRO-000002807 | B4: 45663 | C4: 100 | D4: Proposal | E4: 45663 | F4: UK | G4: =_xlfn.XLOOKUP(E4,'Wk no''s'!B:B,'Wk no''s'!C:C,FALSE) -> 2
A5: PRO-000002795 | B5: 45663 | C5: 100 | D5: Proposal | E5: 45663 | F5: France | G5: =_xlfn.XLOOKUP(E5,'Wk no''s'!B:B,'Wk no''s'!C:C,FALSE) -> 2
A6: PRO-000002769 | B6: 45663 | C6: 100 | D6: Shop Drawing | E6: 45663 | F6: USA | G6: =_xlfn.XLOOKUP(E6,'Wk no''s'!B:B,'Wk no''s'!C:C,FALSE) -> 2
A7: PRO-000002171 | B7: 45663 | C7: 100 | D7: Shop Drawing | E7: 45663 | F7: Australia | G7: =_xlfn.XLOOKUP(E7,'Wk no''s'!B:B,'Wk no''s'!C:C,FALSE) -> 2
A8: PRO-000002756 | B8: 45663 | C8: 100 | D8: Shop Drawing | E8: 45663 | F8: Australia | G8: =_xlfn.XLOOKUP(E8,'Wk no''s'!B:B,'Wk no''s'!C:C,FALSE) -> 2
A9: PRO-000002780 | B9: 45663 | C9: 100 | D9: Shop Drawing | E9: 45663 | F9: Australia | G9: =_xlfn.XLOOKUP(E9,'Wk no''s'!B:B,'Wk no''s'!C:C,FALSE) -> 2
A10: PRO-000002804 | B10: 45664 | C10: 100 | D10: Proposal | E10: 45663 | F10: Rest of the World | G10: =_xlfn.XLOOKUP(E10,'Wk no''s'!B:B,'Wk no''s'!C:C,FALSE) -> 2
A11: PRO-000002810 | B11: 45667 | C11: 100 | D11: Proposal | E11: 45663 | F11: Rest of the World | G11: =_xlfn.XLOOKUP(E11,'Wk no''s'!B:B,'Wk no''s'!C:C,FALSE) -> 2
A12: PRO-000002776 | B12: 45664 | C12: 100 | D12: Proposal | E12: 45664 | F12: UK | G12: =_xlfn.XLOOKUP(E12,'Wk no''s'!B:B,'Wk no''s'!C:C,FALSE) -> 2
A13: PRO-000002809 | B13: 45665 | C13: 100 | D13: Proposal | E13: 45664 | F13: UK | G13: =_xlfn.XLOOKUP(E13,'Wk no''s'!B:B,'Wk no''s'!C:C,FALSE) -> 2
A14: PRO-000002813 | C14: 100 | D14: Shop Drawing | E14: 45664 | F14: Australia | G14: =_xlfn.XLOOKUP(E14,'Wk no''s'!B:B,'Wk no''s'!C:C,FALSE) -> 2
A15: PRO-000002749 | B15: 45664 | C15: 100 | D15: Proposal | E15: 45664 | F15: Rest of the World | G15: =_xlfn.XLOOKUP(E15,'Wk no''s'!B:B,'Wk no''s'!C:C,FALSE) -> 2
A16: PRO-000002812 | B16: 45667 | C16: 100 | D16: Proposal | E16: 45664 | F16: Rest of the World | G16: =_xlfn.XLOOKUP(E16,'Wk no''s'!B:B,'Wk no''s'!C:C,FALSE) -> 2
A17: PRO-000002808 | B17: 45664 | C17: 0 | D17: Proposal | E17: 45665 | F17: UK | G17: =_xlfn.XLOOKUP(E17,'Wk no''s'!B:B,'Wk no''s'!C:C,FALSE) -> 2
A18: PRO-000002801 | B18: 45670 | C18: 100 | D18: Proposal | E18: 45665 | F18: UK | G18: =_xlfn.XLOOKUP(E18,'Wk no''s'!B:B,'Wk no''s'!C:C,FALSE) -> 2
A19: PRO-000002826 | B19: 45665 | C19: 100 | D19: CAD Sketch | E19: 45665 | F19: UK | G19: =_xlfn.XLOOKUP(E19,'Wk no''s'!B:B,'Wk no''s'!C:C,FALSE) -> 2
A20: PRO-000002816 | B20: 45670 | C20: 100 | D20: Proposal | E20: 45665 | F20: France | G20: =_xlfn.XLOOKUP(E20,'Wk no''s'!B:B,'Wk no''s'!C:C,FALSE) -> 2
A21: PRO-000002834 | B21: 45667 | C21: 100 | D21: Proposal | E21: 45665 | F21: Rest of the World | G21: =_xlfn.XLOOKUP(E21,'Wk no''s'!B:B,'Wk no''s'!C:C,FALSE) -> 2
A22: PRO-000002797 | B22: 45665 | C22: 0 | D22: Proposal | E22: 45666 | F22: UK | G22: =_xlfn.XLOOKUP(E22,'Wk no''s'!B:B,'Wk no''s'!C:C,FALSE) -> 2
A23: PRO-000002798 | B23: 45666 | C23: 100 | D23: Proposal | E23: 45666 | F23: UK | G23: =_xlfn.XLOOKUP(E23,'Wk no''s'!B:B,'Wk no''s'!C:C,FALSE) -> 2
A24: PRO-000002822 | B24: 45667 | C24: 100 | D24: Proposal | E24: 45666 | F24: UK | G24: =_xlfn.XLOOKUP(E24,'Wk no''s'!B:B,'Wk no''s'!C:C,FALSE) -> 2
A25: PRO-000002832 | B25: 45672 | C25: 100 | D25: Proposal | E25: 45666 | F25: UK | G25: =_xlfn.XLOOKUP(E25,'Wk no''s'!B:B,'Wk no''s'!C:C,FALSE) -> 2
A26: PRO-000002781 | B26: 45664 | C26: 0 | D26: Proposal | E26: 45666 | F26: USA | G26: =_xlfn.XLOOKUP(E26,'Wk no''s'!B:B,'Wk no''s'!C:C,FALSE) -> 2
... A45: PRO-000002788 | B45: 45674 | C45: 100 | D45: Shop Drawing | E45: 45672 | F45: UK | G45: =_xlfn.XLOOKUP(E45,'Wk no''s'!B:B,'Wk no''s'!C:C,FALSE) -> 3
A46: PRO-000002843 | C46: 100 | D46: Proposal | E46: 45672 | F46: UK | G46: =_xlfn.XLOOKUP(E46,'Wk no''s'!B:B,'Wk no''s'!C:C,FALSE) -> 3
A47: PRO-000002848 | B47: 45672 | C47: 100 | D47: Proposal | E47: 45672 | F47: UK | G47: =_xlfn.XLOOKUP(E47,'Wk no''s'!B:B,'Wk no''s'!C:C,FALSE) -> 3
A48: PRO-000002825 | B48: 45673 | C48: 100 | D48: Proposal | E48: 45672 | F48: France | G48: =_xlfn.XLOOKUP(E48,'Wk no''s'!B:B,'Wk no''s'!C:C,FALSE) -> 3
A49: PRO-000002857 | B49: 45673 | C49: 100 | D49: Proposal | E49: 45672 | F49: Rest of the World | G49: =_xlfn.XLOOKUP(E49,'Wk no''s'!B:B,'Wk no''s'!C:C,FALSE) -> 3
A50: PRO-000002839 | B50: 45673 | C50: 100 | D50: Proposal | E50: 45673 | F50: UK | G50: =_xlfn.XLOOKUP(E50,'Wk no''s'!B:B,'Wk no''s'!C:C,FALSE) -> 3
A51: PRO-000002858 | B51: 45677 | C51: 100 | D51: Proposal | E51: 45673 | F51: UK | G51: =_xlfn.XLOOKUP(E51,'Wk no''s'!B:B,'Wk no''s'!C:C,FALSE) -> 3
A52: PRO-000002772 | B52: 45673 | C52: 100 | D52: Proposal | E52: 45673 | F52: USA | G52: =_xlfn.XLOOKUP(E52,'Wk no''s'!B:B,'Wk no''s'!C:C,FALSE) -> 3
A53: PRO-000002830 | B53: 45674 | C53: 100 | D53: Shop Drawing | E53: 45673 | F53: USA | G53: =_xlfn.XLOOKUP(E53,'Wk no''s'!B:B,'Wk no''s'!C:C,FALSE) -> 3
A54: PRO-000002850 | C54: 100 | D54: Shop Drawing | E54: 45673 | F54: USA | G54: =_xlfn.XLOOKUP(E54,'Wk no''s'!B:B,'Wk no''s'!C:C,FALSE) -> 3
A55: PRO-000002815 | B55: 45673 | C55: 100 | D55: Proposal | E55: 45673 | F55: Australia | G55: =_xlfn.XLOOKUP(E55,'Wk no''s'!B:B,'Wk no''s'!C:C,FALSE) -> 3
A56: PRO-000002838 | C56: 100 | D56: Shop Drawing | E56: 45673 | F56: Australia | G56: =_xlfn.XLOOKUP(E56,'Wk no''s'!B:B,'Wk no''s'!C:C,FALSE) -> 3
A57: PRO-000002793 | B57: 45681 | C57: 100 | D57: Proposal | E57: 45673 | F57: Rest of the World | G57: =_xlfn.XLOOKUP(E57,'Wk no''s'!B:B,'Wk no''s'!C:C,FALSE) -> 3
A58: PRO-000002823 | B58: 45674 | C58: 100 | D58: Proposal | E58: 45674 | F58: UK | G58: =_xlfn.XLOOKUP(E58,'Wk no''s'!B:B,'Wk no''s'!C:C,FALSE) -> 3
...

Sheet Wk no's
B1: Date | C1: Week No | D1: Date in Text Format
B2: 45658 | C2: 1 | D2: =TEXT(B2,"DD")&"/"&TEXT(B2,"MM")&"/"&TEXT(B2,"YYYY") -> 01/01/2025 | E2: =TEXT(B2,"MMM") -> Jan
B3: =+B2+1 -> 45659 | C3: 1 | D3: =TEXT(B3,"DD")&"/"&TEXT(B3,"MM")&"/"&TEXT(B3,"YYYY") -> 02/01/2025 | E3: =TEXT(B3,"MMM") -> Jan
A4: =TEXT(B4,"ddd") -> Fri | B4: =+B3+1 -> 45660 | C4: =IF(A4="Sat",C3+1,C3) -> 1 | D4: =TEXT(B4,"DD")&"/"&TEXT(B4,"MM")&"/"&TEXT(B4,"YYYY") -> 03/01/2025 | E4: =TEXT(B4,"MMM") -> Jan
A5: =TEXT(B5,"ddd") -> Sat | B5: =+B4+1 -> 45661 | C5: =IF(A5="Sat",C4+1,C4) -> 2 | D5: =TEXT(B5,"DD")&"/"&TEXT(B5,"MM")&"/"&TEXT(B5,"YYYY") -> 04/01/2025 | E5: =TEXT(B5,"MMM") -> Jan
A6: =TEXT(B6,"ddd") -> Sun | B6: =+B5+1 -> 45662 | C6: =IF(A6="Sat",C5+1,C5) -> 2 | D6: =TEXT(B6,"DD")&"/"&TEXT(B6,"MM")&"/"&TEXT(B6,"YYYY") -> 05/01/2025 | E6: =TEXT(B6,"MMM") -> Jan
A7: =TEXT(B7,"ddd") -> Mon | B7: =+B6+1 -> 45663 | C7: =IF(A7="Sat",C6+1,C6) -> 2 | D7: =TEXT(B7,"DD")&"/"&TEXT(B7,"MM")&"/"&TEXT(B7,"YYYY") -> 06/01/2025 | E7: =TEXT(B7,"MMM") -> Jan
A8: =TEXT(B8,"ddd") -> Tue | B8: =+B7+1 -> 45664 | C8: =IF(A8="Sat",C7+1,C7) -> 2 | D8: =TEXT(B8,"DD")&"/"&TEXT(B8,"MM")&"/"&TEXT(B8,"YYYY") -> 07/01/2025 | E8: =TEXT(B8,"MMM") -> Jan
A9: =TEXT(B9,"ddd") -> Wed | B9: =+B8+1 -> 45665 | C9: =IF(A9="Sat",C8+1,C8) -> 2 | D9: =TEXT(B9,"DD")&"/"&TEXT(B9,"MM")&"/"&TEXT(B9,"YYYY") -> 08/01/2025 | E9: =TEXT(B9,"MMM") -> Jan
A10: =TEXT(B10,"ddd") -> Thu | B10: =+B9+1 -> 45666 | C10: =IF(A10="Sat",C9+1,C9) -> 2 | D10: =TEXT(B10,"DD")&"/"&TEXT(B10,"MM")&"/"&TEXT(B10,"YYYY") -> 09/01/2025 | E10: =TEXT(B10,"MMM") -> Jan
A11: =TEXT(B11,"ddd") -> Fri | B11: =+B10+1 -> 45667 | C11: =IF(A11="Sat",C10+1,C10) -> 2 | D11: =TEXT(B11,"DD")&"/"&TEXT(B11,"MM")&"/"&TEXT(B11,"YYYY") -> 10/01/2025 | E11: =TEXT(B11,"MMM") -> Jan
A12: =TEXT(B12,"ddd") -> Sat | B12: =+B11+1 -> 45668 | C12: =IF(A12="Sat",C11+1,C11) -> 3 | D12: =TEXT(B12,"DD")&"/"&TEXT(B12,"MM")&"/"&TEXT(B12,"YYYY") -> 11/01/2025 | E12: =TEXT(B12,"MMM") -> Jan
A13: =TEXT(B13,"ddd") -> Sun | B13: =+B12+1 -> 45669 | C13: =IF(A13="Sat",C12+1,C12) -> 3 | D13: =TEXT(B13,"DD")&"/"&TEXT(B13,"MM")&"/"&TEXT(B13,"YYYY") -> 12/01/2025 | E13: =TEXT(B13,"MMM") -> Jan
A14: =TEXT(B14,"ddd") -> Mon | B14: =+B13+1 -> 45670 | C14: =IF(A14="Sat",C13+1,C13) -> 3 | D14: =TEXT(B14,"DD")&"/"&TEXT(B14,"MM")&"/"&TEXT(B14,"YYYY") -> 13/01/2025 | E14: =TEXT(B14,"MMM") -> Jan
A15: =TEXT(B15,"ddd") -> Tue | B15: =+B14+1 -> 45671 | C15: =IF(A15="Sat",C14+1,C14) -> 3 | D15: =TEXT(B15,"DD")&"/"&TEXT(B15,"MM")&"/"&TEXT(B15,"YYYY") -> 14/01/2025 | E15: =TEXT(B15,"MMM") -> Jan
... A366: =TEXT(B366,"ddd") -> Wed | B366: =+B365+1 -> 46022 | C366: =IF(A366="Sat",C365+1,C365) -> 53 | D366: =TEXT(B366,"DD")&"/"&TEXT(B366,"MM")&"/"&TEXT(B366,"YYYY") -> 31/12/2025 | E366: =TEXT(B366,"MMM") -> Dec
