Workbook

Sheet Analysis
B1: Estimating Department _ KPI build
E2: Week | I2: 28
C4: The power BI reports will be sent by email each Monday
C5: Update the Relevent Green Tab with the data
C6: Check the week number formula in the last row goes to the bottom
C7: Refresh the pivot Table on the relevant Pink Tab
C8: The data should pull through into the Estimating KPI tab - you will need to update the week number in cell E2 to drive the formulas
B10: Avg Quote Time - Power BI Report - Saved on Tab of Same Name
C11: This report shows the hours taken to close an estimate
C12: This feeds the Quality KPI
B14: Estimate Time - Power BI Report - Saved on Tab of Same Name
C15: This report shows the estimates and data on those completed on time
C16: This feeds the Productivity and the Delivery KPI

Sheet Estimating KPIs
B1: Owner | C1: Julian Sparrow
D2: Completed up to week | E2: 42 | F2: update | G2: Data to Sun | N2: =+N7+2 -> 45669 | O2: =+O7+2 -> 45676 | P2: =+P7+2 -> 45683 | Q2: =+Q7+2 -> 45690 | R2: =+R7+2 -> 45697 | S2: =+S7+2 -> 45704 | T2: =+T7+2 -> 45711 | U2: =+U7+2 -> 45718 | ... BM2: =+BM7+2 -> 46026
B4: =IF(E2<(E3),"Overdue","Current") -> Current | D4: Submission | E4: Weekly | M4: =IF(M6>$E$3,"Future",IF(M6>$E$2,"OD",IF($E$2>=M6,"Calc"))) -> Future | N4: =IF(N6>$E$2,"Future",IF(N6>$E$2,"OD",IF($E$2>=N6,"Calc"))) -> Calc | O4: =IF(O6>$E$2,"Future",IF(O6>$E$2,"OD",IF($E$2>=O6,"Calc"))) -> Calc | P4: =IF(P6>$E$2,"Future",IF(P6>$E$2,"OD",IF($E$2>=P6,"Calc"))) -> Calc | Q4: =IF(Q6>$E$2,"Future",IF(Q6>$E$2,"OD",IF($E$2>=Q6,"Calc"))) -> Calc | R4: =IF(R6>$E$2,"Future",IF(R6>$E$2,"OD",IF($E$2>=R6,"Calc"))) -> Calc | S4: =IF(S6>$E$2,"Future",IF(S6>$E$2,"OD",IF($E$2>=S6,"Calc"))) -> Calc | T4: =IF(T6>$E$2,"Future",IF(T6>$E$2,"OD",IF($E$2>=T6,"Calc"))) -> Calc | U4: =IF(U6>$E$2,"Future",IF(U6>$E$2,"OD",IF($E$2>=U6,"Calc"))) -> Calc | ... BM4: =IF(BM6>$E$2,"Future",IF(BM6>$E$2,"OD",IF($E$2>=BM6,"Calc"))) -> Future | BN4: =IF($E$2>=BN6,"Calc",IF(BN6>$E$2,IF(BN12>0,"Not Calc yet","Future"))) -> Future
B6: Department: | C6: HR Monthly | G6: Commentary [in relation to current week, trend and outlook] | H6: Week | I6: =J6-1 -> 49 | J6: =K6-1 -> 50 | K6: =L6-1 -> 51 | L6: 52 | M6: 1 | N6: =M6+1 -> 2 | O6: =N6+1 -> 3 | P6: =O6+1 -> 4 | Q6: =P6+1 -> 5 | R6: =Q6+1 -> 6 | S6: =R6+1 -> 7 | T6: =S6+1 -> 8 | U6: =T6+1 -> 9 | ... BM6: =BL6+1 -> 53 | BN6: YTD
B7: Category | C7: KPI | D7: Measure | E7: UOM | F7: Sign | H7: Date (Fri) | I7: =J7-7 -> 45632 | J7: =K7-7 -> 45639 | K7: =L7-7 -> 45646 | L7: =M7-7 -> 45653 | M7: 45660 | N7: =M7+7 -> 45667 | O7: =N7+7 -> 45674 | P7: =O7+7 -> 45681 | Q7: =P7+7 -> 45688 | R7: =Q7+7 -> 45695 | S7: =R7+7 -> 45702 | T7: =S7+7 -> 45709 | U7: =T7+7 -> 45716 | ... BM7: =BL7+7 -> 46024
B8: Productivity | C8: Quotes Issues | D8: Count of quotes issued | E8: Count | F8: Under Breach | G8: Target Based on Qtr 1 actuals | H8: Target | M8: Blank | N8: =IF(N6>$E$2,"",126) -> 126 | O8: =IF(O6>$E$2,"",126) -> 126 | P8: =IF(P6>$E$2,"",126) -> 126 | Q8: =IF(Q6>$E$2,"",126) -> 126 | R8: =IF(R6>$E$2,"",126) -> 126 | S8: =IF(S6>$E$2,"",126) -> 126 | T8: =IF(T6>$E$2,"",126) -> 126 | U8: =IF(U6>$E$2,"",126) -> 126 | ... BN8: =IF(BN6>$E$2,"",126)
H9: Actual | M9: Blank | N9: =IFERROR(IF(N6>$E$2,"",+GETPIVOTDATA("Count of Estimating Request: Estimate Request No.",'Pivot of Estimate time'!$B$3,"week No",N6)),"No Data") -> 102 | O9: =IFERROR(IF(O6>$E$2,"",+GETPIVOTDATA("Count of Estimating Request: Estimate Request No.",'Pivot of Estimate time'!$B$3,"week No",O6)),"No Data") -> 127 | P9: =IFERROR(IF(P6>$E$2,"",+GETPIVOTDATA("Count of Estimating Request: Estimate Request No.",'Pivot of Estimate time'!$B$3,"week No",P6)),"No Data") -> 106 | Q9: =IFERROR(IF(Q6>$E$2,"",+GETPIVOTDATA("Count of Estimating Request: Estimate Request No.",'Pivot of Estimate time'!$B$3,"week No",Q6)),"No Data") -> 150 | R9: =IFERROR(IF(R6>$E$2,"",+GETPIVOTDATA("Count of Estimating Request: Estimate Request No.",'Pivot of Estimate time'!$B$3,"week No",R6)),"No Data") -> 135 | S9: =IFERROR(IF(S6>$E$2,"",+GETPIVOTDATA("Count of Estimating Request: Estimate Request No.",'Pivot of Estimate time'!$B$3,"week No",S6)),"No Data") -> 133 | T9: =IFERROR(IF(T6>$E$2,"",+GETPIVOTDATA("Count of Estimating Request: Estimate Request No.",'Pivot of Estimate time'!$B$3,"week No",T6)),"No Data") -> 130 | U9: =IFERROR(IF(U6>$E$2,"",+GETPIVOTDATA("Count of Estimating Request: Estimate Request No.",'Pivot of Estimate time'!$B$3,"week No",U6)),"No Data") -> 132 | ... BN9: =IFERROR(IF(BN6>$E$2,"",+GETPIVOTDATA("Count of Estimating Request: Estimate Request No.",'Pivot of Estimate time'!$B$3,"week No",BN6)),"No Data")
H10: Variance | M10: =IF(M9="Blank","Blank",IF(M9="TBC","TBC",IF(M9="Undefined","Undefined",IF(M$4="OD","OD",IF(M$6>$E$2,"",IF((M9-M8)>=0,"G",IF((M9-(M8*0.95))>=0,"A","R"))))))) -> Blank | N10: =IF(N9="Blank","Blank",IF(N9="TBC","TBC",IF(N9="Undefined","Undefined",IF(N$4="OD","OD",IF(N$9="No Data","No Data",IF(N$6>$E$2,"",IF((N9-N8)>=0,"G",IF((N9-(N8*0.95))>=0,"A","R")))))))) -> R | O10: =IF(O9="Blank","Blank",IF(O9="TBC","TBC",IF(O9="Undefined","Undefined",IF(O$4="OD","OD",IF(O$9="No Data","No Data",IF(O$6>$E$2,"",IF((O9-O8)>=0,"G",IF((O9-(O8*0.95))>=0,"A","R")))))))) -> G | P10: =IF(P9="Blank","Blank",IF(P9="TBC","TBC",IF(P9="Undefined","Undefined",IF(P$4="OD","OD",IF(P$9="No Data","No Data",IF(P$6>$E$2,"",IF((P9-P8)>=0,"G",IF((P9-(P8*0.95))>=0,"A","R")))))))) -> R | Q10: =IF(Q9="Blank","Blank",IF(Q9="TBC","TBC",IF(Q9="Undefined","Undefined",IF(Q$4="OD","OD",IF(Q$9="No Data","No Data",IF(Q$6>$E$2,"",IF((Q9-Q8)>=0,"G",IF((Q9-(Q8*0.95))>=0,"A","R")))))))) -> G | R10: =IF(R9="Blank","Blank",IF(R9="TBC","TBC",IF(R9="Undefined","Undefined",IF(R$4="OD","OD",IF(R$9="No Data","No Data",IF(R$6>$E$2,"",IF((R9-R8)>=0,"G",IF((R9-(R8*0.95))>=0,"A","R")))))))) -> G | S10: =IF(S9="Blank","Blank",IF(S9="TBC","TBC",IF(S9="Undefined","Undefined",IF(S$4="OD","OD",IF(S$9="No Data","No Data",IF(S$6>$E$2,"",IF((S9-S8)>=0,"G",IF((S9-(S8*0.95))>=0,"A","R")))))))) -> G | T10: =IF(T9="Blank","Blank",IF(T9="TBC","TBC",IF(T9="Undefined","Undefined",IF(T$4="OD","OD",IF(T$9="No Data","No Data",IF(T$6>$E$2,"",IF((T9-T8)>=0,"G",IF((T9-(T8*0.95))>=0,"A","R")))))))) -> G | U10: =IF(U9="Blank","Blank",IF(U9="TBC","TBC",IF(U9="Undefined","Undefined",IF(U$4="OD","OD",IF(U$9="No Data","No Data",IF(U$6>$E$2,"",IF((U9-U8)>=0,"G",IF((U9-(U8*0.95))>=0,"A","R")))))))) -> G | ... AV10: =IF(AV9="Blank","Blank",IF(AV9="TBC","TBC",IF(AV9="Undefined","Undefined",IF(AV$4="OD","OD",IF(AV$9="No Data","No Data",IF(AV$6>$E$2,"",IF((AV9-AV8)>=0,"G",IF((AV9-(AV8*0.95))>=0,"A","R")))))))) -> R | AW10: =IF(AW9="Blank","Blank", IF(AW9="TBC","TBC", IF(AW9="Undefined","Undefined", IF(AW$4="OD","OD", IF(AW$9="No Data","No Data", IF(AW$6>$E$2,"", IF((AW9-AW8)>=0,"G", IF((AW9-(AW8*0.95))>=0,"A", "R")))))))) -> G | AX10: =IF(AX9="Blank","Blank",IF(AX9="TBC","TBC",IF(AX9="Undefined","Undefined",IF(AX$4="OD","OD",IF(AX$9="No Data","No Data",IF(AX$6>$E$2,"",IF((AX9-AX8)>=0,"G",IF((AX9-(AX8*0.95))>=0,"A","R")))))))) -> R | AY10: =IF(AY9="Blank","Blank",IF(AY9="TBC","TBC",IF(AY9="Undefined","Undefined",IF(AY$4="OD","OD",IF(AY$9="No Data","No Data",IF(AY$6>$E$2,"",IF((AY9-AY8)>=0,"G",IF((AY9-(AY8*0.95))>=0,"A","R")))))))) -> R | AZ10: =IF(AZ9="Blank","Blank",IF(AZ9="TBC","TBC",IF(AZ9="Undefined","Undefined",IF(AZ$4="OD","OD",IF(AZ$9="No Data","No Data",IF(AZ$6>$E$2,"",IF((AZ9-AZ8)>=0,"G",IF((AZ9-(AZ8*0.95))>=0,"A","R")))))))) -> R | BA10: =IF(BA9="Blank","Blank",IF(BA9="TBC","TBC",IF(BA9="Undefined","Undefined",IF(BA$4="OD","OD",IF(BA$9="No Data","No Data",IF(BA$6>$E$2,"",IF((BA9-BA8)>=0,"G",IF((BA9-(BA8*0.95))>=0,"A","R")))))))) -> A | BB10: =IF(BB9="Blank","Blank",IF(BB9="TBC","TBC",IF(BB9="Undefined","Undefined",IF(BB$4="OD","OD",IF(BB$9="No Data","No Data",IF(BB$6>$E$2,"",IF((BB9-BB8)>=0,"G",IF((BB9-(BB8*0.95))>=0,"A","R")))))))) -> A | BC10: =IF(BC9="Blank","Blank",IF(BC9="TBC","TBC",IF(BC9="Undefined","Undefined",IF(BC$4="OD","OD",IF(BC$9="No Data","No Data",IF(BC$6>$E$2,"",IF((BC9-BC8)>=0,"G",IF((BC9-(BC8*0.95))>=0,"A","R")))))))) | BD10: =IF(BD9="Blank","Blank",IF(BD9="TBC","TBC",IF(BD9="Undefined","Undefined",IF(BD$4="OD","OD",IF(BD$9="No Data","No Data",IF(BD$6>$E$2,"",IF((BD9-BD8)>=0,"G",IF((BD9-(BD8*0.95))>=0,"A","R")))))))) | BE10: =IF(BE9="Blank","Blank",IF(BE9="TBC","TBC",IF(BE9="Undefined","Undefined",IF(BE$4="OD","OD",IF(BE$9="No Data","No Data",IF(BE$6>$E$2,"",IF((BE9-BE8)>=0,"G",IF((BE9-(BE8*0.95))>=0,"A","R")))))))) | ... BM10: =IF(BM9="Blank","Blank",IF(BM9="TBC","TBC",IF(BM9="Undefined","Undefined",IF(BM$4="OD","OD",IF(BM$9="No Data","No Data",IF(BM$6>$E$2,"",IF((BM9-BM8)>=0,"G",IF((BM9-(BM8*0.95))>=0,"A","R"))))))))
B11: Delivery | C11: Quotes Issues on Time | D11: Percentage of quotes issues on time (TBC all of export only) | E11: Percentage | F11: Under Breach | G11: Target Based on Qtr 1 actuals | H11: Target | M11: Blank | N11: =IF(N6>$E$2,"",85) -> 85 | O11: =IF(O6>$E$2,"",85) -> 85 | P11: =IF(P6>$E$2,"",85) -> 85 | Q11: =IF(Q6>$E$2,"",85) -> 85 | R11: =IF(R6>$E$2,"",85) -> 85 | S11: =IF(S6>$E$2,"",85) -> 85 | T11: =IF(T6>$E$2,"",85) -> 85 | U11: =IF(U6>$E$2,"",85) -> 85 | ... BN11: =IF(BN6>$E$2,"",85)
H12: Actual | M12: Blank | N12: =IFERROR(IF(N6>$E$2,"",+GETPIVOTDATA("Sum of On Time / Late",'Pivot of Estimate time'!$B$3,"week No",N6)/GETPIVOTDATA("Count of Estimating Request: Estimate Request No.",'Pivot of Estimate time'!$B$3,"week No",N6)*100),"No Data") -> 96.078431 | O12: =IFERROR(IF(O6>$E$2,"",+GETPIVOTDATA("Sum of On Time / Late",'Pivot of Estimate time'!$B$3,"week No",O6)/GETPIVOTDATA("Count of Estimating Request: Estimate Request No.",'Pivot of Estimate time'!$B$3,"week No",O6)*100),"No Data") -> 87.401575 | P12: =IFERROR(IF(P6>$E$2,"",+GETPIVOTDATA("Sum of On Time / Late",'Pivot of Estimate time'!$B$3,"week No",P6)/GETPIVOTDATA("Count of Estimating Request: Estimate Request No.",'Pivot of Estimate time'!$B$3,"week No",P6)*100),"No Data") -> 79.245283 | Q12: =IFERROR(IF(Q6>$E$2,"",+GETPIVOTDATA("Sum of On Time / Late",'Pivot of Estimate time'!$B$3,"week No",Q6)/GETPIVOTDATA("Count of Estimating Request: Estimate Request No.",'Pivot of Estimate time'!$B$3,"week No",Q6)*100),"No Data") -> 84 | R12: =IFERROR(IF(R6>$E$2,"",+GETPIVOTDATA("Sum of On Time / Late",'Pivot of Estimate time'!$B$3,"week No",R6)/GETPIVOTDATA("Count of Estimating Request: Estimate Request No.",'Pivot of Estimate time'!$B$3,"week No",R6)*100),"No Data") -> 85.185185 | S12: =IFERROR(IF(S6>$E$2,"",+GETPIVOTDATA("Sum of On Time / Late",'Pivot of Estimate time'!$B$3,"week No",S6)/GETPIVOTDATA("Count of Estimating Request: Estimate Request No.",'Pivot of Estimate time'!$B$3,"week No",S6)*100),"No Data") -> 87.218045 | T12: =IFERROR(IF(T6>$E$2,"",+GETPIVOTDATA("Sum of On Time / Late",'Pivot of Estimate time'!$B$3,"week No",T6)/GETPIVOTDATA("Count of Estimating Request: Estimate Request No.",'Pivot of Estimate time'!$B$3,"week No",T6)*100),"No Data") -> 87.692308 | U12: =IFERROR(IF(U6>$E$2,"",+GETPIVOTDATA("Sum of On Time / Late",'Pivot of Estimate time'!$B$3,"week No",U6)/GETPIVOTDATA("Count of Estimating Request: Estimate Request No.",'Pivot of Estimate time'!$B$3,"week No",U6)*100),"No Data") -> 86.363636 | ... BM12: =IFERROR(IF(BM6>$E$2,"",+GETPIVOTDATA("Sum of On Time / Late",'Pivot of Estimate time'!$B$3,"week No",BM6)/GETPIVOTDATA("Count of Estimating Request: Estimate Request No.",'Pivot of Estimate time'!$B$3,"week No",BM6)*100),"No Data")
H13: Variance | M13: =IF(M12="Blank","Blank",IF(M12="TBC","TBC",IF(M12="Undefined","Undefined",IF(M$4="OD","OD",IF(M$6>$E$2,"",IF((M12-M11)>=0,"G",IF((M12-(M11*0.95))>=0,"A","R"))))))) -> Blank | N13: =IF(N12="Blank","Blank",IF(N12="TBC","TBC",IF(N12="Undefined","Undefined",IF(N12="No Data","No Data",IF(N$4="OD","OD",IF(N$6>$E$2,"",IF((N12-N11)>=0,"G",IF((N12-(N11*0.95))>=0,"A","R")))))))) -> G | O13: =IF(O12="Blank","Blank",IF(O12="TBC","TBC",IF(O12="Undefined","Undefined",IF(O12="No Data","No Data",IF(O$4="OD","OD",IF(O$6>$E$2,"",IF((O12-O11)>=0,"G",IF((O12-(O11*0.95))>=0,"A","R")))))))) -> G | P13: =IF(P12="Blank","Blank",IF(P12="TBC","TBC",IF(P12="Undefined","Undefined",IF(P12="No Data","No Data",IF(P$4="OD","OD",IF(P$6>$E$2,"",IF((P12-P11)>=0,"G",IF((P12-(P11*0.95))>=0,"A","R")))))))) -> R | Q13: =IF(Q12="Blank","Blank",IF(Q12="TBC","TBC",IF(Q12="Undefined","Undefined",IF(Q12="No Data","No Data",IF(Q$4="OD","OD",IF(Q$6>$E$2,"",IF((Q12-Q11)>=0,"G",IF((Q12-(Q11*0.95))>=0,"A","R")))))))) -> A | R13: =IF(R12="Blank","Blank",IF(R12="TBC","TBC",IF(R12="Undefined","Undefined",IF(R12="No Data","No Data",IF(R$4="OD","OD",IF(R$6>$E$2,"",IF((R12-R11)>=0,"G",IF((R12-(R11*0.95))>=0,"A","R")))))))) -> G | S13: =IF(S12="Blank","Blank",IF(S12="TBC","TBC",IF(S12="Undefined","Undefined",IF(S12="No Data","No Data",IF(S$4="OD","OD",IF(S$6>$E$2,"",IF((S12-S11)>=0,"G",IF((S12-(S11*0.95))>=0,"A","R")))))))) -> G | T13: =IF(T12="Blank","Blank",IF(T12="TBC","TBC",IF(T12="Undefined","Undefined",IF(T12="No Data","No Data",IF(T$4="OD","OD",IF(T$6>$E$2,"",IF((T12-T11)>=0,"G",IF((T12-(T11*0.95))>=0,"A","R")))))))) -> G | U13: =IF(U12="Blank","Blank",IF(U12="TBC","TBC",IF(U12="Undefined","Undefined",IF(U12="No Data","No Data",IF(U$4="OD","OD",IF(U$6>$E$2,"",IF((U12-U11)>=0,"G",IF((U12-(U11*0.95))>=0,"A","R")))))))) -> G | ... BN13: =IF(BN12="Blank","Blank",IF(BN12="TBC","TBC",IF(BN12="Undefined","Undefined",IF(BN12="No Data","No Data",IF(BN$4="OD","OD",IF(BN$6>$E$2,"",IF((BN12-BN11)>=0,"G",IF((BN12-(BN11*0.95))>=0,"A","R"))))))))
B14: Quality | C14: Estimated Hours | D14: Hours used on estimations, (further split by division) | E14: Hours | F14: Over Breach | G14: Target Based on Qtr 1 actuals | H14: Target | M14: Blank | N14: =IF(N6>$E$2,"",28) -> 28 | O14: =IF(O6>$E$2,"",28) -> 28 | P14: =IF(P6>$E$2,"",28) -> 28 | Q14: =IF(Q6>$E$2,"",28) -> 28 | R14: =IF(R6>$E$2,"",28) -> 28 | S14: =IF(S6>$E$2,"",28) -> 28 | T14: =IF(T6>$E$2,"",28) -> 28 | U14: =IF(U6>$E$2,"",28) -> 28 | ... BN14: =IF(BN6>$E$2,"",28)
H15: Actual | M15: Blank | N15: =IFERROR(IF(N6>$E$2,"",+GETPIVOTDATA("Sum of Hours Taken to Close",'Pivot Avg Quote Time '!$B$5,"week No",N6)/GETPIVOTDATA("Count of Estimating Request: Estimate Request No.",'Pivot Avg Quote Time '!$B$5,"week No",N6)),"No Data") -> 60.596774 | O15: =IFERROR(IF(O6>$E$2,"",+GETPIVOTDATA("Sum of Hours Taken to Close",'Pivot Avg Quote Time '!$B$5,"week No",O6)/GETPIVOTDATA("Count of Estimating Request: Estimate Request No.",'Pivot Avg Quote Time '!$B$5,"week No",O6)),"No Data") -> 21.351351 | P15: =IFERROR(IF(P6>$E$2,"",+GETPIVOTDATA("Sum of Hours Taken to Close",'Pivot Avg Quote Time '!$B$5,"week No",P6)/GETPIVOTDATA("Count of Estimating Request: Estimate Request No.",'Pivot Avg Quote Time '!$B$5,"week No",P6)),"No Data") -> 29.637681 | Q15: =IFERROR(IF(Q6>$E$2,"",+GETPIVOTDATA("Sum of Hours Taken to Close",'Pivot Avg Quote Time '!$B$5,"week No",Q6)/GETPIVOTDATA("Count of Estimating Request: Estimate Request No.",'Pivot Avg Quote Time '!$B$5,"week No",Q6)),"No Data") -> 29.119048 | R15: =IFERROR(IF(R6>$E$2,"",+GETPIVOTDATA("Sum of Hours Taken to Close",'Pivot Avg Quote Time '!$B$5,"week No",R6)/GETPIVOTDATA("Count of Estimating Request: Estimate Request No.",'Pivot Avg Quote Time '!$B$5,"week No",R6)),"No Data") -> 32.630769 | S15: =IFERROR(IF(S6>$E$2,"",+GETPIVOTDATA("Sum of Hours Taken to Close",'Pivot Avg Quote Time '!$B$5,"week No",S6)/GETPIVOTDATA("Count of Estimating Request: Estimate Request No.",'Pivot Avg Quote Time '!$B$5,"week No",S6)),"No Data") -> 22.584615 | T15: =IFERROR(IF(T6>$E$2,"",+GETPIVOTDATA("Sum of Hours Taken to Close",'Pivot Avg Quote Time '!$B$5,"week No",T6)/GETPIVOTDATA("Count of Estimating Request: Estimate Request No.",'Pivot Avg Quote Time '!$B$5,"week No",T6)),"No Data") -> 31.144737 | U15: =IFERROR(IF(U6>$E$2,"",+GETPIVOTDATA("Sum of Hours Taken to Close",'Pivot Avg Quote Time '!$B$5,"week No",U6)/GETPIVOTDATA("Count of Estimating Request: Estimate Request No.",'Pivot Avg Quote Time '!$B$5,"week No",U6)),"No Data") -> 19.615385 | ... BN15: =IFERROR(IF(BN6>$E$2,"",+GETPIVOTDATA("Sum of Hours Taken to Close",'Pivot Avg Quote Time '!$B$5,"week No",BN6)/GETPIVOTDATA("Count of Estimating Request: Estimate Request No.",'Pivot Avg Quote Time '!$B$5,"week No",BN6)),"No Data")
H16: Variance | M16: =IF(M15="Blank","Blank",IF(M15="TBC","TBC",IF(M15="Undefined","Undefined",IF(M$4="OD","OD",IF(M$6>$E$2,"",IF((M15-M14)<=0,"G",IF((M15-(M14*0.95))<=0,"A","R"))))))) -> Blank | N16: =IF(N15="Blank","Blank",IF(N15="TBC","TBC",IF(N15="Undefined","Undefined",IF(N15="No data","No Data",IF(N$4="OD","OD",IF(N$6>$E$2,"",IF((N15-N14)<=0,"G",IF((N15-(N14/0.95))<=0,"A","R")))))))) -> R | O16: =IF(O15="Blank","Blank",IF(O15="TBC","TBC",IF(O15="Undefined","Undefined",IF(O15="No data","No Data",IF(O$4="OD","OD",IF(O$6>$E$2,"",IF((O15-O14)<=0,"G",IF((O15-(O14/0.95))<=0,"A","R")))))))) -> G | P16: =IF(P15="Blank","Blank",IF(P15="TBC","TBC",IF(P15="Undefined","Undefined",IF(P15="No data","No Data",IF(P$4="OD","OD",IF(P$6>$E$2,"",IF((P15-P14)<=0,"G",IF((P15-(P14/0.95))<=0,"A","R")))))))) -> R | Q16: =IF(Q15="Blank","Blank",IF(Q15="TBC","TBC",IF(Q15="Undefined","Undefined",IF(Q15="No data","No Data",IF(Q$4="OD","OD",IF(Q$6>$E$2,"",IF((Q15-Q14)<=0,"G",IF((Q15-(Q14/0.95))<=0,"A","R")))))))) -> A | R16: =IF(R15="Blank","Blank",IF(R15="TBC","TBC",IF(R15="Undefined","Undefined",IF(R15="No data","No Data",IF(R$4="OD","OD",IF(R$6>$E$2,"",IF((R15-R14)<=0,"G",IF((R15-(R14/0.95))<=0,"A","R")))))))) -> R | S16: =IF(S15="Blank","Blank",IF(S15="TBC","TBC",IF(S15="Undefined","Undefined",IF(S15="No data","No Data",IF(S$4="OD","OD",IF(S$6>$E$2,"",IF((S15-S14)<=0,"G",IF((S15-(S14/0.95))<=0,"A","R")))))))) -> G | T16: =IF(T15="Blank","Blank",IF(T15="TBC","TBC",IF(T15="Undefined","Undefined",IF(T15="No data","No Data",IF(T$4="OD","OD",IF(T$6>$E$2,"",IF((T15-T14)<=0,"G",IF((T15-(T14/0.95))<=0,"A","R")))))))) -> R | U16: =IF(U15="Blank","Blank",IF(U15="TBC","TBC",IF(U15="Undefined","Undefined",IF(U15="No data","No Data",IF(U$4="OD","OD",IF(U$6>$E$2,"",IF((U15-U14)<=0,"G",IF((U15-(U14/0.95))<=0,"A","R")))))))) -> G | ... BM16: =IF(BM15="Blank","Blank",IF(BM15="TBC","TBC",IF(BM15="Undefined","Undefined",IF(BM15="No data","No Data",IF(BM$4="OD","OD",IF(BM$6>$E$2,"",IF((BM15-BM14)<=0,"G",IF((BM15-(BM14/0.95))<=0,"A","R"))))))))
B17: Cost | C17: Rate of Sales per square meter | D17: Value of sales per Sq meter (Power BI data but excludes those with an item per SQM below 0.03) | E17: £ | F17: Under Breach | G17: Target set but may be reevaluated | H17: Target | M17: Blank | N17: TBC | O17: TBC | P17: TBC | Q17: TBC | R17: TBC | S17: TBC | T17: TBC | U17: TBC | V17: TBC | W17: TBC | X17: TBC | Y17: TBC | Z17: TBC | AA17: TBC | AB17: TBC | AC17: TBC | AD17: TBC | AE17: TBC | AF17: TBC | AG17: TBC | AH17: 75 | AI17: 75 | AJ17: 75 | AK17: 75 | AL17: 75 | AM17: 75 | AN17: 75 | AO17: 75 | AP17: 75 | AQ17: 75 | AR17: 75 | AS17: 75 | AT17: 75 | AU17: 75 | AV17: 75 | AW17: 75 | AX17: 75 | AY17: 75 | AZ17: 75 | BA17: 75 | BB17: 75 | BC17: 0 | BD17: 0 | BE17: 0 | BF17: 0 | BG17: 0 | BH17: 0 | BI17: 0 | BJ17: 0 | BK17: 0 | BL17: 0 | BM17: 0
H18: Actual | M18: Blank | N18: TBC | O18: TBC | P18: TBC | Q18: TBC | R18: TBC | S18: TBC | T18: TBC | U18: TBC | V18: TBC | W18: TBC | X18: TBC | Y18: TBC | Z18: TBC | AA18: TBC | AB18: TBC | AC18: TBC | AD18: TBC | AE18: TBC | AF18: TBC | AG18: TBC | AH18: =+'SQM Wk 22'!N1 -> 75.655769 | AI18: =+' SQM Wk 23'!N1 -> 87.727857 | AJ18: =+'SQM Wk 24'!O1 -> 82.874878 | AK18: =+'SQM Wk 25'!O1 -> 82.126 | AL18: =+'SQM Wk 26'!O1 -> 72.681429 | AM18: =+'SQM WK27'!O1 -> 78.721579 | AN18: =+'SQM WK28'!O1 -> 82.652727 | AO18: =+'SQM WK29'!O1 -> 72.047273 | AP18: =+'SQM WK30'!O1 -> 68.755625 | AQ18: =+'SQM WK31'!O1 -> 103.18844 | AR18: =+'SQM WK32'!O1 -> 69.103333 | AS18: =+'SQM WK33'!O1 -> 77.475625 | AT18: =+'SQM WK 34'!O1 -> 63.224062 | AU18: =+' SQM WK 35'!O1 -> 150.0293 | AV18: =+SQMWK36!O1 -> 70.96 | AW18: =+'SQM WK37'!O1 -> 79.844902 | AX18: =+'SQM WK 38'!O1 -> 79.964756 | AY18: =+'SQM WK39'!O1 -> 107.59414 | AZ18: =+'SQM WK 40'!O1 -> 80.211034 | BA18: =+'SQM WK41'!O1 -> 79.488621 | BB18: =+'SQM WK42'!O1 -> 80.659884
H19: Variance | M19: =IF(M18="Blank","Blank",IF(M18="TBC","TBC",IF(M18="Undefined","Undefined",IF(M$4="OD","OD",IF(M$6>$E$2,"",IF((M18-M17)>=0,"G",IF((M18-(M17*0.95))>=0,"A","R"))))))) -> Blank | N19: =IF(N18="Blank","Blank",IF(N18="TBC","TBC",IF(N18="Undefined","Undefined",IF(N$4="OD","OD",IF(N$6>$E$2,"",IF((N18-N17)>=0,"G",IF((N18-(N17*0.95))>=0,"A","R"))))))) -> TBC | O19: =IF(O18="Blank","Blank",IF(O18="TBC","TBC",IF(O18="Undefined","Undefined",IF(O$4="OD","OD",IF(O$6>$E$2,"",IF((O18-O17)>=0,"G",IF((O18-(O17*0.95))>=0,"A","R"))))))) -> TBC | P19: =IF(P18="Blank","Blank",IF(P18="TBC","TBC",IF(P18="Undefined","Undefined",IF(P$4="OD","OD",IF(P$6>$E$2,"",IF((P18-P17)>=0,"G",IF((P18-(P17*0.95))>=0,"A","R"))))))) -> TBC | Q19: =IF(Q18="Blank","Blank",IF(Q18="TBC","TBC",IF(Q18="Undefined","Undefined",IF(Q$4="OD","OD",IF(Q$6>$E$2,"",IF((Q18-Q17)>=0,"G",IF((Q18-(Q17*0.95))>=0,"A","R"))))))) -> TBC | R19: =IF(R18="Blank","Blank",IF(R18="TBC","TBC",IF(R18="Undefined","Undefined",IF(R$4="OD","OD",IF(R$6>$E$2,"",IF((R18-R17)>=0,"G",IF((R18-(R17*0.95))>=0,"A","R"))))))) -> TBC | S19: =IF(S18="Blank","Blank",IF(S18="TBC","TBC",IF(S18="Undefined","Undefined",IF(S$4="OD","OD",IF(S$6>$E$2,"",IF((S18-S17)>=0,"G",IF((S18-(S17*0.95))>=0,"A","R"))))))) -> TBC | T19: =IF(T18="Blank","Blank",IF(T18="TBC","TBC",IF(T18="Undefined","Undefined",IF(T$4="OD","OD",IF(T$6>$E$2,"",IF((T18-T17)>=0,"G",IF((T18-(T17*0.95))>=0,"A","R"))))))) -> TBC | ... BM19: =IF(BM18="Blank","Blank",IF(BM18="TBC","TBC",IF(BM18="Undefined","Undefined",IF(BM$4="OD","OD",IF(BM$6>$E$2,"",IF((BM18-BM17)>=0,"G",IF((BM18-(BM17*0.95))>=0,"A","R")))))))
B21: R | C21: KPI is worse than Target | N21: Avg wek 1-13 used as target | Z21: The targets above are the avg of Q1 2025
B22: A | C22: KPI is <5% worse than Target | N22: =AVERAGE(N9:Y9) -> 126.83333 | Z22: But can be reset if needed
B23: G | C23: KPI is better than Target | N23: =AVERAGE(N12:Y12) -> 84.54126
B24: TBC | C24: Missing Submission | N24: =AVERAGE(N15:Y15) -> 28.704464 | Z24: The cost KPI isnt yet being reported - the above actual values are done by removing those £SQ meter below 0.03 on the power BI report
B25: Blank | C25: No Submission | Z25: But awaiting your work this week before updating the actual report

Sheet Pivot Avg Quote Time 
B3: Blank | C3: (Multiple Items)
B5: Row Labels | C5: Count of Estimating Request: Estimate Request No. | D5: Sum of Hours Taken to Close
B6: (blank)
B7: 2 | C7: 62 | D7: 3757
B8: 3 | C8: 74 | D8: 1580
B9: 4 | C9: 69 | D9: 2045
B10: 5 | C10: 84 | D10: 2446
B11: 6 | C11: 65 | D11: 2121
B12: 7 | C12: 65 | D12: 1468
B13: 8 | C13: 76 | D13: 2367
B14: 9 | C14: 78 | D14: 1530
B15: 10 | C15: 81 | D15: 1719
B16: 11 | C16: 62 | D16: 1154
B17: 12 | C17: 80 | D17: 2489
B18: 13 | C18: 86 | D18: 2307
... B47: 42 | C47: 62 | D47: 1624
B48: Grand Total | C48: 2663 | D48: 82849

Sheet Pivot of Estimate time
B1: On Time / Late | C1: (All)
B3: Row Labels | C3: Sum of On Time / Late | D3: Count of Estimating Request: Estimate Request No.
B4: FALSE | C4: 0 | D4: 1
B5: (blank)
B6: 2 | C6: 98 | D6: 102
B7: 3 | C7: 111 | D7: 127
B8: 4 | C8: 84 | D8: 106
B9: 5 | C9: 126 | D9: 150
B10: 6 | C10: 115 | D10: 135
B11: 7 | C11: 116 | D11: 133
B12: 8 | C12: 114 | D12: 130
B13: 9 | C13: 114 | D13: 132
B14: 10 | C14: 95 | D14: 124
B15: 11 | C15: 106 | D15: 119
B16: 12 | C16: 92 | D16: 124
B17: 13 | C17: 114 | D17: 140
... B46: 42 | C46: 101 | D46: 123
B47: Grand Total | C47: 3894 | D47: 4929

Sheet Avg Quote Time
A1: Estimating Request: Estimate Request No. | B1: Hours Taken to Close | C1: Date/Time Closed | D1: Sales Division | E1: Blank | F1: week No
A2: EST-000029602 | C2: 45664 | D2: Australia | E2: =IF(B2=0,"Blank","Not Blank") -> Blank | F2: =_xlfn.XLOOKUP(C2,'Wk no''s'!B:B,'Wk no''s'!C:C,FALSE) -> 2
A3: EST-000029181 | B3: 136 | C3: 45665 | D3: France | E3: =IF(B3=0,"Blank","Not Blank") -> Not Blank | F3: =_xlfn.XLOOKUP(C3,'Wk no''s'!B:B,'Wk no''s'!C:C,FALSE) -> 2
A4: EST-000027498 | C4: 45667 | D4: Ireland | E4: =IF(B4=0,"Blank","Not Blank") -> Blank | F4: =_xlfn.XLOOKUP(C4,'Wk no''s'!B:B,'Wk no''s'!C:C,FALSE) -> 2
A5: EST-000029222 | C5: 45667 | D5: Ireland | E5: =IF(B5=0,"Blank","Not Blank") -> Blank | F5: =_xlfn.XLOOKUP(C5,'Wk no''s'!B:B,'Wk no''s'!C:C,FALSE) -> 2
A6: EST-000029242 | C6: 45667 | D6: Ireland | E6: =IF(B6=0,"Blank","Not Blank") -> Blank | F6: =_xlfn.XLOOKUP(C6,'Wk no''s'!B:B,'Wk no''s'!C:C,FALSE) -> 2
A7: EST-000029264 | C7: 45667 | D7: Ireland | E7: =IF(B7=0,"Blank","Not Blank") -> Blank | F7: =_xlfn.XLOOKUP(C7,'Wk no''s'!B:B,'Wk no''s'!C:C,FALSE) -> 2
A8: EST-000029366 | C8: 45667 | D8: Ireland | E8: =IF(B8=0,"Blank","Not Blank") -> Blank | F8: =_xlfn.XLOOKUP(C8,'Wk no''s'!B:B,'Wk no''s'!C:C,FALSE) -> 2
A9: EST-000029486 | C9: 45667 | D9: Ireland | E9: =IF(B9=0,"Blank","Not Blank") -> Blank | F9: =_xlfn.XLOOKUP(C9,'Wk no''s'!B:B,'Wk no''s'!C:C,FALSE) -> 2
A10: EST-000029544 | C10: 45663 | D10: Ireland | E10: =IF(B10=0,"Blank","Not Blank") -> Blank | F10: =_xlfn.XLOOKUP(C10,'Wk no''s'!B:B,'Wk no''s'!C:C,FALSE) -> 2
A11: EST-000029536 | C11: 45663 | D11: Ireland | E11: =IF(B11=0,"Blank","Not Blank") -> Blank | F11: =_xlfn.XLOOKUP(C11,'Wk no''s'!B:B,'Wk no''s'!C:C,FALSE) -> 2
A12: EST-000029538 | C12: 45663 | D12: Ireland | E12: =IF(B12=0,"Blank","Not Blank") -> Blank | F12: =_xlfn.XLOOKUP(C12,'Wk no''s'!B:B,'Wk no''s'!C:C,FALSE) -> 2
A13: EST-000029558 | C13: 45663 | D13: Ireland | E13: =IF(B13=0,"Blank","Not Blank") -> Blank | F13: =_xlfn.XLOOKUP(C13,'Wk no''s'!B:B,'Wk no''s'!C:C,FALSE) -> 2
A14: EST-000029569 | C14: 45664 | D14: Ireland | E14: =IF(B14=0,"Blank","Not Blank") -> Blank | F14: =_xlfn.XLOOKUP(C14,'Wk no''s'!B:B,'Wk no''s'!C:C,FALSE) -> 2
A15: EST-000029594 | C15: 45664 | D15: Ireland | E15: =IF(B15=0,"Blank","Not Blank") -> Blank | F15: =_xlfn.XLOOKUP(C15,'Wk no''s'!B:B,'Wk no''s'!C:C,FALSE) -> 2
... A23: EST-000029778 | C23: 45667 | D23: Ireland | E23: =IF(B23=0,"Blank","Not Blank") -> Blank | F23: =_xlfn.XLOOKUP(C23,'Wk no''s'!B:B,'Wk no''s'!C:C,FALSE) -> 2
A24: EST-000028482 | B24: 280 | C24: 45664 | D24: Middle East | E24: =IF(B24=0,"Blank","Not Blank") -> Not Blank | F24: =_xlfn.XLOOKUP(C24,'Wk no''s'!B:B,'Wk no''s'!C:C,FALSE) -> 2
A25: EST-000028764 | B25: 232 | C25: 45664 | D25: Middle East | E25: =IF(B25=0,"Blank","Not Blank") -> Not Blank | F25: =_xlfn.XLOOKUP(C25,'Wk no''s'!B:B,'Wk no''s'!C:C,FALSE) -> 2
A26: EST-000029302 | B26: 128 | C26: 45663 | D26: Middle East | E26: =IF(B26=0,"Blank","Not Blank") -> Not Blank | F26: =_xlfn.XLOOKUP(C26,'Wk no''s'!B:B,'Wk no''s'!C:C,FALSE) -> 2
A27: EST-000029532 | B27: 8 | C27: 45664 | D27: Middle East | E27: =IF(B27=0,"Blank","Not Blank") -> Not Blank | F27: =_xlfn.XLOOKUP(C27,'Wk no''s'!B:B,'Wk no''s'!C:C,FALSE) -> 2
A28: EST-000029533 | B28: 0 | C28: 45663 | D28: Middle East | E28: =IF(B28=0,"Blank","Not Blank") -> Blank | F28: =_xlfn.XLOOKUP(C28,'Wk no''s'!B:B,'Wk no''s'!C:C,FALSE) -> 2
A29: EST-000029534 | B29: 8 | C29: 45664 | D29: Middle East | E29: =IF(B29=0,"Blank","Not Blank") -> Not Blank | F29: =_xlfn.XLOOKUP(C29,'Wk no''s'!B:B,'Wk no''s'!C:C,FALSE) -> 2
A30: EST-000029628 | B30: 24 | C30: 45667 | D30: Middle East | E30: =IF(B30=0,"Blank","Not Blank") -> Not Blank | F30: =_xlfn.XLOOKUP(C30,'Wk no''s'!B:B,'Wk no''s'!C:C,FALSE) -> 2
A31: EST-000029667 | B31: 8 | C31: 45667 | D31: Middle East | E31: =IF(B31=0,"Blank","Not Blank") -> Not Blank | F31: =_xlfn.XLOOKUP(C31,'Wk no''s'!B:B,'Wk no''s'!C:C,FALSE) -> 2
A32: EST-000029687 | B32: 8 | C32: 45667 | D32: Middle East | E32: =IF(B32=0,"Blank","Not Blank") -> Not Blank | F32: =_xlfn.XLOOKUP(C32,'Wk no''s'!B:B,'Wk no''s'!C:C,FALSE) -> 2
A33: EST-000029717 | B33: 8 | C33: 45667 | D33: Middle East | E33: =IF(B33=0,"Blank","Not Blank") -> Not Blank | F33: =_xlfn.XLOOKUP(C33,'Wk no''s'!B:B,'Wk no''s'!C:C,FALSE) -> 2
A34: EST-000028580 | B34: 256 | C34: 45663 | D34: Rest of the World | E34: =IF(B34=0,"Blank","Not Blank") -> Not Blank | F34: =_xlfn.XLOOKUP(C34,'Wk no''s'!B:B,'Wk no''s'!C:C,FALSE) -> 2
A35: EST-000029353 | B35: 105 | C35: 45663 | D35: Rest of the World | E35: =IF(B35=0,"Blank","Not Blank") -> Not Blank | F35: =_xlfn.XLOOKUP(C35,'Wk no''s'!B:B,'Wk no''s'!C:C,FALSE) -> 2
... A41: EST-000029587 | B41: -7 | C41: 45664 | D41: Rest of the World | E41: =IF(B41=0,"Blank","Not Blank") -> Not Blank | F41: =_xlfn.XLOOKUP(C41,'Wk no''s'!B:B,'Wk no''s'!C:C,FALSE) -> 2
A42: EST-000029643 | C42: 45667 | D42: Rest of the World | E42: =IF(B42=0,"Blank","Not Blank") -> Blank | F42: =_xlfn.XLOOKUP(C42,'Wk no''s'!B:B,'Wk no''s'!C:C,FALSE) -> 2
A43: EST-000029647 | B43: 0 | C43: 45665 | D43: Rest of the World | E43: =IF(B43=0,"Blank","Not Blank") -> Blank | F43: =_xlfn.XLOOKUP(C43,'Wk no''s'!B:B,'Wk no''s'!C:C,FALSE) -> 2
A44: EST-000029685 | C44: 45665 | D44: Rest of the World | E44: =IF(B44=0,"Blank","Not Blank") -> Blank | F44: =_xlfn.XLOOKUP(C44,'Wk no''s'!B:B,'Wk no''s'!C:C,FALSE) -> 2
A45: EST-000029699 | C45: 45667 | D45: Rest of the World | E45: =IF(B45=0,"Blank","Not Blank") -> Blank | F45: =_xlfn.XLOOKUP(C45,'Wk no''s'!B:B,'Wk no''s'!C:C,FALSE) -> 2
A46: EST-000028931 | B46: 128 | C46: 45664 | D46: UK | E46: =IF(B46=0,"Blank","Not Blank") -> Not Blank | F46: =_xlfn.XLOOKUP(C46,'Wk no''s'!B:B,'Wk no''s'!C:C,FALSE) -> 2
A47: EST-000028937 | B47: 192 | C47: 45667 | D47: UK | E47: =IF(B47=0,"Blank","Not Blank") -> Not Blank | F47: =_xlfn.XLOOKUP(C47,'Wk no''s'!B:B,'Wk no''s'!C:C,FALSE) -> 2
A48: EST-000029411 | B48: 0 | C48: 45664 | D48: UK | E48: =IF(B48=0,"Blank","Not Blank") -> Blank | F48: =_xlfn.XLOOKUP(C48,'Wk no''s'!B:B,'Wk no''s'!C:C,FALSE) -> 2
A49: EST-000029477 | B49: 112 | C49: 45665 | D49: UK | E49: =IF(B49=0,"Blank","Not Blank") -> Not Blank | F49: =_xlfn.XLOOKUP(C49,'Wk no''s'!B:B,'Wk no''s'!C:C,FALSE) -> 2
A50: EST-000029487 | B50: 128 | C50: 45667 | D50: UK | E50: =IF(B50=0,"Blank","Not Blank") -> Not Blank | F50: =_xlfn.XLOOKUP(C50,'Wk no''s'!B:B,'Wk no''s'!C:C,FALSE) -> 2
A51: EST-000029510 | C51: 45663 | D51: UK | E51: =IF(B51=0,"Blank","Not Blank") -> Blank | F51: =_xlfn.XLOOKUP(C51,'Wk no''s'!B:B,'Wk no''s'!C:C,FALSE) -> 2
A52: EST-000029506 | B52: 97 | C52: 45665 | D52: UK | E52: =IF(B52=0,"Blank","Not Blank") -> Not Blank | F52: =_xlfn.XLOOKUP(C52,'Wk no''s'!B:B,'Wk no''s'!C:C,FALSE) -> 2
...

Sheet Estimating on time
A1: Estimating Request: Estimate Request No. | B1: Project Name | C1: Estimating Request: Owner Name | D1: Complete By Date | E1: Date/Time Closed | F1: On Time / Late | G1: Date Closed | H1: Sales Division | I1: Extract Date | J1: week No
A2: EST-000034253 | B2: BRINDLEY PLACE NO 2 EXTENSION BIRMINGHAM | C2: Estimating | D2: 45814 | F2: 0 | H2: UK | I2: =LEFT(G2,10) | J2: =_xlfn.XLOOKUP(I2,'Wk no''s'!D:D,'Wk no''s'!C:C,FALSE) -> FALSE
A3: EST-000029558 | B3: AIRBUS FITOUT 5TH FLOOR GEORGES DOCK 5 & 6 DUBLIN | C3: Venees Ling | D3: 45664 | E3: 45663 | F3: 1 | G3: 06/01/2025, 12:14 | H3: Ireland | I3: =LEFT(G3,10) -> 06/01/2025 | J3: =_xlfn.XLOOKUP(I3,'Wk no''s'!D:D,'Wk no''s'!C:C,FALSE) -> 2
A4: EST-000029544 | B4: ASTELLAS PROJECT ABLE TRALEE KERRY | C4: Venees Ling | D4: 45664 | E4: 45663 | F4: 1 | G4: 06/01/2025, 09:11 | H4: Ireland | I4: =LEFT(G4,10) -> 06/01/2025 | J4: =_xlfn.XLOOKUP(I4,'Wk no''s'!D:D,'Wk no''s'!C:C,FALSE) -> 2
A5: EST-000029778 | B5: DUBLIN AIRPORT T1 MEZZANINE LOUNGE | C5: Venees Ling | D5: 45670 | E5: 45667 | F5: 1 | G5: 10/01/2025, 14:20 | H5: Ireland | I5: =LEFT(G5,10) -> 10/01/2025 | J5: =_xlfn.XLOOKUP(I5,'Wk no''s'!D:D,'Wk no''s'!C:C,FALSE) -> 2
A6: EST-000029536 | B6: DUBLIN AIRPORT T1 MEZZANINE LOUNGE | C6: Venees Ling | D6: 45664 | E6: 45663 | F6: 1 | G6: 06/01/2025, 16:14 | H6: Ireland | I6: =LEFT(G6,10) -> 06/01/2025 | J6: =_xlfn.XLOOKUP(I6,'Wk no''s'!D:D,'Wk no''s'!C:C,FALSE) -> 2
A7: EST-000029538 | B7: IPUT 3 DUBLIN LANDINGS | C7: Venees Ling | D7: 45664 | E7: 45663 | F7: 1 | G7: 06/01/2025, 08:41 | H7: Ireland | I7: =LEFT(G7,10) -> 06/01/2025 | J7: =_xlfn.XLOOKUP(I7,'Wk no''s'!D:D,'Wk no''s'!C:C,FALSE) -> 2
A8: EST-000029714 | B8: PORTLAOISE GARDA DIVISIONAL HQ | C8: Venees Ling | D8: 45667 | E8: 45666 | F8: 1 | G8: 09/01/2025, 11:06 | H8: Ireland | I8: =LEFT(G8,10) -> 09/01/2025 | J8: =_xlfn.XLOOKUP(I8,'Wk no''s'!D:D,'Wk no''s'!C:C,FALSE) -> 2
A9: EST-000029760 | B9: PPG SHANNON CO CLARE | C9: Venees Ling | D9: 45670 | E9: 45667 | F9: 1 | G9: 10/01/2025, 09:53 | H9: Ireland | I9: =LEFT(G9,10) -> 10/01/2025 | J9: =_xlfn.XLOOKUP(I9,'Wk no''s'!D:D,'Wk no''s'!C:C,FALSE) -> 2
A10: EST-000029678 | B10: RDS ANGLESEA STAND BALLSBRIDGE | C10: Venees Ling | D10: 45666 | E10: 45666 | F10: 1 | G10: 09/01/2025, 10:51 | H10: Ireland | I10: =LEFT(G10,10) -> 09/01/2025 | J10: =_xlfn.XLOOKUP(I10,'Wk no''s'!D:D,'Wk no''s'!C:C,FALSE) -> 2
A11: EST-000029628 | B11: ELSEWEDY CABLE TELECOM ADMIN BLDG RAMADAN EGYPT | C11: Christine Moring | D11: 45666 | E11: 45667 | F11: 0 | G11: 10/01/2025, 15:09 | H11: Middle East | I11: =LEFT(G11,10) -> 10/01/2025 | J11: =_xlfn.XLOOKUP(I11,'Wk no''s'!D:D,'Wk no''s'!C:C,FALSE) -> 2
A12: EST-000029717 | B12: EXPO CITY MICRO OFFICES DUBAI | C12: Christine Moring | D12: 45671 | E12: 45667 | F12: 1 | G12: 10/01/2025, 10:32 | H12: Middle East | I12: =LEFT(G12,10) -> 10/01/2025 | J12: =_xlfn.XLOOKUP(I12,'Wk no''s'!D:D,'Wk no''s'!C:C,FALSE) -> 2
A13: EST-000029532 | B13: EXPO CITY MICRO OFFICES DUBAI | C13: Christine Moring | D13: 45666 | E13: 45664 | F13: 1 | G13: 07/01/2025, 11:39 | H13: Middle East | I13: =LEFT(G13,10) -> 07/01/2025 | J13: =_xlfn.XLOOKUP(I13,'Wk no''s'!D:D,'Wk no''s'!C:C,FALSE) -> 2
A14: EST-000029533 | B14: NDA - DEWA HQ TROX TILES DUBAI | C14: Julian Sparrow | D14: 45666 | E14: 45663 | F14: 1 | G14: 06/01/2025, 15:30 | H14: Middle East | I14: =LEFT(G14,10) -> 06/01/2025 | J14: =_xlfn.XLOOKUP(I14,'Wk no''s'!D:D,'Wk no''s'!C:C,FALSE) -> 2
... A4930: EST-000037614 | B4930: WHITE STREET 124-125 | C4930: Ian Liegeois | D4930: 45936 | E4930: 45944 | F4930: 0 | G4930: 14/10/2025, 21:45 | H4930: USA | I4930: =LEFT(G4930,10) -> 14/10/2025 | J4930: =_xlfn.XLOOKUP(I4930,'Wk no''s'!D:D,'Wk no''s'!C:C,FALSE) -> 42

Sheet SQM WK42
A1: Line Name | B1: Quantity | C1: Net Unit Price Currency | D1: Net Unit Price | E1: Net Total Currency | F1: Net Total | G1: Item SQM | H1: Line SQM | I1: Â£/SQM Currency | J1: Â£/SQM | K1: Description | L1: Project Owner: Full Name | M1: Sales Region | N1: Project Name | O1: =AVERAGE(O2:O87) -> 80.659884 | P1: =AVERAGE(P2:P87) -> 80.602823
A2: QL-0326303 | B2: 95 | C2: GBP | D2: 28.8 | E2: GBP | F2: 2736 | G2: 0.36 | H2: 34.2 | I2: GBP | J2: 80 | K2: SYS 330 TILE STEEL 1200mm X 300mm S1820 10 RAL 9010 20% WRAPPED 16 80 KG SQUARE | L2: Becky Titley | M2: Scotland | N2: ROCKSTAR BARCLAY HOUSE PHASE 4 GF FACILITIES EDINBURGH | O2: =IF(G2<0.03,"",J2) -> 80 | P2: =+F2/H2 -> 80
A3: QL-0324166 | B3: 867 | C3: GBP | D3: 25.12 | E3: GBP | F3: 21779.04 | G3: 0.36 | H3: 312.12 | I3: GBP | J3: 69.78 | K3: SYS 330 TILE STEEL 1200mm X 300mm 1522 10 RAL 9010 20% WRAPPED 16 80 KG SQUARE | L3: Ben Bishop | M3: Northern Home Counties | N3: GROVE BUSINESS PARK BLOCKS E F AND G OXFORD | O3: =IF(G3<0.03,"",J3) -> 69.78 | P3: =+F3/H3 -> 69.777778
A4: QL-0256352 | B4: 1246 | C4: GBP | D4: 17.99 | E4: GBP | F4: 22415.54 | G4: 0.33 | H4: 411.18 | I4: GBP | J4: 54.52 | K4: SYS 330 TILE STEEL 1100mm X 300mm 1522 10 RAL 9010 20% BLACK ADHESIVE TISSUE SQUARE (RAL TBC) | L4: David Baylis | M4: North | N4: BANK HOUSE REDEVELOPMENT LEEDS | O4: =IF(G4<0.03,"",J4) -> 54.52 | P4: =+F4/H4 -> 54.515152
A5: QL-0256366 | B5: 363 | C5: GBP | D5: 17.99 | E5: GBP | F5: 6530.37 | G5: 0.33 | H5: 119.79 | I5: GBP | J5: 54.52 | K5: SYS 330 TILE STEEL 1100mm X 300mm 1522 10 RAL 9010 20% BLACK ADHESIVE TISSUE SQUARE (RAL TBC) | L5: David Baylis | M5: North | N5: BANK HOUSE REDEVELOPMENT LEEDS | O5: =IF(G5<0.03,"",J5) -> 54.52 | P5: =+F5/H5 -> 54.515152
A6: QL-0321142 | B6: 90 | C6: GBP | D6: 65.7 | E6: GBP | F6: 5913 | G6: 0.9 | H6: 81 | I6: GBP | J6: 73 | K6: SYS 330 TILE STEEL 1500mm X 600mm 1522 10 RAL 9010 20% WRAPPED 16 80 KG SQUARE | L6: David Baylis | M6: Wales | N6: WREXHAM AFC KOP STAND GROUND FLOOR | O6: =IF(G6<0.03,"",J6) -> 73 | P6: =+F6/H6 -> 73
A7: QL-0328271 | B7: 30 | C7: GBP | D7: 36.41 | E7: GBP | F7: 1092.3 | G7: 0.27 | H7: 8.09 | I7: GBP | J7: 135 | K7: SYS 330 TILE STEEL 899mm X 300mm D1821 10 RAL 9016 20% WRAPPED 16 80 KG SQUARE | L7: Eurshell Fearon | M7: London | N7: MOORFIELDS NO 21 DEUTSCHE BANK REFURB LONDON | O7: =IF(G7<0.03,"",J7) -> 135 | P7: =+F7/H7 -> 135.01854
A8: QL-0328272 | B8: 14 | C8: GBP | D8: 54.43 | E8: GBP | F8: 762.02 | G8: 0.4 | H8: 5.64 | I8: GBP | J8: 135 | K8: SYS 330 TILE STEEL 1344mm X 300mm D1821 10 RAL 9016 20% WRAPPED 16 80 KG SQUARE | L8: Eurshell Fearon | M8: London | N8: MOORFIELDS NO 21 DEUTSCHE BANK REFURB LONDON | O8: =IF(G8<0.03,"",J8) -> 135 | P8: =+F8/H8 -> 135.10993
A9: QL-0328273 | B9: 5 | C9: GBP | D9: 26.28 | E9: GBP | F9: 131.4 | G9: 0.19 | H9: 0.97 | I9: GBP | J9: 134.98 | K9: SYS 330 TILE STEEL 649mm X 300mm D1821 10 RAL 9016 20% WRAPPED 16 80 KG SQUARE | L9: Eurshell Fearon | M9: London | N9: MOORFIELDS NO 21 DEUTSCHE BANK REFURB LONDON | O9: =IF(G9<0.03,"",J9) -> 134.98 | P9: =+F9/H9 -> 135.46392
A10: QL-0328278 | B10: 10 | C10: GBP | D10: 72.86 | E10: GBP | F10: 728.6 | G10: 0.54 | H10: 5.4 | I10: GBP | J10: 135 | K10: SYS 330 TILE STEEL 1799mm X 300mm D1821 10 RAL 9016 20% WRAPPED 16 80 KG SQUARE | L10: Eurshell Fearon | M10: London | N10: MOORFIELDS NO 21 DEUTSCHE BANK REFURB LONDON | O10: =IF(G10<0.03,"",J10) -> 135 | P10: =+F10/H10 -> 134.92593
A11: QL-0328279 | B11: 2 | C11: GBP | D11: 44.51 | E11: GBP | F11: 89.02 | G11: 0.33 | H11: 0.66 | I11: GBP | J11: 135 | K11: SYS 330 TILE STEEL 1099mm X 300mm D1821 10 RAL 9016 20% WRAPPED 16 80 KG SQUARE | L11: Eurshell Fearon | M11: London | N11: MOORFIELDS NO 21 DEUTSCHE BANK REFURB LONDON | O11: =IF(G11<0.03,"",J11) -> 135 | P11: =+F11/H11 -> 134.87879
A12: QL-0328277 | B12: 6 | C12: GBP | D12: 36.41 | E12: GBP | F12: 218.46 | G12: 0.27 | H12: 1.62 | I12: GBP | J12: 135 | K12: SYS 330 TILE STEEL 899mm X 300mm D1821 10 RAL 9016 20% WRAPPED 16 80 KG SQUARE | L12: Eurshell Fearon | M12: London | N12: MOORFIELDS NO 21 DEUTSCHE BANK REFURB LONDON | O12: =IF(G12<0.03,"",J12) -> 135 | P12: =+F12/H12 -> 134.85185
A13: QL-0328282 | B13: 9 | C13: GBP | D13: 36.41 | E13: GBP | F13: 327.69 | G13: 0.27 | H13: 2.43 | I13: GBP | J13: 135 | K13: SYS 330 TILE STEEL 899mm X 300mm D1821 10 RAL 9016 20% WRAPPED 16 80 KG SQUARE | L13: Eurshell Fearon | M13: London | N13: MOORFIELDS NO 21 DEUTSCHE BANK REFURB LONDON | O13: =IF(G13<0.03,"",J13) -> 135 | P13: =+F13/H13 -> 134.85185
... A121: QL-0328671 | B121: 162 | C121: GBP | D121: 95.72 | E121: GBP | F121: 15506.64 | G121: 1.4 | H121: 226.8 | I121: GBP | J121: 68.37 | K121: SYS 330 TILE STEEL 2800mm X 500mm 2227 10 RAL 9010 20% WRAPPED 16 80 KG SQUARE | L121: Sam James | M121: London | N121: RADSTOCK HOUSE ECCLESTON STREET NO 3-5 LONDON | O121: =IF(G121<0.03,"",J121) -> 68.37 | P121: =+F121/H121 -> 68.371429

Sheet SQM WK41
A1: Line Name | B1: Quantity | C1: Net Unit Price Currency | D1: Net Unit Price | E1: Net Total Currency | F1: Net Total | G1: Item SQM | H1: Line SQM | I1: Â£/SQM Currency | J1: Â£/SQM | K1: Description | L1: Project Owner: Full Name | M1: Sales Region | N1: Project Name | O1: =AVERAGE(O2:O87) -> 79.488621 | P1: =AVERAGE(P2:P87) -> 79.420119
A2: QL-0320155 | B2: 3778 | C2: GBP | D2: 25.25 | E2: GBP | F2: 95394.5 | G2: 0.36 | H2: 1360.08 | I2: GBP | J2: 70.14 | K2: SYS 330 TILE STEEL 1200mm X 300mm 1522 10 RAL 9010 20% AB WRAPPED 16 80 KG SQUARE | L2: Ben Bishop | M2: Northern Home Counties | N2: PROJECT VITRUM FLRS 1 & 2 CAMBRIDGE | O2: =IF(G2<0.03,"",J2) -> 70.14 | P2: =+F2/H2 -> 70.138889
A3: QL-0320174 | B3: 5 | C3: GBP | D3: 46.33 | E3: GBP | F3: 231.65 | G3: 0.35 | H3: 1.73 | I3: GBP | J3: 134.25 | K3: SYS 330 TILE STEEL 1190mm X 290mm PLAIN RAL 9010 20% AB NO INFILL SERVICE TILE CS-07 FUME HOOD | L3: Ben Bishop | M3: Northern Home Counties | N3: PROJECT VITRUM FLRS 1 & 2 CAMBRIDGE | O3: =IF(G3<0.03,"",J3) -> 134.25 | P3: =+F3/H3 -> 133.90173
A4: QL-0320177 | B4: 5 | C4: GBP | D4: 42.79 | E4: GBP | F4: 213.95 | G4: 0.35 | H4: 1.73 | I4: GBP | J4: 123.99 | K4: SYS 330 TILE STEEL 1190mm X 290mm PLAIN RAL 9010 20% AB NO INFILL SERVICE TILE CS-04 SERVES 4 BENCHES | L4: Ben Bishop | M4: Northern Home Counties | N4: PROJECT VITRUM FLRS 1 & 2 CAMBRIDGE | O4: =IF(G4<0.03,"",J4) -> 123.99 | P4: =+F4/H4 -> 123.67052
A5: QL-0320178 | B5: 12 | C5: GBP | D5: 39.34 | E5: GBP | F5: 472.08 | G5: 0.35 | H5: 4.14 | I5: GBP | J5: 114 | K5: SYS 330 TILE STEEL 1190mm X 290mm PLAIN RAL 9010 20% AB NO INFILL SERVICE TILE CS-03 SERVES 4 BENCHES | L5: Ben Bishop | M5: Northern Home Counties | N5: PROJECT VITRUM FLRS 1 & 2 CAMBRIDGE | O5: =IF(G5<0.03,"",J5) -> 114 | P5: =+F5/H5 -> 114.02899
A6: QL-0320175 | B6: 26 | C6: GBP | D6: 32.18 | E6: GBP | F6: 836.68 | G6: 0.35 | H6: 8.97 | I6: GBP | J6: 93.25 | K6: SYS 330 TILE STEEL 1190mm X 290mm PLAIN RAL 9010 20% AB NO INFILL SERVICE TILE CS-06 SERVES TO BENCHES | L6: Ben Bishop | M6: Northern Home Counties | N6: PROJECT VITRUM FLRS 1 & 2 CAMBRIDGE | O6: =IF(G6<0.03,"",J6) -> 93.25 | P6: =+F6/H6 -> 93.275362
A7: QL-0320176 | B7: 6 | C7: GBP | D7: 42.79 | E7: GBP | F7: 256.74 | G7: 0.35 | H7: 2.07 | I7: GBP | J7: 123.99 | K7: SYS 330 TILE STEEL 1190mm X 290mm PLAIN RAL 9010 20% AB NO INFILL SERVICE TILE CS-05 SERVES 4 BENCHES | L7: Ben Bishop | M7: Northern Home Counties | N7: PROJECT VITRUM FLRS 1 & 2 CAMBRIDGE | O7: =IF(G7<0.03,"",J7) -> 123.99 | P7: =+F7/H7 -> 124.02899
A8: QL-0320179 | B8: 25 | C8: GBP | D8: 55.88 | E8: GBP | F8: 1397 | G8: 0.35 | H8: 8.63 | I8: GBP | J8: 161.92 | K8: SYS 330 TILE STEEL 1190mm X 290mm PLAIN RAL 9010 20% AB NO INFILL SERVICE TILE CS-02 SERVES 4 BENCHES | L8: Ben Bishop | M8: Northern Home Counties | N8: PROJECT VITRUM FLRS 1 & 2 CAMBRIDGE | O8: =IF(G8<0.03,"",J8) -> 161.92 | P8: =+F8/H8 -> 161.87717
A9: QL-0320180 | B9: 26 | C9: GBP | D9: 47.39 | E9: GBP | F9: 1232.14 | G9: 0.35 | H9: 8.97 | I9: GBP | J9: 137.32 | K9: SYS 330 TILE STEEL 1190mm X 290mm PLAIN RAL 9010 20% AB NO INFILL SERVICE TILE FE-01 FUME HOOD EXHAUST CEILING TILE | L9: Ben Bishop | M9: Northern Home Counties | N9: PROJECT VITRUM FLRS 1 & 2 CAMBRIDGE | O9: =IF(G9<0.03,"",J9) -> 137.32 | P9: =+F9/H9 -> 137.36232
A10: QL-0318333 | B10: 3 | C10: GBP | D10: 36 | E10: GBP | F10: 108 | G10: 0.48 | H10: 1.44 | I10: GBP | J10: 75 | K10: SYS 330 TILE STEEL 800mm X 600mm 1522 10 RAL 9010 20% WRAPPED 16 80 KG SQUARE | L10: Eurshell Fearon | M10: London | N10: ALDERMANBURY SQUARE NO 1 FLOOR 2 REFURB LONDON | O10: =IF(G10<0.03,"",J10) -> 75 | P10: =+F10/H10 -> 75
A11: QL-0318334 | B11: 3 | C11: GBP | D11: 40.5 | E11: GBP | F11: 121.5 | G11: 0.54 | H11: 1.62 | I11: GBP | J11: 75 | K11: SYS 330 TILE STEEL 900mm X 600mm 1522 10 RAL 9010 20% WRAPPED 16 80 KG SQUARE | L11: Eurshell Fearon | M11: London | N11: ALDERMANBURY SQUARE NO 1 FLOOR 2 REFURB LONDON | O11: =IF(G11<0.03,"",J11) -> 75 | P11: =+F11/H11 -> 75
A12: QL-0318332 | B12: 1 | C12: GBP | D12: 27 | E12: GBP | F12: 27 | G12: 0.36 | H12: 0.36 | I12: GBP | J12: 75 | K12: SYS 330 TILE STEEL 1200mm X 300mm 1522 10 RAL 9010 20% WRAPPED 16 80 KG SQUARE | L12: Eurshell Fearon | M12: London | N12: ALDERMANBURY SQUARE NO 1 FLOOR 2 REFURB LONDON | O12: =IF(G12<0.03,"",J12) -> 75 | P12: =+F12/H12 -> 75
A13: QL-0318335 | B13: 1 | C13: GBP | D13: 20.25 | E13: GBP | F13: 20.25 | G13: 0.27 | H13: 0.27 | I13: GBP | J13: 75 | K13: SYS 330 TILE STEEL 900mm X 300mm 1522 10 RAL 9010 20% WRAPPED 16 80 KG SQUARE | L13: Eurshell Fearon | M13: London | N13: ALDERMANBURY SQUARE NO 1 FLOOR 2 REFURB LONDON | O13: =IF(G13<0.03,"",J13) -> 75 | P13: =+F13/H13 -> 75
A14: QL-0318331 | B14: 34 | C14: GBP | D14: 54 | E14: GBP | F14: 1836 | G14: 0.72 | H14: 24.48 | I14: GBP | J14: 75 | K14: SYS 330 TILE STEEL 1200mm X 600mm 1522 10 RAL 9010 20% WRAPPED 16 80 KG SQUARE | L14: Eurshell Fearon | M14: London | N14: ALDERMANBURY SQUARE NO 1 FLOOR 2 REFURB LONDON
A15: QL-0317008 | B15: 140 | C15: GBP | D15: 48.45 | E15: GBP | F15: 6783 | G15: 0.71 | H15: 99.75 | I15: GBP | J15: 68 | K15: SYS 330 TILE 1424 x 500mm S1820 20 RAL 9010 FT WRAPPED 18 80 KG SQUARE | L15: Eurshell Fearon | M15: Midlands | N15: SNOW HILL BLDG 1 QUEENSWAY FLR 10 REFURB BIRMINGHAM | O15: =IF(G15<0.03,"",J15) -> 68 | P15: =+F15/H15 -> 68
A16: QL-0316844 | B16: 1 | C16: GBP | D16: 14.31 | E16: GBP | F16: 14.31 | G16: 0.27 | H16: 0.27 | I16: GBP | J16: 53 | K16: SYS 330 TILE STEEL 900mm X 300mm PLAIN RAL 9016 20% WRAPPED 16 80 KG SQUARE OUT TURN TO LONG EDGES | L16: Jack Turnbull | M16: London | N16: MADDOX STREET NO 31 - 33 CAT A LONDON | O16: =IF(G16<0.03,"",J16) -> 53 | P16: =+F16/H16 -> 53
A17: QL-0316845 | B17: 4 | C17: GBP | D17: 9.54 | E17: GBP | F17: 38.16 | G17: 0.18 | H17: 0.72 | I17: GBP | J17: 53 | K17: SYS 330 TILE STEEL 600mm X 300mm PLAIN RAL 9016 20% WRAPPED 16 80 KG SQUARE OUT TURN TO LONG EDGES | L17: Jack Turnbull | M17: London | N17: MADDOX STREET NO 31 - 33 CAT A LONDON | O17: =IF(G17<0.03,"",J17) -> 53 | P17: =+F17/H17 -> 53
A18: QL-0316842 | B18: 20 | C18: GBP | D18: 32.38 | E18: GBP | F18: 647.6 | G18: 0.43 | H18: 8.52 | I18: GBP | J18: 76.01 | K18: SYS 330 TILE STEEL 1420mm X 300mm 1003 OVERALL RAL 9016 20% WRAPPED 16 80 KG SQUARE | L18: Jack Turnbull | M18: London | N18: MADDOX STREET NO 31 - 33 CAT A LONDON | O18: =IF(G18<0.03,"",J18) -> 76.01 | P18: =+F18/H18 -> 76.00939
A19: QL-0316843 | B19: 110 | C19: GBP | D19: 25.54 | E19: GBP | F19: 2809.4 | G19: 0.34 | H19: 36.96 | I19: GBP | J19: 76.01 | K19: SYS 330 TILE STEEL 1120mm X 300mm 1003 OVERALL RAL 9016 20% WRAPPED 16 80 KG SQUARE | L19: Jack Turnbull | M19: London | N19: MADDOX STREET NO 31 - 33 CAT A LONDON | O19: =IF(G19<0.03,"",J19) -> 76.01 | P19: =+F19/H19 -> 76.011905
A20: QL-0316854 | B20: 36 | C20: GBP | D20: 25.54 | E20: GBP | F20: 919.44 | G20: 0.34 | H20: 12.1 | I20: GBP | J20: 76.01 | K20: SYS 330 TILE STEEL 1120mm X 300mm 1003 OVERALL RAL 9016 20% WRAPPED 16 80 KG SQUARE | L20: Jack Turnbull | M20: London | N20: MADDOX STREET NO 31 - 33 CAT A LONDON | O20: =IF(G20<0.03,"",J20) -> 76.01 | P20: =+F20/H20 -> 75.986777
A21: QL-0316891 | B21: 179 | C21: GBP | D21: 25.54 | E21: GBP | F21: 4571.66 | G21: 0.34 | H21: 60.14 | I21: GBP | J21: 76.01 | K21: SYS 330 TILE STEEL 1120mm X 300mm 1003 OVERALL RAL 9016 20% WRAPPED 16 80 KG SQUARE | L21: Jack Turnbull | M21: London | N21: MADDOX STREET NO 31 - 33 CAT A LONDON | O21: =IF(G21<0.03,"",J21) -> 76.01 | P21: =+F21/H21 -> 76.01696
A22: QL-0316855 | B22: 3 | C22: GBP | D22: 9.54 | E22: GBP | F22: 28.62 | G22: 0.18 | H22: 0.54 | I22: GBP | J22: 53 | K22: SYS 330 TILE STEEL 600mm X 300mm PLAIN RAL 9016 20% WRAPPED 16 80 KG SQUARE OUT TURN TO LONG EDGES | L22: Jack Turnbull | M22: London | N22: MADDOX STREET NO 31 - 33 CAT A LONDON | O22: =IF(G22<0.03,"",J22) -> 53 | P22: =+F22/H22 -> 53
A23: QL-0316892 | B23: 30 | C23: GBP | D23: 32.38 | E23: GBP | F23: 971.4 | G23: 0.43 | H23: 12.78 | I23: GBP | J23: 76.01 | K23: SYS 330 TILE STEEL 1420mm X 300mm 1003 OVERALL RAL 9016 20% WRAPPED 16 80 KG SQUARE | L23: Jack Turnbull | M23: London | N23: MADDOX STREET NO 31 - 33 CAT A LONDON | O23: =IF(G23<0.03,"",J23) -> 76.01 | P23: =+F23/H23 -> 76.00939
A24: QL-0316895 | B24: 4 | C24: GBP | D24: 19.08 | E24: GBP | F24: 76.32 | G24: 0.36 | H24: 1.44 | I24: GBP | J24: 53 | K24: SYS 330 TILE STEEL 1200mm X 300mm PLAIN RAL 9016 20% WRAPPED 16 80 KG SQUARE OUT TURN TO LONG EDGES | L24: Jack Turnbull | M24: London | N24: MADDOX STREET NO 31 - 33 CAT A LONDON | O24: =IF(G24<0.03,"",J24) -> 53 | P24: =+F24/H24 -> 53
A25: QL-0316859 | B25: 212 | C25: GBP | D25: 25.54 | E25: GBP | F25: 5414.48 | G25: 0.34 | H25: 71.23 | I25: GBP | J25: 76.01 | K25: SYS 330 TILE STEEL 1120mm X 300mm 1003 OVERALL RAL 9016 20% WRAPPED 16 80 KG SQUARE | L25: Jack Turnbull | M25: London | N25: MADDOX STREET NO 31 - 33 CAT A LONDON | O25: =IF(G25<0.03,"",J25) -> 76.01 | P25: =+F25/H25 -> 76.014039
A26: QL-0316893 | B26: 30 | C26: GBP | D26: 18.7 | E26: GBP | F26: 561 | G26: 0.25 | H26: 7.38 | I26: GBP | J26: 76.02 | K26: SYS 330 TILE STEEL 820mm X 300mm 1003 OVERALL RAL 9016 20% WRAPPED 16 80 KG SQUARE | L26: Jack Turnbull | M26: London | N26: MADDOX STREET NO 31 - 33 CAT A LONDON | O26: =IF(G26<0.03,"",J26) -> 76.02 | P26: =+F26/H26 -> 76.01626
... A60: QL-0312938 | B60: 4 | C60: GBP | D60: 12.76 | E60: GBP | F60: 51.04 | G60: 0.09 | H60: 0.36 | I60: GBP | J60: 141.78 | K60: SYS 330 TILE STEEL 600mm X 150mm 1522 10 RAL 9010 20% WRAPPED 16 80 KG SQUARE | L60: Jack Wingfield | M60: London | N60: QUEENSBERRY HOUSE OLD BURLINGTON STREET NO 3 CAT B LONDON | O60: =IF(G60<0.03,"",J60) -> 141.78 | P60: =+F60/H60 -> 141.77778
A61: QL-0312939 | B61: 28 | C61: GBP | D61: 13.45 | E61: GBP | F61: 376.6 | G61: 0.18 | H61: 5.04 | I61: GBP | J61: 74.72 | K61: SYS 330 TILE STEEL 600mm X 300mm 1522 10 RAL 9010 20% WRAPPED 16 80 KG SQUARE | L61: Jack Wingfield | M61: London | N61: QUEENSBERRY HOUSE OLD BURLINGTON STREET NO 3 CAT B LONDON
A62: QL-0312944 | B62: 34 | C62: GBP | D62: 20.18 | E62: GBP | F62: 686.12 | G62: 0.27 | H62: 9.18 | I62: GBP | J62: 74.74 | K62: SYS 330 TILE STEEL 900mm X 300mm 1522 10 RAL 9010 20% WRAPPED 16 80 KG SQUARE | L62: Jack Wingfield | M62: London | N62: QUEENSBERRY HOUSE OLD BURLINGTON STREET NO 3 CAT B LONDON
A63: QL-0312942 | B63: 6 | C63: GBP | D63: 19.06 | E63: GBP | F63: 114.36 | G63: 0.26 | H63: 1.53 | I63: GBP | J63: 74.75 | K63: SYS 330 TILE STEEL 850mm X 300mm 1522 10 RAL 9010 20% WRAPPED 16 80 KG SQUARE | L63: Jack Wingfield | M63: London | N63: QUEENSBERRY HOUSE OLD BURLINGTON STREET NO 3 CAT B LONDON
A64: QL-0312943 | B64: 15 | C64: GBP | D64: 19.62 | E64: GBP | F64: 294.3 | G64: 0.26 | H64: 3.94 | I64: GBP | J64: 74.74 | K64: SYS 330 TILE STEEL 875mm X 300mm 1522 10 RAL 9010 20% WRAPPED 16 80 KG SQUARE | L64: Jack Wingfield | M64: London | N64: QUEENSBERRY HOUSE OLD BURLINGTON STREET NO 3 CAT B LONDON
A65: QL-0312937 | B65: 56 | C65: GBP | D65: 13 | E65: GBP | F65: 728 | G65: 0.17 | H65: 9.74 | I65: GBP | J65: 74.71 | K65: SYS 330 TILE STEEL 580mm X 300mm 1522 10 RAL 9010 20% WRAPPED 16 80 KG SQUARE | L65: Jack Wingfield | M65: London | N65: QUEENSBERRY HOUSE OLD BURLINGTON STREET NO 3 CAT B LONDON
A66: QL-0312955 | B66: 40 | C66: GBP | D66: 29.71 | E66: GBP | F66: 1188.4 | G66: 0.4 | H66: 15.9 | I66: GBP | J66: 74.74 | K66: SYS 330 TILE STEEL 1325mm X 300mm 1522 10 RAL 9010 20% WRAPPED 16 80 KG SQUARE | L66: Jack Wingfield | M66: London | N66: QUEENSBERRY HOUSE OLD BURLINGTON STREET NO 3 CAT B LONDON
A67: QL-0312956 | B67: 50 | C67: GBP | D67: 15.13 | E67: GBP | F67: 756.5 | G67: 0.2 | H67: 10.13 | I67: GBP | J67: 74.72 | K67: SYS 330 TILE STEEL 1350mm X 150mm 1522 10 RAL 9010 20% WRAPPED 16 80 KG SQUARE | L67: Jack Wingfield | M67: London | N67: QUEENSBERRY HOUSE OLD BURLINGTON STREET NO 3 CAT B LONDON
A68: QL-0312954 | B68: 4 | C68: GBP | D68: 24.75 | E68: GBP | F68: 99 | G68: 0.33 | H68: 1.33 | I68: GBP | J68: 74.72 | K68: SYS 330 TILE STEEL 1325mm X 250mm 1522 10 RAL 9010 20% WRAPPED 16 80 KG SQUARE | L68: Jack Wingfield | M68: London | N68: QUEENSBERRY HOUSE OLD BURLINGTON STREET NO 3 CAT B LONDON
A69: QL-0312957 | B69: 8 | C69: GBP | D69: 15.69 | E69: GBP | F69: 125.52 | G69: 0.21 | H69: 1.68 | I69: GBP | J69: 74.71 | K69: SYS 330 TILE STEEL 1400mm X 150mm 1522 10 RAL 9010 20% WRAPPED 16 80 KG SQUARE | L69: Jack Wingfield | M69: London | N69: QUEENSBERRY HOUSE OLD BURLINGTON STREET NO 3 CAT B LONDON
A70: QL-0312958 | B70: 16 | C70: GBP | D70: 20.92 | E70: GBP | F70: 334.72 | G70: 0.28 | H70: 4.48 | I70: GBP | J70: 74.71 | K70: SYS 330 TILE STEEL 1400mm X 200mm 1522 10 RAL 9010 20% WRAPPED 16 80 KG SQUARE | L70: Jack Wingfield | M70: London | N70: QUEENSBERRY HOUSE OLD BURLINGTON STREET NO 3 CAT B LONDON
A71: QL-0312961 | B71: 4 | C71: GBP | D71: 32.51 | E71: GBP | F71: 130.04 | G71: 0.44 | H71: 1.74 | I71: GBP | J71: 74.74 | K71: SYS 330 TILE STEEL 1450mm X 300mm 1522 10 RAL 9010 20% WRAPPED 16 80 KG SQUARE | L71: Jack Wingfield | M71: London | N71: QUEENSBERRY HOUSE OLD BURLINGTON STREET NO 3 CAT B LONDON
A72: QL-0312962 | B72: 32 | C72: GBP | D72: 33.63 | E72: GBP | F72: 1076.16 | G72: 0.45 | H72: 14.4 | I72: GBP | J72: 74.73 | K72: SYS 330 TILE STEEL 1500mm X 300mm 1522 10 RAL 9010 20% WRAPPED 16 80 KG SQUARE | L72: Jack Wingfield | M72: London | N72: QUEENSBERRY HOUSE OLD BURLINGTON STREET NO 3 CAT B LONDON
... A114: QL-0318298 | B114: 412 | C114: GBP | D114: 24.33 | E114: GBP | F114: 10023.96 | G114: 0.17 | H114: 70.04 | I114: GBP | J114: 143.12 | K114: SYS 330 TILE STEEL 850mm X 200mm 1522 10 RAL 9010 FT WRAPPED 16 80 KG SQUARE | L114: Sam James | M114: London | N114: DUKES HOTEL CORRIDOR CEILINGS MAYFAIR LONDON

Sheet SQM WK 40
A1: Line Name | B1: Quantity | C1: Net Unit Price Currency | D1: Net Unit Price | E1: Net Total Currency | F1: Net Total | G1: Item SQM | H1: Line SQM | I1: Â£/SQM Currency | J1: Â£/SQM | K1: Description | L1: Project Owner: Full Name | M1: Sales Region | N1: Project Name | O1: =AVERAGE(O2:O87) -> 80.211034 | P1: =AVERAGE(P2:P87) -> 80.210402
A2: QL-0309454 | B2: 22 | C2: GBP | D2: 22.71 | E2: GBP | F2: 499.62 | G2: 0.24 | H2: 5.34 | I2: GBP | J2: 93.57 | K2: SYS 330 TILE STEEL 809mm X 300mm 1522 10 RAL 9010 20% WRAPPED 16 80 KG SQUARE | L2: Ben Bishop | M2: Midlands | N2: COLMORE SQUARE NO 1 GROUND FLOOR BIRMINGHAM | O2: =IF(G2<0.03,"",J2) -> 93.57 | P2: =+F2/H2 -> 93.561798
A3: QL-0311344 | B3: 18 | C3: GBP | D3: 26.63 | E3: GBP | F3: 479.34 | G3: 0.29 | H3: 5.18 | I3: GBP | J3: 92.47 | K3: SYS 330 TILE STEEL 960mm X 300mm 1522 10 RAL 9010 20% WRAPPED 16 80 KG SQUARE | L3: Ben Bishop | M3: Midlands | N3: COLMORE SQUARE NO 1 GROUND FLOOR BIRMINGHAM | O3: =IF(G3<0.03,"",J3) -> 92.47 | P3: =+F3/H3 -> 92.53668
A4: QL-0316298 | B4: 1290 | C4: GBP | D4: 25.25 | E4: GBP | F4: 32572.5 | G4: 0.36 | H4: 464.4 | I4: GBP | J4: 70.14 | K4: SYS 330 TILE STEEL 1200mm X 300mm 1522 10 RAL 9010 20% WRAPPED 16 80 KG CLOSED ENDS | L4: Ben Bishop | M4: Northern Home Counties | N4: STATION ROAD NO 21 FLRS 4 & 5 CAMBRIDGE | O4: =IF(G4<0.03,"",J4) -> 70.14 | P4: =+F4/H4 -> 70.138889
A5: QL-0316260 | B5: 1960 | C5: GBP | D5: 25.25 | E5: GBP | F5: 49490 | G5: 0.36 | H5: 705.6 | I5: GBP | J5: 70.14 | K5: SYS 330 TILE STEEL 1200mm X 300mm 1522 10 RAL 9010 20% WRAPPED 16 80 KG CLOSED ENDS | L5: Ben Bishop | M5: Northern Home Counties | N5: STATION ROAD NO 21 FLRS 4 & 5 CAMBRIDGE | O5: =IF(G5<0.03,"",J5) -> 70.14 | P5: =+F5/H5 -> 70.138889
A6: QL-0316163 | B6: 905 | C6: GBP | D6: 29.33 | E6: GBP | F6: 26543.65 | G6: 0.36 | H6: 325.8 | I6: GBP | J6: 81.47 | K6: SYS 330 TILE 600mm X 600mm 1522 10 RAL 7022 30% 30mm THK RW4 BLACK TISSUE WRAPPED ACOUSTIC PAD | L6: Ed Fagan | M6: London | N6: BROADGATE NO 1-2 CAT B JLL AMR LONDON | O6: =IF(G6<0.03,"",J6) -> 81.47 | P6: =+F6/H6 -> 81.472222
A7: QL-0315484 | B7: 3875 | C7: GBP | D7: 24.59 | E7: GBP | F7: 95286.25 | G7: 0.36 | H7: 1393.84 | I7: GBP | J7: 68.36 | K7: SYS 330 TILE STEEL 1199mm X 300mm 1522 10 RAL 9010 20% BLACK ADHESIVE TISSUE SQUARE | L7: Jack Turnbull | M7: London | N7: KING WILLIAM STREET NO 45 REGIS HOUSE PH2 LONDON | O7: =IF(G7<0.03,"",J7) -> 68.36 | P7: =+F7/H7 -> 68.362402
A8: QL-0310997 | B8: 30 | C8: GBP | D8: 63.9 | E8: GBP | F8: 1917 | G8: 0.6 | H8: 18 | I8: GBP | J8: 106.5 | K8: SYS 330 TILE AL 1000mm X 600mm LEAF-SMALL RAL 9003 20% WRAPPED 16 80 KG SQUARE | L8: Jack Turnbull | M8: London | N8: WARWICK COURT CAT B EGYM LONDON | O8: =IF(G8<0.03,"",J8) -> 106.5 | P8: =+F8/H8 -> 106.5
A9: QL-0311008 | B9: 24 | C9: GBP | D9: 71.57 | E9: GBP | F9: 1717.68 | G9: 0.67 | H9: 16.13 | I9: GBP | J9: 106.5 | K9: SYS 330 TILE AL 1120mm X 600mm LEAF-SMALL RAL 9003 20% WRAPPED 16 80 KG SQUARE | L9: Jack Turnbull | M9: London | N9: WARWICK COURT CAT B EGYM LONDON | O9: =IF(G9<0.03,"",J9) -> 106.5 | P9: =+F9/H9 -> 106.48977
A10: QL-0311006 | B10: 24 | C10: GBP | D10: 34.51 | E10: GBP | F10: 828.24 | G10: 0.32 | H10: 7.78 | I10: GBP | J10: 106.51 | K10: SYS 330 TILE AL 540mm X 600mm LEAF-SMALL RAL 9003 20% WRAPPED 16 80 KG SQUARE | L10: Jack Turnbull | M10: London | N10: WARWICK COURT CAT B EGYM LONDON | O10: =IF(G10<0.03,"",J10) -> 106.51 | P10: =+F10/H10 -> 106.45758
A11: QL-0311007 | B11: 8 | C11: GBP | D11: 109.91 | E11: GBP | F11: 879.28 | G11: 1.03 | H11: 8.26 | I11: GBP | J11: 106.5 | K11: SYS 330 TILE AL 1720mm X 600mm LEAF-SMALL RAL 9003 20% WRAPPED 16 80 KG SQUARE | L11: Jack Turnbull | M11: London | N11: WARWICK COURT CAT B EGYM LONDON | O11: =IF(G11<0.03,"",J11) -> 106.5 | P11: =+F11/H11 -> 106.45036
A12: QL-0310968 | B12: 8 | C12: GBP | D12: 76.68 | E12: GBP | F12: 613.44 | G12: 0.72 | H12: 5.76 | I12: GBP | J12: 106.5 | K12: SYS 330 TILE AL 1200mm X 600mm LEAF-SMALL RAL 9003 20% WRAPPED 16 80 KG SQUARE | L12: Jack Turnbull | M12: London | N12: WARWICK COURT CAT B EGYM LONDON | O12: =IF(G12<0.03,"",J12) -> 106.5 | P12: =+F12/H12 -> 106.5
A13: QL-0310142 | B13: 380 | C13: GBP | D13: 17.98 | E13: GBP | F13: 6832.4 | G13: 0.36 | H13: 136.8 | I13: GBP | J13: 49.94 | K13: SYS 330 TILE STEEL 1200mm X 300mm 1522 10 RAL 9010 20% WRAPPED 16 80 KG SQUARE | L13: Jack Wingfield | M13: London | N13: BRITISH LIBRARY SOUND & VISION FIT OUT LONDON | O13: =IF(G13<0.03,"",J13) -> 49.94 | P13: =+F13/H13 -> 49.944444
A14: QL-0312544 | B14: 299 | C14: GBP | D14: 62.59 | E14: GBP | F14: 18714.41 | G14: 0 | H14: 0 | J14: #Error! | K14: SYS 330 TILE SYS 330 TILE STEEL 1500mm x 600mm 2051 10 RAL 5018 WRAPPED 16 80 KG LIGHT TURQUOISE BLUE FINISH, TBC | L14: Jack Wingfield | M14: London | N14: KINGS CROSS CENTRAL GOOGLE HQ KGX1 CAT B LONDON
A15: QL-0311837 | B15: 327 | C15: GBP | D15: 44.08 | E15: GBP | F15: 14414.16 | G15: 0.72 | H15: 235.44 | I15: GBP | J15: 61.22 | K15: SYS 330 TILE 1200mm X 600mm 1003 OVERALL RAL 9010 20% WRAPPED 16 80 KG SQUARE | L15: Mark Guest | M15: South East | N15: AWE HUB ALDERMASTON ENGINEERING WING LEVEL 02 ALDERMASTON | O15: =IF(G15<0.03,"",J15) -> 61.22 | P15: =+F15/H15 -> 61.222222
A16: QL-0311846 | B16: 608 | C16: GBP | D16: 22.04 | E16: GBP | F16: 13400.32 | G16: 0.36 | H16: 218.88 | I16: GBP | J16: 61.22 | K16: SYS 330 TILE STEEL 600mm X 600mm 1003 OVERALL RAL 9010 20% WRAPPED 16 80 KG SQUARE | L16: Mark Guest | M16: South East | N16: AWE HUB ALDERMASTON ENGINEERING WING LEVEL 02 ALDERMASTON | O16: =IF(G16<0.03,"",J16) -> 61.22 | P16: =+F16/H16 -> 61.222222
A17: QL-0311855 | B17: 385 | C17: GBP | D17: 44.08 | E17: GBP | F17: 16970.8 | G17: 0.72 | H17: 277.2 | I17: GBP | J17: 61.22 | K17: SYS 330 TILE STEEL 1200mm X 600mm 1513 10 RAL 9010 20% WRAPPED 16 80 KG SQUARE | L17: Mark Guest | M17: South East | N17: AWE HUB ALDERMASTON ENGINEERING WING LEVEL 02 ALDERMASTON | O17: =IF(G17<0.03,"",J17) -> 61.22 | P17: =+F17/H17 -> 61.222222
A18: QL-0316077 | B18: 38 | C18: GBP | D18: 31.5 | E18: GBP | F18: 1197 | G18: 0.42 | H18: 15.96 | I18: GBP | J18: 75 | K18: SYS 330 TILE STEEL 1400mm X 300mm 1522 10 RAL 9010 20% WRAPPED 16 80 KG SQUARE | L18: Nick Drake | M18: London | N18: SAVILE ROW NO 23 ROKOS FLR 2-3 LONDON | O18: =IF(G18<0.03,"",J18) -> 75 | P18: =+F18/H18 -> 75
A19: QL-0316078 | B19: 100 | C19: GBP | D19: 27 | E19: GBP | F19: 2700 | G19: 0.36 | H19: 36 | I19: GBP | J19: 75 | K19: SYS 330 TILE STEEL 1200mm X 300mm 1522 10 RAL 9010 20% WRAPPED 16 80 KG SQUARE | L19: Nick Drake | M19: London | N19: SAVILE ROW NO 23 ROKOS FLR 2-3 LONDON | O19: =IF(G19<0.03,"",J19) -> 75 | P19: =+F19/H19 -> 75
A20: QL-0315180 | B20: 15 | C20: GBP | D20: 72 | E20: GBP | F20: 1080 | G20: 0.9 | H20: 13.5 | I20: GBP | J20: 80 | K20: SYS 330 TILE STEEL 1500mm X 600mm 1522 10 RAL 9010 20% WRAPPED 16 80 KG SQUARE HORIZON | L20: Nick Drake | M20: London | N20: SOUTHAMPTON ROW NO 31 HOLBORN LINKS PH 2 LONDON | O20: =IF(G20<0.03,"",J20) -> 80 | P20: =+F20/H20 -> 80
