Workbook

Sheet Analysis
B4: No of complaints Raised per Week - Power BI Report - Saved on tab of the same name
C5: This shows the complaints raised by dates and the reason code assigned to the complaint
C6: Ive extracted the date from the date / time field and looked up the week number
C8: This can be seen on the Tab Pivot of complaints
C9: Picked up from the KPI submission all of the complaint numbers submitted
C10: SOP - on 15 weeks only 5 agree - Power BI is higher by 11 (Only SOP included, export SOP are not, if they were the difference would be greater
C11: Product Design - close on 15 weeks 11 agree and 4 show differences of +/- 1 - total difference is 2 with Power BI being higher
C12: Bridgend Manufacturing - cant see how to pull out Bridgend Manufacturing
C13: Maybole Manufacturing - Cant see how to pull out Maybole Manufacturing
C14: Quality - Cant see how to pull out the Quality complaints
C16: Tried to reconcile these back - but could not see a pattern

Sheet Lookup List
A1: Department
A2: Salesforce | B2: Salesforce
A3: Shop Floor | B3: 03 Shop Floor
A4: N/A | B4: N/A
A5: Assembly | B5: 03 Assembly
A6: Transport | B6: Transport
A7: UK SOP | B7: 01 SOP
A8: UK SOP | B8: 01 SOP
A9: Warehouse | B9: Warehouse
A10: Product Design/Engineering | B10: 02 Product Design
A11: Customer | B11: Customer
A12: Export SOP | B12: 01 Export SOP
A13: External Courier | B13: External Courier
... A26: Block 2 | B26: Block 2

Sheet Pivot of Complaints
B2: Count of Customer Service Number | C2: Column Labels
B3: Row Labels | C3: 2 | D3: 3 | E3: 4 | F3: 5 | G3: 6 | H3: 7 | I3: 8 | J3: 9 | K3: 10 | L3: 11 | M3: 12 | N3: 13 | O3: 14 | P3: 15 | Q3: 16 | R3: 17 | S3: 18 | T3: 19 | U3: (blank) | V3: 20 | W3: 21 | X3: 22 | Y3: 23 | Z3: 24 | AA3: 25 | AB3: 26 | AC3: 27 | AD3: 28 | AE3: 29 | AF3: 30 | AG3: 31 | AH3: 32 | AI3: 33 | AJ3: 34 | AK3: 35 | AL3: 36 | AM3: 37 | AN3: 38 | AO3: 39 | AP3: 40 | AQ3: Grand Total
B4: 01 Export SOP | C4: 1 | I4: 1 | O4: 1 | W4: 1 | Z4: 1 | AQ4: 5
B5: 01 SOP | C5: 2 | D5: 1 | E5: 4 | F5: 1 | G5: 5 | H5: 2 | J5: 2 | K5: 1 | L5: 4 | M5: 7 | N5: 4 | O5: 3 | P5: 1 | Q5: 1 | R5: 1 | S5: 1 | T5: 1 | V5: 5 | W5: 3 | X5: 2 | Y5: 1 | Z5: 3 | AA5: 1 | AB5: 1 | AC5: 2 | AD5: 1 | AE5: 1 | AF5: 3 | AH5: 1 | AI5: 1 | AJ5: 2 | AK5: 4 | AL5: 2 | AM5: 1 | AN5: 1 | AO5: 2 | AP5: 4 | AQ5: 82
B6: 02 Product Design | C6: 1 | F6: 1 | G6: 2 | H6: 1 | I6: 1 | J6: 1 | M6: 3 | O6: 1 | P6: 2 | Q6: 1 | S6: 3 | V6: 1 | Y6: 1 | Z6: 2 | AA6: 5 | AC6: 1 | AD6: 1 | AG6: 1 | AH6: 2 | AJ6: 1 | AM6: 1 | AN6: 1 | AO6: 2 | AP6: 3 | AQ6: 39
B7: 03 Assembly | C7: 1 | F7: 1 | H7: 1 | I7: 2 | J7: 2 | K7: 2 | L7: 1 | N7: 1 | O7: 1 | P7: 2 | Q7: 2 | S7: 3 | T7: 3 | V7: 2 | W7: 1 | X7: 1 | AA7: 2 | AB7: 3 | AC7: 2 | AE7: 3 | AF7: 1 | AH7: 1 | AO7: 1 | AP7: 1 | AQ7: 40
B8: 03 Assembly Block 2 | D8: 4 | F8: 2 | J8: 2 | K8: 2 | L8: 2 | AB8: 1 | AN8: 1 | AQ8: 14
B9: 03 Shop Floor | C9: 1 | D9: 1 | E9: 1 | F9: 1 | I9: 2 | K9: 2 | L9: 3 | M9: 5 | N9: 1 | O9: 2 | S9: 1 | T9: 2 | V9: 2 | W9: 1 | Y9: 1 | AA9: 1 | AB9: 3 | AC9: 4 | AE9: 1 | AG9: 1 | AO9: 1 | AQ9: 37
B10: Block 2 | T10: 1 | AQ10: 1
B11: Customer | C11: 2 | D11: 1 | E11: 6 | F11: 4 | H11: 1 | I11: 2 | J11: 1 | K11: 2 | L11: 3 | N11: 2 | O11: 1 | P11: 2 | Q11: 4 | S11: 2 | T11: 2 | V11: 1 | W11: 2 | X11: 3 | Y11: 1 | Z11: 2 | AA11: 2 | AB11: 2 | AC11: 1 | AD11: 2 | AE11: 1 | AF11: 5 | AG11: 1 | AH11: 2 | AI11: 1 | AJ11: 1 | AK11: 1 | AL11: 2 | AM11: 4 | AN11: 1 | AO11: 2 | AP11: 2 | AQ11: 74
B12: Design | D12: 1 | E12: 2 | F12: 1 | AQ12: 4
B13: Estimating | D13: 1 | E13: 2 | F13: 1 | H13: 1 | K13: 3 | N13: 1 | O13: 1 | P13: 1 | W13: 1 | X13: 1 | AA13: 1 | AD13: 1 | AF13: 1 | AM13: 1 | AN13: 1 | AO13: 1 | AQ13: 19
B14: Ext â€“ External | L14: 1 | AQ14: 1
B15: External Courier | D15: 1 | E15: 1 | H15: 1 | I15: 1 | J15: 1 | K15: 1 | M15: 1 | N15: 1 | Q15: 1 | W15: 1 | X15: 1 | AB15: 1 | AH15: 1 | AM15: 1 | AO15: 1 | AQ15: 15
B16: Fast Track | D16: 1 | E16: 1 | F16: 3 | I16: 1 | K16: 1 | N16: 1 | S16: 1 | T16: 1 | V16: 1 | Z16: 1 | AO16: 1 | AQ16: 13
B17: Finance | D17: 3 | P17: 1 | S17: 1 | X17: 1 | AQ17: 6
B18: Lighting Supplier | E18: 2 | G18: 1 | H18: 1 | T18: 1 | X18: 1 | Y18: 1 | AQ18: 7
B19: N/A | C19: 1 | AQ19: 1
B20: Paintline | D20: 1 | E20: 1 | J20: 2 | O20: 1 | Y20: 1 | AB20: 2 | AC20: 1 | AJ20: 1 | AQ20: 10
B21: Press | D21: 1 | G21: 1 | J21: 1 | K21: 1 | X21: 1 | AQ21: 5
B22: Salesforce | C22: 1 | D22: 2 | E22: 2 | F22: 1 | G22: 1 | I22: 1 | J22: 1 | K22: 1 | L22: 1 | M22: 1 | P22: 1 | S22: 1 | T22: 1 | V22: 2 | Y22: 1 | Z22: 1 | AC22: 2 | AH22: 3 | AI22: 3 | AK22: 1 | AM22: 1 | AO22: 2 | AP22: 1 | AQ22: 32
B23: Supplier | L23: 1 | P23: 1 | Q23: 1 | S23: 1 | Y23: 1 | AA23: 1 | AC23: 1 | AE23: 1 | AF23: 1 | AH23: 2 | AI23: 1 | AN23: 1 | AO23: 2 | AQ23: 15
B24: Transport | C24: 2 | D24: 1 | E24: 2 | G24: 1 | H24: 2 | I24: 1 | M24: 1 | N24: 1 | O24: 1 | P24: 2 | Q24: 1 | S24: 2 | X24: 1 | Y24: 1 | Z24: 3 | AC24: 2 | AF24: 1 | AG24: 2 | AH24: 2 | AI24: 1 | AK24: 1 | AL24: 1 | AN24: 1 | AP24: 1 | AQ24: 34
B25: Warehouse | C25: 1 | F25: 1 | G25: 1 | K25: 1 | L25: 1 | M25: 1 | N25: 2 | X25: 3 | AB25: 1 | AC25: 3 | AD25: 1 | AE25: 1 | AF25: 1 | AG25: 1 | AI25: 1 | AL25: 1 | AQ25: 21
B26: FALSE | E26: 1 | W26: 1 | X26: 2 | Y26: 1 | Z26: 1 | AA26: 2 | AB26: 1 | AC26: 4 | AD26: 2 | AE26: 8 | AF26: 2 | AG26: 3 | AH26: 1 | AI26: 2 | AJ26: 1 | AK26: 2 | AL26: 5 | AM26: 1 | AN26: 3 | AO26: 4 | AP26: 6 | AQ26: 53
B27: (blank)
B28: Grand Total | C28: 13 | D28: 19 | E28: 25 | F28: 17 | G28: 12 | H28: 10 | I28: 12 | J28: 13 | K28: 17 | L28: 17 | M28: 19 | N28: 14 | O28: 12 | P28: 13 | Q28: 11 | R28: 1 | S28: 16 | T28: 12 | V28: 14 | W28: 11 | X28: 17 | Y28: 10 | Z28: 14 | AA28: 15 | AB28: 15 | AC28: 23 | AD28: 8 | AE28: 16 | AF28: 15 | AG28: 9 | AH28: 15 | AI28: 10 | AJ28: 6 | AK28: 9 | AL28: 11 | AM28: 10 | AN28: 10 | AO28: 19 | AP28: 18 | AQ28: 528
C33: 1 | D33: =C33+1 -> 2 | E33: =D33+1 -> 3 | F33: =E33+1 -> 4 | G33: =F33+1 -> 5 | H33: =G33+1 -> 6 | I33: =H33+1 -> 7 | J33: =I33+1 -> 8 | K33: =J33+1 -> 9 | ... U33: =T33+1 -> 19
C34: 45660 | D34: =C34+7 -> 45667 | E34: =D34+7 -> 45674 | F34: =E34+7 -> 45681 | G34: =F34+7 -> 45688 | H34: =G34+7 -> 45695 | I34: =H34+7 -> 45702 | J34: =I34+7 -> 45709 | K34: =J34+7 -> 45716 | ... U34: =T34+7 -> 45786
B35: SOP KPI | C35: Blank | D35: Missed | E35: Missed | F35: Missed | G35: 3 | H35: 0 | I35: 1 | J35: 3 | K35: 2 | L35: 1 | M35: 1 | N35: 3 | O35: 4 | P35: 0 | Q35: 1 | R35: 2 | S35: 1 | T35: 1 | U35: 3
B36: Power BI Report | D36: =+GETPIVOTDATA("Customer Service Number",$B$2,"Department2","01 SOP","week No",D$33) -> 2 | E36: =+GETPIVOTDATA("Customer Service Number",$B$2,"Department2","01 SOP","week No",E$33) -> 1 | F36: =+GETPIVOTDATA("Customer Service Number",$B$2,"Department2","01 SOP","week No",F$33) -> 4 | G36: =+GETPIVOTDATA("Customer Service Number",$B$2,"Department2","01 SOP","week No",G$33) -> 1 | H36: =+GETPIVOTDATA("Customer Service Number",$B$2,"Department2","01 SOP","week No",H$33) -> 5 | I36: =+GETPIVOTDATA("Customer Service Number",$B$2,"Department2","01 SOP","week No",I$33) -> 2 | J36: =+GETPIVOTDATA("Customer Service Number",$B$2,"Department2","01 SOP","week No",J$33) -> 0 | K36: =+GETPIVOTDATA("Customer Service Number",$B$2,"Department2","01 SOP","week No",K$33) -> 2 | ... U36: =+GETPIVOTDATA("Customer Service Number",$B$2,"Department2","01 SOP","week No",U$33) -> 1
B37: +ve KPI higher than report | G37: =+G35-G36 -> 2 | H37: =+H35-H36 -> -5 | I37: =+I35-I36 -> -1 | J37: =+J35-J36 -> 3 | K37: =+K35-K36 -> 0 | L37: =+L35-L36 -> 0 | M37: =+M35-M36 -> -3 | N37: =+N35-N36 -> -4 | ... U37: =+U35-U36 -> 2
B39: Prod Design | C39: Blank | D39: 0 | E39: 0 | F39: 0 | G39: 1 | H39: 2 | I39: 0.94 | J39: 0 | K39: 0 | L39: 0 | M39: 0 | N39: 3 | O39: 0 | P39: 0 | Q39: 3 | R39: 0 | S39: 0 | T39: 2 | U39: 0
B40: Power BI Report | D40: =+GETPIVOTDATA("Customer Service Number",$B$2,"Department2","02 Product Design","week No",D33) -> 1 | E40: =+GETPIVOTDATA("Customer Service Number",$B$2,"Department2","02 Product Design","week No",E33) -> 0 | F40: =+GETPIVOTDATA("Customer Service Number",$B$2,"Department2","02 Product Design","week No",F33) -> 0 | G40: =+GETPIVOTDATA("Customer Service Number",$B$2,"Department2","02 Product Design","week No",G33) -> 1 | H40: =+GETPIVOTDATA("Customer Service Number",$B$2,"Department2","02 Product Design","week No",H33) -> 2 | I40: =+GETPIVOTDATA("Customer Service Number",$B$2,"Department2","02 Product Design","week No",I33) -> 1 | J40: =+GETPIVOTDATA("Customer Service Number",$B$2,"Department2","02 Product Design","week No",J33) -> 1 | K40: =+GETPIVOTDATA("Customer Service Number",$B$2,"Department2","02 Product Design","week No",K33) -> 1 | ... U40: =+GETPIVOTDATA("Customer Service Number",$B$2,"Department2","02 Product Design","week No",U33) -> 0
B41: +ve KPI higher than report | G41: =+G39-G40 -> 0 | H41: =+H39-H40 -> 0 | I41: =+I39-I40 -> -0.06 | J41: =+J39-J40 -> -1 | K41: =+K39-K40 -> -1 | L41: =+L39-L40 -> 0 | M41: =+M39-M40 -> 0 | N41: =+N39-N40 -> 0 | ... U41: =+U39-U40 -> 0
B44: Bridgend Manufacturing | C44: Blank | D44: 1 | E44: 6 | F44: 2 | G44: 5 | H44: 1 | I44: 1 | J44: 2 | K44: 4 | L44: 4 | M44: 2 | N44: 0 | O44: 0 | P44: 0 | Q44: 2 | R44: 3 | S44: 0
B45: Power BI Report
B49: Maybole Manufacturing | C49: Blank | D49: Missed | E49: Missed | F49: Missed | G49: Missed | H49: Missed | I49: Missed | J49: Missed | K49: Missed | L49: Missed | M49: Missed | N49: Missed | O49: Missed | P49: 2 | Q49: 0 | R49: 1 | S49: 0 | T49: 0 | U49: 0
B50: Power BI Report
B54: Quality | C54: Blank | D54: Missed | E54: Missed | F54: Missed | G54: Missed | H54: Missed | I54: Missed | J54: Missed | K54: Missed | L54: Missed | M54: Missed | N54: Missed | O54: Missed | P54: 3 | Q54: 3 | R54: 1 | S54: 0 | T54: 0 | U54: 0
...

Sheet KPI
B2: Week | C2: 2 | D2: 3 | E2: 4 | F2: 5 | G2: 6 | H2: 7 | I2: 8 | J2: 9 | K2: 10 | L2: 11 | M2: 12 | N2: 13 | O2: 14 | P2: 15 | Q2: 16 | R2: 17 | S2: 18 | T2: 19 | U2: 20 | V2: 21 | W2: 22 | X2: 23 | Y2: 24 | Z2: 25 | AA2: 26 | AB2: 27 | AC2: 28 | AD2: 29 | AE2: 30 | AF2: 31 | AG2: 32 | AH2: 33 | AI2: 34 | AJ2: 35 | AK2: 36 | AL2: 37 | AM2: 38 | AN2: 39 | AO2: 40 | AP2: 41 | AQ2: 42 | AR2: 43 | AS2: 44 | AT2: 45 | AU2: 46 | AV2: 47 | AW2: 48 | AX2: 49 | AY2: 50 | AZ2: 51 | BA2: 52
B3: Cleansing
C4: =+GETPIVOTDATA("Sum of On Time",'Pivot Cleansing'!$A$3,"Week No",C$2)/GETPIVOTDATA("Count of Order Tracking: Order Tracking No",'Pivot Cleansing'!$A$3,"Week No",C$2) -> 0.92156863 | D4: =+GETPIVOTDATA("Sum of On Time",'Pivot Cleansing'!$A$3,"Week No",D$2)/GETPIVOTDATA("Count of Order Tracking: Order Tracking No",'Pivot Cleansing'!$A$3,"Week No",D$2) -> 0.95145631 | E4: =+GETPIVOTDATA("Sum of On Time",'Pivot Cleansing'!$A$3,"Week No",E$2)/GETPIVOTDATA("Count of Order Tracking: Order Tracking No",'Pivot Cleansing'!$A$3,"Week No",E$2) -> 0.6875 | F4: =+GETPIVOTDATA("Sum of On Time",'Pivot Cleansing'!$A$3,"Week No",F$2)/GETPIVOTDATA("Count of Order Tracking: Order Tracking No",'Pivot Cleansing'!$A$3,"Week No",F$2) -> 0.32608696 | G4: =+GETPIVOTDATA("Sum of On Time",'Pivot Cleansing'!$A$3,"Week No",G$2)/GETPIVOTDATA("Count of Order Tracking: Order Tracking No",'Pivot Cleansing'!$A$3,"Week No",G$2) -> 0.56140351 | H4: =+GETPIVOTDATA("Sum of On Time",'Pivot Cleansing'!$A$3,"Week No",H$2)/GETPIVOTDATA("Count of Order Tracking: Order Tracking No",'Pivot Cleansing'!$A$3,"Week No",H$2) -> 0.58823529 | I4: =+GETPIVOTDATA("Sum of On Time",'Pivot Cleansing'!$A$3,"Week No",I$2)/GETPIVOTDATA("Count of Order Tracking: Order Tracking No",'Pivot Cleansing'!$A$3,"Week No",I$2) -> 0.62222222 | J4: =+GETPIVOTDATA("Sum of On Time",'Pivot Cleansing'!$A$3,"Week No",J$2)/GETPIVOTDATA("Count of Order Tracking: Order Tracking No",'Pivot Cleansing'!$A$3,"Week No",J$2) -> 0.65384615 | ... AQ4: =+GETPIVOTDATA("Sum of On Time",'Pivot Cleansing'!$A$3,"Week No",AQ$2)/GETPIVOTDATA("Count of Order Tracking: Order Tracking No",'Pivot Cleansing'!$A$3,"Week No",AQ$2) -> 1
B5: On Time | C5: =+GETPIVOTDATA("Sum of On Time",'Pivot Cleansing'!$A$3,"Week No",C$2) -> 141 | D5: =+GETPIVOTDATA("Sum of On Time",'Pivot Cleansing'!$A$3,"Week No",D$2) -> 98 | E5: =+GETPIVOTDATA("Sum of On Time",'Pivot Cleansing'!$A$3,"Week No",E$2) -> 55 | F5: =+GETPIVOTDATA("Sum of On Time",'Pivot Cleansing'!$A$3,"Week No",F$2) -> 15 | G5: =+GETPIVOTDATA("Sum of On Time",'Pivot Cleansing'!$A$3,"Week No",G$2) -> 32 | H5: =+GETPIVOTDATA("Sum of On Time",'Pivot Cleansing'!$A$3,"Week No",H$2) -> 30 | I5: =+GETPIVOTDATA("Sum of On Time",'Pivot Cleansing'!$A$3,"Week No",I$2) -> 28 | J5: =+GETPIVOTDATA("Sum of On Time",'Pivot Cleansing'!$A$3,"Week No",J$2) -> 34 | ... AQ5: =+GETPIVOTDATA("Sum of On Time",'Pivot Cleansing'!$A$3,"Week No",AQ$2) -> 51
B6: Total Count | C6: =GETPIVOTDATA("Count of Order Tracking: Order Tracking No",'Pivot Cleansing'!$A$3,"Week No",C$2) -> 153 | D6: =GETPIVOTDATA("Count of Order Tracking: Order Tracking No",'Pivot Cleansing'!$A$3,"Week No",D$2) -> 103 | E6: =GETPIVOTDATA("Count of Order Tracking: Order Tracking No",'Pivot Cleansing'!$A$3,"Week No",E$2) -> 80 | F6: =GETPIVOTDATA("Count of Order Tracking: Order Tracking No",'Pivot Cleansing'!$A$3,"Week No",F$2) -> 46 | G6: =GETPIVOTDATA("Count of Order Tracking: Order Tracking No",'Pivot Cleansing'!$A$3,"Week No",G$2) -> 57 | H6: =GETPIVOTDATA("Count of Order Tracking: Order Tracking No",'Pivot Cleansing'!$A$3,"Week No",H$2) -> 51 | I6: =GETPIVOTDATA("Count of Order Tracking: Order Tracking No",'Pivot Cleansing'!$A$3,"Week No",I$2) -> 45 | J6: =GETPIVOTDATA("Count of Order Tracking: Order Tracking No",'Pivot Cleansing'!$A$3,"Week No",J$2) -> 52 | ... AQ6: =GETPIVOTDATA("Count of Order Tracking: Order Tracking No",'Pivot Cleansing'!$A$3,"Week No",AQ$2) -> 51
C7: =+C5/C6 -> 0.92156863 | D7: =+D5/D6 -> 0.95145631 | E7: =+E5/E6 -> 0.6875 | F7: =+F5/F6 -> 0.32608696 | G7: =+G5/G6 -> 0.56140351 | H7: =+H5/H6 -> 0.58823529 | I7: =+I5/I6 -> 0.62222222 | J7: =+J5/J6 -> 0.65384615 | ... AQ7: =+AQ5/AQ6 -> 1
B9: Sign off
C10: =+GETPIVOTDATA("Sum of On Time",'Pivot Sign Off'!$A$3,"Week No",C$2)/GETPIVOTDATA("Count of Order Tracking: Order Tracking No",'Pivot Sign Off'!$A$3,"Week No",C$2) -> 0.86928105 | D10: =+GETPIVOTDATA("Sum of On Time",'Pivot Sign Off'!$A$3,"Week No",D$2)/GETPIVOTDATA("Count of Order Tracking: Order Tracking No",'Pivot Sign Off'!$A$3,"Week No",D$2) -> 0.88349515 | E10: =+GETPIVOTDATA("Sum of On Time",'Pivot Sign Off'!$A$3,"Week No",E$2)/GETPIVOTDATA("Count of Order Tracking: Order Tracking No",'Pivot Sign Off'!$A$3,"Week No",E$2) -> 0.8375 | F10: =+GETPIVOTDATA("Sum of On Time",'Pivot Sign Off'!$A$3,"Week No",F$2)/GETPIVOTDATA("Count of Order Tracking: Order Tracking No",'Pivot Sign Off'!$A$3,"Week No",F$2) -> 0.91304348 | G10: =+GETPIVOTDATA("Sum of On Time",'Pivot Sign Off'!$A$3,"Week No",G$2)/GETPIVOTDATA("Count of Order Tracking: Order Tracking No",'Pivot Sign Off'!$A$3,"Week No",G$2) -> 0.80701754 | H10: =+GETPIVOTDATA("Sum of On Time",'Pivot Sign Off'!$A$3,"Week No",H$2)/GETPIVOTDATA("Count of Order Tracking: Order Tracking No",'Pivot Sign Off'!$A$3,"Week No",H$2) -> 0.82352941 | I10: =+GETPIVOTDATA("Sum of On Time",'Pivot Sign Off'!$A$3,"Week No",I$2)/GETPIVOTDATA("Count of Order Tracking: Order Tracking No",'Pivot Sign Off'!$A$3,"Week No",I$2) -> 0.75555556 | J10: =+GETPIVOTDATA("Sum of On Time",'Pivot Sign Off'!$A$3,"Week No",J$2)/GETPIVOTDATA("Count of Order Tracking: Order Tracking No",'Pivot Sign Off'!$A$3,"Week No",J$2) -> 0.69230769 | ... AQ10: =+GETPIVOTDATA("Sum of On Time",'Pivot Sign Off'!$A$3,"Week No",AQ$2)/GETPIVOTDATA("Count of Order Tracking: Order Tracking No",'Pivot Sign Off'!$A$3,"Week No",AQ$2) -> 1
B11: On Time | C11: =+GETPIVOTDATA("Sum of On Time",'Pivot Sign Off'!$A$3,"Week No",C$2) -> 133 | D11: =+GETPIVOTDATA("Sum of On Time",'Pivot Sign Off'!$A$3,"Week No",D$2) -> 91 | E11: =+GETPIVOTDATA("Sum of On Time",'Pivot Sign Off'!$A$3,"Week No",E$2) -> 67 | F11: =+GETPIVOTDATA("Sum of On Time",'Pivot Sign Off'!$A$3,"Week No",F$2) -> 42 | G11: =+GETPIVOTDATA("Sum of On Time",'Pivot Sign Off'!$A$3,"Week No",G$2) -> 46 | H11: =+GETPIVOTDATA("Sum of On Time",'Pivot Sign Off'!$A$3,"Week No",H$2) -> 42 | I11: =+GETPIVOTDATA("Sum of On Time",'Pivot Sign Off'!$A$3,"Week No",I$2) -> 34 | J11: =+GETPIVOTDATA("Sum of On Time",'Pivot Sign Off'!$A$3,"Week No",J$2) -> 36 | ... AQ11: =+GETPIVOTDATA("Sum of On Time",'Pivot Sign Off'!$A$3,"Week No",AQ$2) -> 51
B12: Total Count | C12: =GETPIVOTDATA("Count of Order Tracking: Order Tracking No",'Pivot Sign Off'!$A$3,"Week No",C$2) -> 153 | D12: =GETPIVOTDATA("Count of Order Tracking: Order Tracking No",'Pivot Sign Off'!$A$3,"Week No",D$2) -> 103 | E12: =GETPIVOTDATA("Count of Order Tracking: Order Tracking No",'Pivot Sign Off'!$A$3,"Week No",E$2) -> 80 | F12: =GETPIVOTDATA("Count of Order Tracking: Order Tracking No",'Pivot Sign Off'!$A$3,"Week No",F$2) -> 46 | G12: =GETPIVOTDATA("Count of Order Tracking: Order Tracking No",'Pivot Sign Off'!$A$3,"Week No",G$2) -> 57 | H12: =GETPIVOTDATA("Count of Order Tracking: Order Tracking No",'Pivot Sign Off'!$A$3,"Week No",H$2) -> 51 | I12: =GETPIVOTDATA("Count of Order Tracking: Order Tracking No",'Pivot Sign Off'!$A$3,"Week No",I$2) -> 45 | J12: =GETPIVOTDATA("Count of Order Tracking: Order Tracking No",'Pivot Sign Off'!$A$3,"Week No",J$2) -> 52 | ... AQ12: =GETPIVOTDATA("Count of Order Tracking: Order Tracking No",'Pivot Sign Off'!$A$3,"Week No",AQ$2) -> 51
C13: =+C11/C12 -> 0.86928105 | D13: =+D11/D12 -> 0.88349515 | E13: =+E11/E12 -> 0.8375 | F13: =+F11/F12 -> 0.91304348 | G13: =+G11/G12 -> 0.80701754 | H13: =+H11/H12 -> 0.82352941 | I13: =+I11/I12 -> 0.75555556 | J13: =+J11/J12 -> 0.69230769 | ... AQ13: =+AQ11/AQ12 -> 1
B16: On this data, the week are collated by the raised dates,
B17: As orders are there longer than the target, it will trigger them not being on time
B18: i.e a record created in week 26 will be on time, when reported in week 26 and week 27 | R18: 24
B19: If its still there in week 28 it will be overdue, | R19: 25
B20: so the historic record of week 26 will change. If originally there were 25 records 100% on time, now week 26 would change to 96%, if just this record became overdue. | R20: =+R18/R19 -> 0.96

Sheet Pivot Cleansing
D2: Cleansing OTIF
A3: Row Labels | B3: Count of Order Tracking: Order Tracking No | C3: Sum of On Time
A4: (blank)
A5: 2 | B5: 153 | C5: 141
A6: 3 | B6: 103 | C6: 98
A7: 4 | B7: 80 | C7: 55
A8: 5 | B8: 46 | C8: 15
A9: 6 | B9: 57 | C9: 32
A10: 7 | B10: 51 | C10: 30
A11: 8 | B11: 45 | C11: 28
A12: 9 | B12: 52 | C12: 34
A13: 10 | B13: 51 | C13: 21
A14: 11 | B14: 48 | C14: 27
A15: 12 | B15: 44 | C15: 22
A16: 13 | B16: 42 | C16: 26
... A45: 42 | B45: 51 | C45: 51
A46: Grand Total | B46: 2141 | C46: 1433

Sheet Pivot Sign Off
D2: Sign off OTIF
A3: Row Labels | B3: Count of Order Tracking: Order Tracking No | C3: Sum of On Time
A4: (blank)
A5: 2 | B5: 153 | C5: 133
A6: 3 | B6: 103 | C6: 91
A7: 4 | B7: 80 | C7: 67
A8: 5 | B8: 46 | C8: 42
A9: 6 | B9: 57 | C9: 46
A10: 7 | B10: 51 | C10: 42
A11: 8 | B11: 45 | C11: 34
A12: 9 | B12: 52 | C12: 36
A13: 10 | B13: 51 | C13: 37
A14: 11 | B14: 48 | C14: 34
A15: 12 | B15: 44 | C15: 34
A16: 13 | B16: 42 | C16: 29
... A45: 42 | B45: 51 | C45: 51
A46: Grand Total | B46: 2141 | C46: 1635

Sheet No of Complaints raised per wee
A1: Company Name | B1: Contact Name | C1: Project Name | D1: Customer Service Number | E1: Fault Category | F1: Department | G1: Date/Time Opened | H1: Sales Divison | I1: Department2 | J1: Extract Date | K1: week No
A2: Maris Contracts | B2: Daniel Tully | C2: HILLSWOOD DRIVE NO 1000 CHERTSEY | D2: 00022117 | E2: S - Billing Error | F2: Salesforce | G2: 07/01/2025, 09:30 | H2: UK | I2: =_xlfn.XLOOKUP(F2,'Lookup List'!A:A,'Lookup List'!B:B,FALSE) -> Salesforce | J2: =LEFT(G2,10) -> 07/01/2025 | K2: =_xlfn.XLOOKUP(J2,'Wk no''s'!D:D,'Wk no''s'!C:C,FALSE) -> 2
A3: Overbury Interiors Plc | B3: Mick Beckham | C3: PARK HOUSE FINSBURY CIRCUS NO 16/18 PH 1 FLR 6 CISCO LONDON | D3: 00022119 | E3: Q - Product Damaged | F3: Shop Floor | G3: 07/01/2025, 09:41 | H3: UK | I3: =_xlfn.XLOOKUP(F3,'Lookup List'!A:A,'Lookup List'!B:B,FALSE) -> 03 Shop Floor | J3: =LEFT(G3,10) -> 07/01/2025 | K3: =_xlfn.XLOOKUP(J3,'Wk no''s'!D:D,'Wk no''s'!C:C,FALSE) -> 2
A4: Celtic Contractors Ltd | B4: Paul Cooney | C4: DEVONSHIRE SQUARE NO 2-5 PREMIER PLACE CAT B JANE STREET | D4: 00022131 | E4: N - Not a valid complaint | F4: N/A | G4: 08/01/2025, 11:57 | H4: UK | I4: =_xlfn.XLOOKUP(F4,'Lookup List'!A:A,'Lookup List'!B:B,FALSE) -> N/A | J4: =LEFT(G4,10) -> 08/01/2025 | K4: =_xlfn.XLOOKUP(J4,'Wk no''s'!D:D,'Wk no''s'!C:C,FALSE) -> 2
A5: Celtic Contractors Ltd | B5: Paul Cooney | C5: DEVONSHIRE SQUARE NO 2-5 PREMIER PLACE CAT B JANE STREET | D5: 00022134 | E5: Q - Product packaging issue | F5: Assembly | G5: 08/01/2025, 12:58 | H5: UK | I5: =_xlfn.XLOOKUP(F5,'Lookup List'!A:A,'Lookup List'!B:B,FALSE) -> 03 Assembly | J5: =LEFT(G5,10) -> 08/01/2025 | K5: =_xlfn.XLOOKUP(J5,'Wk no''s'!D:D,'Wk no''s'!C:C,FALSE) -> 2
A6: Nevill Long Ltd Northampton | B6: Gemma Drake | C6: CAMBRIDGE SCIENCE PARK BUILDING 22 | D6: 00022136 | E6: Q - Product Damaged | F6: Transport | G6: 08/01/2025, 14:12 | H6: UK | I6: =_xlfn.XLOOKUP(F6,'Lookup List'!A:A,'Lookup List'!B:B,FALSE) -> Transport | J6: =LEFT(G6,10) -> 08/01/2025 | K6: =_xlfn.XLOOKUP(J6,'Wk no''s'!D:D,'Wk no''s'!C:C,FALSE) -> 2
A7: BPC Interiors Ltd | B7: Tony Edwards | C7: MANCHESTER SQUARE NO 20 CAT B LAZARD LONDON | D7: 00022144 | E7: S - Not delivered | F7: UK SOP | G7: 09/01/2025, 11:47 | H7: UK | I7: =_xlfn.XLOOKUP(F7,'Lookup List'!A:A,'Lookup List'!B:B,FALSE) -> 01 SOP | J7: =LEFT(G7,10) -> 09/01/2025 | K7: =_xlfn.XLOOKUP(J7,'Wk no''s'!D:D,'Wk no''s'!C:C,FALSE) -> 2
A8: SIG Interiors Ltd (Croydon) | B8: Albina Elston | C8: NATIONAL PHYSICAL LABATORY L4 G8 REFURB LONDON | D8: 00022145 | E8: S - Sales order processing error | F8: UK SOP | G8: 09/01/2025, 13:10 | H8: UK | I8: =_xlfn.XLOOKUP(F8,'Lookup List'!A:A,'Lookup List'!B:B,FALSE) -> 01 SOP | J8: =LEFT(G8,10) -> 09/01/2025 | K8: =_xlfn.XLOOKUP(J8,'Wk no''s'!D:D,'Wk no''s'!C:C,FALSE) -> 2
A9: Laser (Essex) Ltd | B9: Tracey Willis | C9: PRINCIPAL PLACE LHR 16 AMAZON SCREENING ROOM LONDON | D9: 00022147 | E9: S - Incorrect carriage or storage method | F9: Transport | G9: 09/01/2025, 13:22 | H9: UK | I9: =_xlfn.XLOOKUP(F9,'Lookup List'!A:A,'Lookup List'!B:B,FALSE) -> Transport | J9: =LEFT(G9,10) -> 09/01/2025 | K9: =_xlfn.XLOOKUP(J9,'Wk no''s'!D:D,'Wk no''s'!C:C,FALSE) -> 2
A10: Workplace Interiors Company Cheltenham Ltd | B10: Chloe Phillips | C10: WORKPLACE INTERIORS MISC 2025 | D10: 00022152 | E10: Q - Product packaging issue | F10: Warehouse | G10: 09/01/2025, 14:48 | H10: UK | I10: =_xlfn.XLOOKUP(F10,'Lookup List'!A:A,'Lookup List'!B:B,FALSE) -> Warehouse | J10: =LEFT(G10,10) -> 09/01/2025 | K10: =_xlfn.XLOOKUP(J10,'Wk no''s'!D:D,'Wk no''s'!C:C,FALSE) -> 2
A11: SAS International Inc | B11: Kelly Karakoutas | C11: PARK AVENUE 270 AMENITY FLOORS 15 & 16, JP MORGAN | D11: 00022138 | E11: Q - Product manufactured incorrectly | F11: Product Design/Engineering | G11: 09/01/2025, 07:39 | H11: USA | I11: =_xlfn.XLOOKUP(F11,'Lookup List'!A:A,'Lookup List'!B:B,FALSE) -> 02 Product Design | J11: =LEFT(G11,10) -> 09/01/2025 | K11: =_xlfn.XLOOKUP(J11,'Wk no''s'!D:D,'Wk no''s'!C:C,FALSE) -> 2
A12: SAS International Inc | B12: Kelly Karakoutas | C12: MADISON AVENUE 550 CLAYTON DUBILIER & RICE FIT OUT | D12: 00022150 | E12: C - Customer Dispute | F12: Customer | G12: 09/01/2025, 14:20 | H12: USA | I12: =_xlfn.XLOOKUP(F12,'Lookup List'!A:A,'Lookup List'!B:B,FALSE) -> Customer | J12: =LEFT(G12,10) -> 09/01/2025 | K12: =_xlfn.XLOOKUP(J12,'Wk no''s'!D:D,'Wk no''s'!C:C,FALSE) -> 2
A13: SAS International Inc | B13: Anthony Berardo | C13: PARK AVENUE 270 LOBBY JP MORGAN HQ NEW YORK | D13: 00022154 | E13: C - Customer Dispute | F13: Customer | G13: 09/01/2025, 16:41 | H13: USA | I13: =_xlfn.XLOOKUP(F13,'Lookup List'!A:A,'Lookup List'!B:B,FALSE) -> Customer | J13: =LEFT(G13,10) -> 09/01/2025 | K13: =_xlfn.XLOOKUP(J13,'Wk no''s'!D:D,'Wk no''s'!C:C,FALSE) -> 2
... A226: K & B Ceilings Ltd | B226: Brent Davies | C226: LOWER MARSH NO 1-5 LOMA DEVELOPMENT LONDON | D226: 00022928 | E226: S - Sales order processing error | F226: UK SOP | G226: 24/04/2025, 14:18 | H226: UK | I226: =_xlfn.XLOOKUP(F226,'Lookup List'!A:A,'Lookup List'!B:B,FALSE) -> 01 SOP | J226: =LEFT(G226,10) -> 24/04/2025 | K226: =_xlfn.XLOOKUP(J226,'Wk no''s'!D:D,'Wk no''s'!C:C,FALSE) -> 17
A227: SAS Innovation | B227: Luke Chapman-Burns | C227: Events | D227: 00022982 | E227: Q - Product manufactured incorrectly | F227: Product Design | G227: 01/05/2025, 11:45 | I227: =_xlfn.XLOOKUP(F227,'Lookup List'!A:A,'Lookup List'!B:B,FALSE) -> 02 Product Design | J227: =LEFT(G227,10) -> 01/05/2025 | K227: =_xlfn.XLOOKUP(J227,'Wk no''s'!D:D,'Wk no''s'!C:C,FALSE) -> 18
A228: SAS International | B228: Ferouz Benamour | C228: BOULEVARD HAUSSMANN 14 PARIS | D228: 00022973 | E228: Q - Product Finish Issue - Aesthetics | F228: Assembly | G228: 01/05/2025, 08:07 | H228: France | I228: =_xlfn.XLOOKUP(F228,'Lookup List'!A:A,'Lookup List'!B:B,FALSE) -> 03 Assembly | J228: =LEFT(G228,10) -> 01/05/2025 | K228: =_xlfn.XLOOKUP(J228,'Wk no''s'!D:D,'Wk no''s'!C:C,FALSE) -> 18
A229: SAS International Dublin | B229: Chris Carey | C229: APPLE HH5 EXTENSION CORK | D229: 00022986 | E229: Q - Product manufactured incorrectly | F229: Product Design | G229: 01/05/2025, 14:02 | H229: Ireland | I229: =_xlfn.XLOOKUP(F229,'Lookup List'!A:A,'Lookup List'!B:B,FALSE) -> 02 Product Design | J229: =LEFT(G229,10) -> 01/05/2025 | K229: =_xlfn.XLOOKUP(J229,'Wk no''s'!D:D,'Wk no''s'!C:C,FALSE) -> 18
A230: SAS International Dublin | B230: Chris Carey | C230: A & L GOODBODY NORTH WALL QUAY 25-28 DUBLIN | D230: 00022989 | E230: Q - Product manufactured incorrectly | F230: Shop Floor | G230: 01/05/2025, 14:59 | H230: Ireland | I230: =_xlfn.XLOOKUP(F230,'Lookup List'!A:A,'Lookup List'!B:B,FALSE) -> 03 Shop Floor | J230: =LEFT(G230,10) -> 01/05/2025 | K230: =_xlfn.XLOOKUP(J230,'Wk no''s'!D:D,'Wk no''s'!C:C,FALSE) -> 18
A231: Summertown International | B231: Alano Angeles | C231: SCHNEIDER ELECTRIC SILICON OASIS DUBAI | D231: 00022947 | E231: Q - Picking Error | F231: Assembly | G231: 28/04/2025, 11:48 | H231: Middle East | I231: =_xlfn.XLOOKUP(F231,'Lookup List'!A:A,'Lookup List'!B:B,FALSE) -> 03 Assembly | J231: =LEFT(G231,10) -> 28/04/2025 | K231: =_xlfn.XLOOKUP(J231,'Wk no''s'!D:D,'Wk no''s'!C:C,FALSE) -> 18
A232: Integra Contracts Ltd | B232: Gary Thursting | C232: MOORFIELDS NO 21 DEUTSCHE BANK REFURB LONDON | D232: 00022940 | E232: Q - Picking Error | F232: Fast Track | G232: 28/04/2025, 11:00 | H232: UK | I232: =_xlfn.XLOOKUP(F232,'Lookup List'!A:A,'Lookup List'!B:B,FALSE) -> Fast Track | J232: =LEFT(G232,10) -> 28/04/2025 | K232: =_xlfn.XLOOKUP(J232,'Wk no''s'!D:D,'Wk no''s'!C:C,FALSE) -> 18
A233: Belgrade Insulations Ltd | B233: Luke Raven | C233: BUCKINGHAM PALACE ROAD NO 110 REFURB LONDON | D233: 00022943 | E233: Q - Product Damaged | F233: Supplier | G233: 28/04/2025, 11:29 | H233: UK | I233: =_xlfn.XLOOKUP(F233,'Lookup List'!A:A,'Lookup List'!B:B,FALSE) -> Supplier | J233: =LEFT(G233,10) -> 28/04/2025 | K233: =_xlfn.XLOOKUP(J233,'Wk no''s'!D:D,'Wk no''s'!C:C,FALSE) -> 18
A234: Maris Contracts | B234: Petru Guglea | C234: PORTMAN SQUARE NO 10 LVL 3 REFURB LONDON | D234: 00022945 | E234: S - Transit damage | F234: Transport | G234: 28/04/2025, 11:36 | H234: UK | I234: =_xlfn.XLOOKUP(F234,'Lookup List'!A:A,'Lookup List'!B:B,FALSE) -> Transport | J234: =LEFT(G234,10) -> 28/04/2025 | K234: =_xlfn.XLOOKUP(J234,'Wk no''s'!D:D,'Wk no''s'!C:C,FALSE) -> 18
A235: Global Insulation Logistics Ltd | B235: Martyn Roberts | C235: PULSANT DATA CENTRE SE-1 MILTON KEYNES | D235: 00022951 | E235: C - Customer Dispute | F235: Customer | G235: 28/04/2025, 14:52 | H235: UK | I235: =_xlfn.XLOOKUP(F235,'Lookup List'!A:A,'Lookup List'!B:B,FALSE) -> Customer | J235: =LEFT(G235,10) -> 28/04/2025 | K235: =_xlfn.XLOOKUP(J235,'Wk no''s'!D:D,'Wk no''s'!C:C,FALSE) -> 18
A236: Orangebox Ltd | B236: Ben Matthews | C236: ORANGEBOX POD CASSETTES | D236: 00022958 | E236: Q - Product is Deformed | F236: Assembly | G236: 29/04/2025, 11:21 | H236: UK | I236: =_xlfn.XLOOKUP(F236,'Lookup List'!A:A,'Lookup List'!B:B,FALSE) -> 03 Assembly | J236: =LEFT(G236,10) -> 29/04/2025 | K236: =_xlfn.XLOOKUP(J236,'Wk no''s'!D:D,'Wk no''s'!C:C,FALSE) -> 18
A237: BPC Interiors Ltd | B237: Tony Edwards | C237: ST MICHAELS TOWER FLRS 3, 4 AND 5 MANCHESTER | D237: 00022960 | E237: S - Transit damage | F237: Transport | G237: 29/04/2025, 13:20 | H237: UK | I237: =_xlfn.XLOOKUP(F237,'Lookup List'!A:A,'Lookup List'!B:B,FALSE) -> Transport | J237: =LEFT(G237,10) -> 29/04/2025 | K237: =_xlfn.XLOOKUP(J237,'Wk no''s'!D:D,'Wk no''s'!C:C,FALSE) -> 18
A238: Encon Insulation Ltd (Thetford) | B238: Jane Smith | C238: UNI OF EAST ANGLIA MEDICAL SCHOOL REFURB | D238: 00022969 | E238: Q - Product manufactured incorrectly | F238: Salesforce | G238: 30/04/2025, 10:32 | H238: UK | I238: =_xlfn.XLOOKUP(F238,'Lookup List'!A:A,'Lookup List'!B:B,FALSE) -> Salesforce | J238: =LEFT(G238,10) -> 30/04/2025 | K238: =_xlfn.XLOOKUP(J238,'Wk no''s'!D:D,'Wk no''s'!C:C,FALSE) -> 18
A239: Wates Construction (Head Office - Leatherhead) | B239: Emma Nevin | C239: VICTORIA HOUSE BLOOMSBURY SQUARE LONDON | D239: 00022971 | E239: S - Sales order processing error | F239: UK SOP | G239: 30/04/2025, 15:32 | H239: UK | I239: =_xlfn.XLOOKUP(F239,'Lookup List'!A:A,'Lookup List'!B:B,FALSE) -> 01 SOP | J239: =LEFT(G239,10) -> 30/04/2025 | K239: =_xlfn.XLOOKUP(J239,'Wk no''s'!D:D,'Wk no''s'!C:C,FALSE) -> 18
... A559: SAS International Inc | B559: Kelly Karakoutas | C559: 5TH AVENUE NO 665 ROLEX HQ NEW YORK | D559: 00024104 | E559: Q - Product manufactured incorrectly | F559: RDG â€“ Design | G559: 15/10/2025, 10:55 | H559: USA | I559: =_xlfn.XLOOKUP(F559,'Lookup List'!A:A,'Lookup List'!B:B,FALSE) -> FALSE | J559: =LEFT(G559,10) -> 15/10/2025 | K559: =_xlfn.XLOOKUP(J559,'Wk no''s'!D:D,'Wk no''s'!C:C,FALSE) -> 42

Sheet Cleansing OTIF
A1: Order Tracking: Order Tracking No | B1: Infor Order Reference | C1: Project Name | D1: Days In Cleansing | E1: On Time | F1: Order Tracking: Created Date | G1: Week No
A2: ORT-0000010139 | B2: C000416282 | C2: COPTHALL BRIDGE HOUSE HARROGATE | D2: 0 | E2: 1 | F2: 45663 | G2: =_xlfn.XLOOKUP(F2,'Wk no''s'!B:B,'Wk no''s'!C:C,0) -> 2
A3: ORT-0000010140 | B3: C000416283 | C3: SOUTH LONDON & MAUDSLEY HOSPITAL CYP HOUSE LONDON | D3: 0 | E3: 1 | F3: 45663 | G3: =_xlfn.XLOOKUP(F3,'Wk no''s'!B:B,'Wk no''s'!C:C,0) -> 2
A4: ORT-0000010141 | B4: C000416284 | C4: LEADENHALL STREET NO 40 KIRKLAND & ELLIS FLRS 15-34 LONDON | D4: 0 | E4: 1 | F4: 45663 | G4: =_xlfn.XLOOKUP(F4,'Wk no''s'!B:B,'Wk no''s'!C:C,0) -> 2
A5: ORT-0000010142 | B5: C000416285 | C5: MISC TILE & GRID PROJECTS | D5: 0 | E5: 1 | F5: 45663 | G5: =_xlfn.XLOOKUP(F5,'Wk no''s'!B:B,'Wk no''s'!C:C,0) -> 2
A6: ORT-0000010143 | B6: C000416286 | C6: GROSVENOR SQUARE NO 30 ROSEWOOD HOTEL LONDON | D6: 0 | E6: 1 | F6: 45663 | G6: =_xlfn.XLOOKUP(F6,'Wk no''s'!B:B,'Wk no''s'!C:C,0) -> 2
A7: ORT-0000010144 | B7: C000416287 | C7: MANCHESTER AIRPORT T2 EAST WING NEW DEVELOPMENT | D7: 2 | E7: 0 | F7: 45663 | G7: =_xlfn.XLOOKUP(F7,'Wk no''s'!B:B,'Wk no''s'!C:C,0) -> 2
A8: ORT-0000010145 | B8: C000416288 | C8: MANCHESTER AIRPORT T2 EAST WING NEW DEVELOPMENT | D8: 1 | E8: 1 | F8: 45663 | G8: =_xlfn.XLOOKUP(F8,'Wk no''s'!B:B,'Wk no''s'!C:C,0) -> 2
A9: ORT-0000010146 | B9: C000416289 | C9: DALES MANOR BUSINESS PARK CAT A CAMBRIDGE | D9: 0 | E9: 1 | F9: 45663 | G9: =_xlfn.XLOOKUP(F9,'Wk no''s'!B:B,'Wk no''s'!C:C,0) -> 2
A10: ORT-0000010147 | B10: C000416290 | C10: DOVER STREET NO 48 CAT B SIXTH STREET LONDON | D10: 0 | E10: 1 | F10: 45663 | G10: =_xlfn.XLOOKUP(F10,'Wk no''s'!B:B,'Wk no''s'!C:C,0) -> 2
A11: ORT-0000010148 | B11: C000416291 | C11: MISC TILE & GRID PROJECTS | D11: 0 | E11: 1 | F11: 45663 | G11: =_xlfn.XLOOKUP(F11,'Wk no''s'!B:B,'Wk no''s'!C:C,0) -> 2
A12: ORT-0000010149 | B12: C000416292 | C12: SOUTH PARADE NO 10 GRND FLR LEEDS | D12: 0 | E12: 1 | F12: 45663 | G12: =_xlfn.XLOOKUP(F12,'Wk no''s'!B:B,'Wk no''s'!C:C,0) -> 2
A13: ORT-0000010150 | B13: C000416293 | C13: HCA HALE MANCHESTER | D13: 1 | E13: 1 | F13: 45663 | G13: =_xlfn.XLOOKUP(F13,'Wk no''s'!B:B,'Wk no''s'!C:C,0) -> 2
... A25: ORT-0000010162 | B25: C000416308 | C25: TESCO MISC 2025 | D25: 0 | E25: 1 | F25: 45663 | G25: =_xlfn.XLOOKUP(F25,'Wk no''s'!B:B,'Wk no''s'!C:C,0) -> 2
A26: ORT-0000010163 | C26: OCASO FUENCARRAL 107 MADRID | D26: 0 | E26: 1 | F26: 45663 | G26: =_xlfn.XLOOKUP(F26,'Wk no''s'!B:B,'Wk no''s'!C:C,0) -> 2
A27: ORT-0000010164 | B27: C000416311 | C27: CHEAPSIDE NO 100 CAT B CRAVAITH SWAINE & MOORE LONDON | D27: 0 | E27: 1 | F27: 45663 | G27: =_xlfn.XLOOKUP(F27,'Wk no''s'!B:B,'Wk no''s'!C:C,0) -> 2
A28: ORT-0000010165 | B28: C000416313 | C28: JACK TURNBULL MISC TILE & GRID 2025 | D28: 0 | E28: 1 | F28: 45663 | G28: =_xlfn.XLOOKUP(F28,'Wk no''s'!B:B,'Wk no''s'!C:C,0) -> 2
A29: ORT-0000010166 | B29: C000416314 | C29: BOLDON HOUSE DURHAM UNIVERSITY | D29: 0 | E29: 1 | F29: 45664 | G29: =_xlfn.XLOOKUP(F29,'Wk no''s'!B:B,'Wk no''s'!C:C,0) -> 2
A30: ORT-0000010167 | B30: C000416315 | C30: TESCO MISC 2025 | D30: 0 | E30: 1 | F30: 45664 | G30: =_xlfn.XLOOKUP(F30,'Wk no''s'!B:B,'Wk no''s'!C:C,0) -> 2
A31: ORT-0000010168 | B31: C000416316 | C31: TESCO MISC 2025 | D31: 0 | E31: 1 | F31: 45664 | G31: =_xlfn.XLOOKUP(F31,'Wk no''s'!B:B,'Wk no''s'!C:C,0) -> 2
A32: ORT-0000010169 | B32: C000416317 | C32: WORKPLACE INTERIORS MISC 2025 | D32: 0 | E32: 1 | F32: 45664 | G32: =_xlfn.XLOOKUP(F32,'Wk no''s'!B:B,'Wk no''s'!C:C,0) -> 2
A33: ORT-0000010170 | B33: C000416318 | C33: KINGS ROAD NO 120 LIBERTY GLOBAL FABRIC LONDON | D33: 0 | E33: 1 | F33: 45664 | G33: =_xlfn.XLOOKUP(F33,'Wk no''s'!B:B,'Wk no''s'!C:C,0) -> 2
A34: ORT-0000010171 | B34: C000416319 | C34: CITY POINT ROPEMAKER STREET FLR 16 REFURB LONDON | D34: 0 | E34: 1 | F34: 45664 | G34: =_xlfn.XLOOKUP(F34,'Wk no''s'!B:B,'Wk no''s'!C:C,0) -> 2
A35: ORT-0000010172 | B35: C000416320 | C35: UNI OF OXFORD CENTRE FOR LIFE AND MIND SCIENCES | D35: 0 | E35: 1 | F35: 45664 | G35: =_xlfn.XLOOKUP(F35,'Wk no''s'!B:B,'Wk no''s'!C:C,0) -> 2
A36: ORT-0000010173 | B36: C000416321 | C36: NORTHCLIFFE HOUSE TUDOR STREET NO 26 FLRS 4-6 LONDON | D36: 0 | E36: 1 | F36: 45664 | G36: =_xlfn.XLOOKUP(F36,'Wk no''s'!B:B,'Wk no''s'!C:C,0) -> 2
A37: ORT-0000010174 | B37: C000416322 | C37: CANNON STREET NO 110 FLR 7 REFURB LONDON | D37: 0 | E37: 1 | F37: 45664 | G37: =_xlfn.XLOOKUP(F37,'Wk no''s'!B:B,'Wk no''s'!C:C,0) -> 2
A38: ORT-0000010175 | B38: C000416323 | C38: UNKNOWN | D38: 0 | E38: 1 | F38: 45664 | G38: =_xlfn.XLOOKUP(F38,'Wk no''s'!B:B,'Wk no''s'!C:C,0) -> 2
... A98: ORT-0000010243 | B98: C000416440 | C98: MANCHESTER SQUARE NO 20 CAT B LAZARD LONDON | D98: 0 | E98: 1 | F98: 45666 | G98: =_xlfn.XLOOKUP(F98,'Wk no''s'!B:B,'Wk no''s'!C:C,0) -> 2
A99: ORT-0000010244 | C99: QUEENS QUAY BRISTOL CEILINGS | D99: 0 | E99: 1 | F99: 45666 | G99: =_xlfn.XLOOKUP(F99,'Wk no''s'!B:B,'Wk no''s'!C:C,0) -> 2
A100: ORT-0000010245 | B100: C000416442 | C100: MILLER HOMES LOCHSIDE VIEW NO 2 EDINBURGH | D100: 0 | E100: 1 | F100: 45666 | G100: =_xlfn.XLOOKUP(F100,'Wk no''s'!B:B,'Wk no''s'!C:C,0) -> 2
A101: ORT-0000010246 | B101: C000416443 | C101: LONDON WALL NO 120 MOOR HOUSE CITADEL REFURB LONDON | D101: 0 | E101: 1 | F101: 45666 | G101: =_xlfn.XLOOKUP(F101,'Wk no''s'!B:B,'Wk no''s'!C:C,0) -> 2
A102: ORT-0000010247 | B102: C000416444 | C102: OXFORD SCIENCE PARK PLOT 16 FIT OUT - IVERSEN BUILDING | D102: 0 | E102: 1 | F102: 45666 | G102: =_xlfn.XLOOKUP(F102,'Wk no''s'!B:B,'Wk no''s'!C:C,0) -> 2
A103: ORT-0000010248 | B103: C000416445 | C103: CAPITAL PARK CAMBRIDGE ROAD NO 2 FULBOURN CAMBRIDGE | D103: 3 | E103: 0 | F103: 45666 | G103: =_xlfn.XLOOKUP(F103,'Wk no''s'!B:B,'Wk no''s'!C:C,0) -> 2
A104: ORT-0000010249 | B104: C000416446 | C104: TFL TRAIN DEPOT CONTROLLERS ROOM CROYDON | D104: 0 | E104: 1 | F104: 45666 | G104: =_xlfn.XLOOKUP(F104,'Wk no''s'!B:B,'Wk no''s'!C:C,0) -> 2
A105: ORT-0000010250 | B105: C000416447 | C105: ST MICHAELS FLR 9 HILL DICKINSON LIGHTING MANCHESTER | D105: 1 | E105: 1 | F105: 45666 | G105: =_xlfn.XLOOKUP(F105,'Wk no''s'!B:B,'Wk no''s'!C:C,0) -> 2
A106: ORT-0000010251 | B106: C000416448 | C106: CAMBRIDGE BIOMEDICAL CAMPUS HISTOPATHOLOGY | D106: 0 | E106: 1 | F106: 45666 | G106: =_xlfn.XLOOKUP(F106,'Wk no''s'!B:B,'Wk no''s'!C:C,0) -> 2
A107: ORT-0000010252 | B107: C000416450 | C107: NEW DOHA INTERNATIONAL AIRPORT EXTENSION | D107: 0 | E107: 1 | F107: 45666 | G107: =_xlfn.XLOOKUP(F107,'Wk no''s'!B:B,'Wk no''s'!C:C,0) -> 2
A108: ORT-0000010253 | B108: C000416452 | C108: WORKPLACE INTERIORS MISC 2025 | D108: 0 | E108: 1 | F108: 45666 | G108: =_xlfn.XLOOKUP(F108,'Wk no''s'!B:B,'Wk no''s'!C:C,0) -> 2
A109: ORT-0000010254 | B109: C000416454 | C109: JACK TURNBULL MISC TILE & GRID 2025 | D109: 0 | E109: 1 | F109: 45666 | G109: =_xlfn.XLOOKUP(F109,'Wk no''s'!B:B,'Wk no''s'!C:C,0) -> 2
A110: ORT-0000010255 | B110: C000416456 | C110: DEWA HQ AL SHERAA BUILDING (B+G+4P+15) AL JADDAF | D110: 0 | E110: 1 | F110: 45666 | G110: =_xlfn.XLOOKUP(F110,'Wk no''s'!B:B,'Wk no''s'!C:C,0) -> 2
...

Sheet Sign Off OTIF
A1: Order Tracking: Order Tracking No | B1: Infor Order Reference | C1: Project Name | D1: Days In Customer Sign Off | E1: On Time | F1: Order Tracking: Created Date | G1: Week No
A2: ORT-0000010139 | B2: C000416282 | C2: COPTHALL BRIDGE HOUSE HARROGATE | D2: 0 | E2: 1 | F2: 45663 | G2: =_xlfn.XLOOKUP(F2,'Wk no''s'!B:B,'Wk no''s'!C:C,0) -> 2
A3: ORT-0000010140 | B3: C000416283 | C3: SOUTH LONDON & MAUDSLEY HOSPITAL CYP HOUSE LONDON | D3: 0 | E3: 1 | F3: 45663 | G3: =_xlfn.XLOOKUP(F3,'Wk no''s'!B:B,'Wk no''s'!C:C,0) -> 2
A4: ORT-0000010141 | B4: C000416284 | C4: LEADENHALL STREET NO 40 KIRKLAND & ELLIS FLRS 15-34 LONDON | D4: 0 | E4: 1 | F4: 45663 | G4: =_xlfn.XLOOKUP(F4,'Wk no''s'!B:B,'Wk no''s'!C:C,0) -> 2
A5: ORT-0000010142 | B5: C000416285 | C5: MISC TILE & GRID PROJECTS | D5: 0 | E5: 1 | F5: 45663 | G5: =_xlfn.XLOOKUP(F5,'Wk no''s'!B:B,'Wk no''s'!C:C,0) -> 2
A6: ORT-0000010143 | B6: C000416286 | C6: GROSVENOR SQUARE NO 30 ROSEWOOD HOTEL LONDON | D6: 0 | E6: 1 | F6: 45663 | G6: =_xlfn.XLOOKUP(F6,'Wk no''s'!B:B,'Wk no''s'!C:C,0) -> 2
A7: ORT-0000010144 | B7: C000416287 | C7: MANCHESTER AIRPORT T2 EAST WING NEW DEVELOPMENT | D7: 0 | E7: 1 | F7: 45663 | G7: =_xlfn.XLOOKUP(F7,'Wk no''s'!B:B,'Wk no''s'!C:C,0) -> 2
A8: ORT-0000010145 | B8: C000416288 | C8: MANCHESTER AIRPORT T2 EAST WING NEW DEVELOPMENT | D8: 0 | E8: 1 | F8: 45663 | G8: =_xlfn.XLOOKUP(F8,'Wk no''s'!B:B,'Wk no''s'!C:C,0) -> 2
A9: ORT-0000010146 | B9: C000416289 | C9: DALES MANOR BUSINESS PARK CAT A CAMBRIDGE | D9: 0 | E9: 1 | F9: 45663 | G9: =_xlfn.XLOOKUP(F9,'Wk no''s'!B:B,'Wk no''s'!C:C,0) -> 2
A10: ORT-0000010147 | B10: C000416290 | C10: DOVER STREET NO 48 CAT B SIXTH STREET LONDON | D10: 0 | E10: 1 | F10: 45663 | G10: =_xlfn.XLOOKUP(F10,'Wk no''s'!B:B,'Wk no''s'!C:C,0) -> 2
A11: ORT-0000010148 | B11: C000416291 | C11: MISC TILE & GRID PROJECTS | D11: 0 | E11: 1 | F11: 45663 | G11: =_xlfn.XLOOKUP(F11,'Wk no''s'!B:B,'Wk no''s'!C:C,0) -> 2
A12: ORT-0000010149 | B12: C000416292 | C12: SOUTH PARADE NO 10 GRND FLR LEEDS | D12: 6 | E12: 0 | F12: 45663 | G12: =_xlfn.XLOOKUP(F12,'Wk no''s'!B:B,'Wk no''s'!C:C,0) -> 2
A13: ORT-0000010150 | B13: C000416293 | C13: HCA HALE MANCHESTER | D13: 0 | E13: 1 | F13: 45663 | G13: =_xlfn.XLOOKUP(F13,'Wk no''s'!B:B,'Wk no''s'!C:C,0) -> 2
... A25: ORT-0000010162 | B25: C000416308 | C25: TESCO MISC 2025 | D25: 0 | E25: 1 | F25: 45663 | G25: =_xlfn.XLOOKUP(F25,'Wk no''s'!B:B,'Wk no''s'!C:C,0) -> 2
A26: ORT-0000010163 | C26: OCASO FUENCARRAL 107 MADRID | D26: 52 | E26: 0 | F26: 45663 | G26: =_xlfn.XLOOKUP(F26,'Wk no''s'!B:B,'Wk no''s'!C:C,0) -> 2
A27: ORT-0000010164 | B27: C000416311 | C27: CHEAPSIDE NO 100 CAT B CRAVAITH SWAINE & MOORE LONDON | D27: 0 | E27: 1 | F27: 45663 | G27: =_xlfn.XLOOKUP(F27,'Wk no''s'!B:B,'Wk no''s'!C:C,0) -> 2
A28: ORT-0000010165 | B28: C000416313 | C28: JACK TURNBULL MISC TILE & GRID 2025 | D28: 0 | E28: 1 | F28: 45663 | G28: =_xlfn.XLOOKUP(F28,'Wk no''s'!B:B,'Wk no''s'!C:C,0) -> 2
A29: ORT-0000010166 | B29: C000416314 | C29: BOLDON HOUSE DURHAM UNIVERSITY | D29: 0 | E29: 1 | F29: 45664 | G29: =_xlfn.XLOOKUP(F29,'Wk no''s'!B:B,'Wk no''s'!C:C,0) -> 2
A30: ORT-0000010167 | B30: C000416315 | C30: TESCO MISC 2025 | D30: 0 | E30: 1 | F30: 45664 | G30: =_xlfn.XLOOKUP(F30,'Wk no''s'!B:B,'Wk no''s'!C:C,0) -> 2
A31: ORT-0000010168 | B31: C000416316 | C31: TESCO MISC 2025 | D31: 0 | E31: 1 | F31: 45664 | G31: =_xlfn.XLOOKUP(F31,'Wk no''s'!B:B,'Wk no''s'!C:C,0) -> 2
A32: ORT-0000010169 | B32: C000416317 | C32: WORKPLACE INTERIORS MISC 2025 | D32: 0 | E32: 1 | F32: 45664 | G32: =_xlfn.XLOOKUP(F32,'Wk no''s'!B:B,'Wk no''s'!C:C,0) -> 2
A33: ORT-0000010170 | B33: C000416318 | C33: KINGS ROAD NO 120 LIBERTY GLOBAL FABRIC LONDON | D33: 1 | E33: 1 | F33: 45664 | G33: =_xlfn.XLOOKUP(F33,'Wk no''s'!B:B,'Wk no''s'!C:C,0) -> 2
A34: ORT-0000010171 | B34: C000416319 | C34: CITY POINT ROPEMAKER STREET FLR 16 REFURB LONDON | D34: 0 | E34: 1 | F34: 45664 | G34: =_xlfn.XLOOKUP(F34,'Wk no''s'!B:B,'Wk no''s'!C:C,0) -> 2
A35: ORT-0000010172 | B35: C000416320 | C35: UNI OF OXFORD CENTRE FOR LIFE AND MIND SCIENCES | D35: 0 | E35: 1 | F35: 45664 | G35: =_xlfn.XLOOKUP(F35,'Wk no''s'!B:B,'Wk no''s'!C:C,0) -> 2
A36: ORT-0000010173 | B36: C000416321 | C36: NORTHCLIFFE HOUSE TUDOR STREET NO 26 FLRS 4-6 LONDON | D36: 0 | E36: 1 | F36: 45664 | G36: =_xlfn.XLOOKUP(F36,'Wk no''s'!B:B,'Wk no''s'!C:C,0) -> 2
A37: ORT-0000010174 | B37: C000416322 | C37: CANNON STREET NO 110 FLR 7 REFURB LONDON | D37: 0 | E37: 1 | F37: 45664 | G37: =_xlfn.XLOOKUP(F37,'Wk no''s'!B:B,'Wk no''s'!C:C,0) -> 2
A38: ORT-0000010175 | B38: C000416323 | C38: UNKNOWN | D38: 0 | E38: 1 | F38: 45664 | G38: =_xlfn.XLOOKUP(F38,'Wk no''s'!B:B,'Wk no''s'!C:C,0) -> 2
... A98: ORT-0000010243 | B98: C000416440 | C98: MANCHESTER SQUARE NO 20 CAT B LAZARD LONDON | D98: 0 | E98: 1 | F98: 45666 | G98: =_xlfn.XLOOKUP(F98,'Wk no''s'!B:B,'Wk no''s'!C:C,0) -> 2
A99: ORT-0000010244 | C99: QUEENS QUAY BRISTOL CEILINGS | D99: 0 | E99: 1 | F99: 45666 | G99: =_xlfn.XLOOKUP(F99,'Wk no''s'!B:B,'Wk no''s'!C:C,0) -> 2
A100: ORT-0000010245 | B100: C000416442 | C100: MILLER HOMES LOCHSIDE VIEW NO 2 EDINBURGH | D100: 0 | E100: 1 | F100: 45666 | G100: =_xlfn.XLOOKUP(F100,'Wk no''s'!B:B,'Wk no''s'!C:C,0) -> 2
A101: ORT-0000010246 | B101: C000416443 | C101: LONDON WALL NO 120 MOOR HOUSE CITADEL REFURB LONDON | D101: 0 | E101: 1 | F101: 45666 | G101: =_xlfn.XLOOKUP(F101,'Wk no''s'!B:B,'Wk no''s'!C:C,0) -> 2
A102: ORT-0000010247 | B102: C000416444 | C102: OXFORD SCIENCE PARK PLOT 16 FIT OUT - IVERSEN BUILDING | D102: 0 | E102: 1 | F102: 45666 | G102: =_xlfn.XLOOKUP(F102,'Wk no''s'!B:B,'Wk no''s'!C:C,0) -> 2
A103: ORT-0000010248 | B103: C000416445 | C103: CAPITAL PARK CAMBRIDGE ROAD NO 2 FULBOURN CAMBRIDGE | D103: 20 | E103: 0 | F103: 45666 | G103: =_xlfn.XLOOKUP(F103,'Wk no''s'!B:B,'Wk no''s'!C:C,0) -> 2
A104: ORT-0000010249 | B104: C000416446 | C104: TFL TRAIN DEPOT CONTROLLERS ROOM CROYDON | D104: 0 | E104: 1 | F104: 45666 | G104: =_xlfn.XLOOKUP(F104,'Wk no''s'!B:B,'Wk no''s'!C:C,0) -> 2
A105: ORT-0000010250 | B105: C000416447 | C105: ST MICHAELS FLR 9 HILL DICKINSON LIGHTING MANCHESTER | D105: 20 | E105: 0 | F105: 45666 | G105: =_xlfn.XLOOKUP(F105,'Wk no''s'!B:B,'Wk no''s'!C:C,0) -> 2
A106: ORT-0000010251 | B106: C000416448 | C106: CAMBRIDGE BIOMEDICAL CAMPUS HISTOPATHOLOGY | D106: 2 | E106: 1 | F106: 45666 | G106: =_xlfn.XLOOKUP(F106,'Wk no''s'!B:B,'Wk no''s'!C:C,0) -> 2
A107: ORT-0000010252 | B107: C000416450 | C107: NEW DOHA INTERNATIONAL AIRPORT EXTENSION | D107: 76 | E107: 0 | F107: 45666 | G107: =_xlfn.XLOOKUP(F107,'Wk no''s'!B:B,'Wk no''s'!C:C,0) -> 2
A108: ORT-0000010253 | B108: C000416452 | C108: WORKPLACE INTERIORS MISC 2025 | D108: 0 | E108: 1 | F108: 45666 | G108: =_xlfn.XLOOKUP(F108,'Wk no''s'!B:B,'Wk no''s'!C:C,0) -> 2
A109: ORT-0000010254 | B109: C000416454 | C109: JACK TURNBULL MISC TILE & GRID 2025 | D109: 0 | E109: 1 | F109: 45666 | G109: =_xlfn.XLOOKUP(F109,'Wk no''s'!B:B,'Wk no''s'!C:C,0) -> 2
A110: ORT-0000010255 | B110: C000416456 | C110: DEWA HQ AL SHERAA BUILDING (B+G+4P+15) AL JADDAF | D110: 40 | E110: 0 | F110: 45666 | G110: =_xlfn.XLOOKUP(F110,'Wk no''s'!B:B,'Wk no''s'!C:C,0) -> 2
...

Sheet Wk no's
B1: Date | C1: Week No | D1: Date in Text Format
B2: 45658 | C2: 1 | D2: =TEXT(B2,"DD")&"/"&TEXT(B2,"MM")&"/"&TEXT(B2,"YYYY") -> 01/01/2025
B3: =+B2+1 -> 45659 | C3: 1 | D3: =TEXT(B3,"DD")&"/"&TEXT(B3,"MM")&"/"&TEXT(B3,"YYYY") -> 02/01/2025
A4: =TEXT(B4,"ddd") -> Fri | B4: =+B3+1 -> 45660 | C4: =IF(A4="Sat",C3+1,C3) -> 1 | D4: =TEXT(B4,"DD")&"/"&TEXT(B4,"MM")&"/"&TEXT(B4,"YYYY") -> 03/01/2025
A5: =TEXT(B5,"ddd") -> Sat | B5: =+B4+1 -> 45661 | C5: =IF(A5="Sat",C4+1,C4) -> 2 | D5: =TEXT(B5,"DD")&"/"&TEXT(B5,"MM")&"/"&TEXT(B5,"YYYY") -> 04/01/2025
A6: =TEXT(B6,"ddd") -> Sun | B6: =+B5+1 -> 45662 | C6: =IF(A6="Sat",C5+1,C5) -> 2 | D6: =TEXT(B6,"DD")&"/"&TEXT(B6,"MM")&"/"&TEXT(B6,"YYYY") -> 05/01/2025
A7: =TEXT(B7,"ddd") -> Mon | B7: =+B6+1 -> 45663 | C7: =IF(A7="Sat",C6+1,C6) -> 2 | D7: =TEXT(B7,"DD")&"/"&TEXT(B7,"MM")&"/"&TEXT(B7,"YYYY") -> 06/01/2025
A8: =TEXT(B8,"ddd") -> Tue | B8: =+B7+1 -> 45664 | C8: =IF(A8="Sat",C7+1,C7) -> 2 | D8: =TEXT(B8,"DD")&"/"&TEXT(B8,"MM")&"/"&TEXT(B8,"YYYY") -> 07/01/2025
A9: =TEXT(B9,"ddd") -> Wed | B9: =+B8+1 -> 45665 | C9: =IF(A9="Sat",C8+1,C8) -> 2 | D9: =TEXT(B9,"DD")&"/"&TEXT(B9,"MM")&"/"&TEXT(B9,"YYYY") -> 08/01/2025
A10: =TEXT(B10,"ddd") -> Thu | B10: =+B9+1 -> 45666 | C10: =IF(A10="Sat",C9+1,C9) -> 2 | D10: =TEXT(B10,"DD")&"/"&TEXT(B10,"MM")&"/"&TEXT(B10,"YYYY") -> 09/01/2025
A11: =TEXT(B11,"ddd") -> Fri | B11: =+B10+1 -> 45667 | C11: =IF(A11="Sat",C10+1,C10) -> 2 | D11: =TEXT(B11,"DD")&"/"&TEXT(B11,"MM")&"/"&TEXT(B11,"YYYY") -> 10/01/2025
A12: =TEXT(B12,"ddd") -> Sat | B12: =+B11+1 -> 45668 | C12: =IF(A12="Sat",C11+1,C11) -> 3 | D12: =TEXT(B12,"DD")&"/"&TEXT(B12,"MM")&"/"&TEXT(B12,"YYYY") -> 11/01/2025
A13: =TEXT(B13,"ddd") -> Sun | B13: =+B12+1 -> 45669 | C13: =IF(A13="Sat",C12+1,C12) -> 3 | D13: =TEXT(B13,"DD")&"/"&TEXT(B13,"MM")&"/"&TEXT(B13,"YYYY") -> 12/01/2025
A14: =TEXT(B14,"ddd") -> Mon | B14: =+B13+1 -> 45670 | C14: =IF(A14="Sat",C13+1,C13) -> 3 | D14: =TEXT(B14,"DD")&"/"&TEXT(B14,"MM")&"/"&TEXT(B14,"YYYY") -> 13/01/2025
A15: =TEXT(B15,"ddd") -> Tue | B15: =+B14+1 -> 45671 | C15: =IF(A15="Sat",C14+1,C14) -> 3 | D15: =TEXT(B15,"DD")&"/"&TEXT(B15,"MM")&"/"&TEXT(B15,"YYYY") -> 14/01/2025
... A366: =TEXT(B366,"ddd") -> Wed | B366: =+B365+1 -> 46022 | C366: =IF(A366="Sat",C365+1,C365) -> 53 | D366: =TEXT(B366,"DD")&"/"&TEXT(B366,"MM")&"/"&TEXT(B366,"YYYY") -> 31/12/2025
