Workbook
Name Display_Week: '[1]High Level'!$D$3
Name Project_Start: '[1]High Level'!$D$2

Sheet KPI Linked Table for Report
A1: =_xlfn.XLOOKUP('KPI Linked Table for Report'!C1,'Week No''s'!B3:B55,'Week No''s'!C3:C55) -> 45947 | B1: Current Week | C1: 42 | E1: Top KPI's by Department - Last 5 week Data | P1: Week | Q1: Week | S1: =+X8 -> 42 | W1: =+X9 -> 45947 | AC1: automatic | AE1: Week | AF1: =+S1 -> 42 | AH1: =+AI9 -> 45947
A2: Sep | B2: Current Month | C2: =_xlfn.XLOOKUP('KPI Linked Table for Report'!A2,'Week No''s'!E:E,'Week No''s'!F:F,0) -> 9 | F2: Displayed below is a mixture of the actual KPI result and the KPI Calc i.e. actual result / Target (In some cases this is inverted) depending on whether the test is adverse if above or below see column M for the definition
D3: Week Ending | F3: The KPI Calc Colours are - Green if KPI Calc is 100% or Greater , Amber if between 95% and 99.9%, Red if lower than 95% | P3: =+R3-1 -> 38 | R3: =+T3-1 -> 39 | T3: =+V3-1 -> 40 | V3: =+X3-1 -> 41 | X3: =+C1 -> 42 | AC3: <<<<Update Wk nos here
D4: Mth no | AE4: Test results by week - 1st Block some are actual results
F5: In HR and Finance there are Monthly KPIs these are noted by the M in the "Freq" column. The "WK" column De
C6: Tab | F6: Department | G6: Manager | H6: Freq | I6: Wk | J6: Category | K6: KPI | L6: UOM | M6: Shown | P6: Week KPI Calc | AE6: Week KPI Calc | AF6: Week KPI Calc | AG6: Week KPI Calc | AH6: Week KPI Calc | AI6: Week KPI Calc
A7: Lookup Drivers for | F7: Mth No | H7: For Monthly KPIs | P7: =_xlfn.XLOOKUP('KPI Linked Table for Report'!P8,'KPI Analysis'!$CU$7:$EU$7,'KPI Analysis'!$CU$8:$EU$8) -> 8 | R7: =_xlfn.XLOOKUP('KPI Linked Table for Report'!R8,'KPI Analysis'!$CU$7:$EU$7,'KPI Analysis'!$CU$8:$EU$8) -> 8 | T7: =_xlfn.XLOOKUP('KPI Linked Table for Report'!T8,'KPI Analysis'!$CU$7:$EU$7,'KPI Analysis'!$CU$8:$EU$8) -> 9 | V7: =_xlfn.XLOOKUP('KPI Linked Table for Report'!V8,'KPI Analysis'!$CU$7:$EU$7,'KPI Analysis'!$CU$8:$EU$8) -> 9 | X7: =_xlfn.XLOOKUP('KPI Linked Table for Report'!X8,'KPI Analysis'!$CU$7:$EU$7,'KPI Analysis'!$CU$8:$EU$8) -> 9 | AC7: automatic | AE7: =_xlfn.XLOOKUP('KPI Linked Table for Report'!AE8,'KPI Analysis'!$CU$7:$EU$7,'KPI Analysis'!$CU$8:$EU$8) -> 8 | AF7: =_xlfn.XLOOKUP('KPI Linked Table for Report'!AF8,'KPI Analysis'!$CU$7:$EU$7,'KPI Analysis'!$CU$8:$EU$8) -> 8 | AG7: =_xlfn.XLOOKUP('KPI Linked Table for Report'!AG8,'KPI Analysis'!$CU$7:$EU$7,'KPI Analysis'!$CU$8:$EU$8) -> 9 | AH7: =_xlfn.XLOOKUP('KPI Linked Table for Report'!AH8,'KPI Analysis'!$CU$7:$EU$7,'KPI Analysis'!$CU$8:$EU$8) -> 9 | AI7: =_xlfn.XLOOKUP('KPI Linked Table for Report'!AI8,'KPI Analysis'!$CU$7:$EU$7,'KPI Analysis'!$CU$8:$EU$8) -> 9
F8: Wk No | H8: For Weekly KPI's | M8: A | P8: =+P3 -> 38 | R8: =+R3 -> 39 | T8: =+T3 -> 40 | V8: =+V3 -> 41 | X8: =+X3 -> 42 | AC8: automatic | AE8: =+AF8-1 -> 38 | AF8: =+AG8-1 -> 39 | AG8: =+AH8-1 -> 40 | AH8: =+AI8-1 -> 41 | AI8: =+AF1 -> 42
F9: Date | H9: Week Ending (Fri) | P9: =_xlfn.XLOOKUP(P8,EHS!$M$6:$BM$6,EHS!$M$7:$BM$7) -> 45919 | R9: =_xlfn.XLOOKUP(R8,EHS!$M$6:$BM$6,EHS!$M$7:$BM$7) -> 45926 | T9: =_xlfn.XLOOKUP(T8,EHS!$M$6:$BM$6,EHS!$M$7:$BM$7) -> 45933 | V9: =_xlfn.XLOOKUP(V8,EHS!$M$6:$BM$6,EHS!$M$7:$BM$7) -> 45940 | X9: =_xlfn.XLOOKUP(X8,EHS!$M$6:$BM$6,EHS!$M$7:$BM$7) -> 45947 | AC9: automatic | AE9: =_xlfn.XLOOKUP(AE8,EHS!$M$6:$BM$6,EHS!$M$7:$BM$7) -> 45919 | AF9: =_xlfn.XLOOKUP(AF8,EHS!$M$6:$BM$6,EHS!$M$7:$BM$7) -> 45926 | AG9: =_xlfn.XLOOKUP(AG8,EHS!$M$6:$BM$6,EHS!$M$7:$BM$7) -> 45933 | AH9: =_xlfn.XLOOKUP(AH8,EHS!$M$6:$BM$6,EHS!$M$7:$BM$7) -> 45940 | AI9: =_xlfn.XLOOKUP(AI8,EHS!$M$6:$BM$6,EHS!$M$7:$BM$7) -> 45947
Z10: Days lost over - 3 incidents
A11: =F11&"-"&C11 -> EHS-KPI P1 | B11: =+'KPI Stats'!G10 -> Above Zero | C11: =+'KPI Stats'!C10 -> KPI P1 | F11: =+'KPI Stats'!B9 -> EHS | G11: =+'KPI Stats'!C9 -> Neil Laing | H11: W | I11: =+'KPI Stats'!F9 -> 42 | J11: =+'KPI Stats'!D10 -> Productivity | K11: =+'KPI Stats'!E10 -> Lost Working Days | L11: =+'KPI Stats'!F10 -> Lost Days | M11: =INDEX('KPI Analysis'!$CO$7:$EU$123,MATCH($A11,'KPI Analysis'!$CO$7:$CO$123,FALSE),MATCH(M$8,'KPI Analysis'!$CO$7:$EU$7,FALSE)) -> Act Result | P11: =IF( OR( INDEX('KPI Analysis'!$AH$7:$CM$123, MATCH($A11,'KPI Analysis'!$AH$7:$AH$123,FALSE), MATCH(P$8,'KPI Analysis'!$AH$7:$CM$7,FALSE) )="R", INDEX('KPI Analysis'!$AH$7:$CM$123, MATCH($A11,'KPI Analysis'!$AH$7:$AH$123,FALSE), MATCH(P$8,'KPI Analysis'!$AH$7:$CM$7,FALSE) )="G", INDEX('KPI Analysis'!$AH$7:$CM$123, MATCH($A11,'KPI Analysis'!$AH$7:$AH$123,FALSE), MATCH(P$8,'KPI Analysis'!$AH$7:$CM$7,FALSE) )="A"), INDEX('KPI Analysis'!$AH$7:$CM$123,MATCH($A11,'KPI Analysis'!$AH$7:$AH$123,FALSE),MATCH(P$8,'KPI Analysis'!$AH$7:$CM$7,FALSE)),"") -> G | Q11: =INDEX('KPI Analysis'!$EW$7:$HC$123,MATCH($A11,'KPI Analysis'!$EW$7:$EW$123,FALSE),MATCH(P$8,'KPI Analysis'!$EW$7:$HC$7,FALSE)) -> 0 | R11: =IF( OR( INDEX('KPI Analysis'!$AH$7:$CM$123, MATCH($A11,'KPI Analysis'!$AH$7:$AH$123,FALSE), MATCH(R$8,'KPI Analysis'!$AH$7:$CM$7,FALSE) )="R", INDEX('KPI Analysis'!$AH$7:$CM$123, MATCH($A11,'KPI Analysis'!$AH$7:$AH$123,FALSE), MATCH(R$8,'KPI Analysis'!$AH$7:$CM$7,FALSE) )="G", INDEX('KPI Analysis'!$AH$7:$CM$123, MATCH($A11,'KPI Analysis'!$AH$7:$AH$123,FALSE), MATCH(R$8,'KPI Analysis'!$AH$7:$CM$7,FALSE) )="A"), INDEX('KPI Analysis'!$AH$7:$CM$123,MATCH($A11,'KPI Analysis'!$AH$7:$AH$123,FALSE),MATCH(R$8,'KPI Analysis'!$AH$7:$CM$7,FALSE)),"") -> G | S11: =INDEX('KPI Analysis'!$EW$7:$HC$123,MATCH($A11,'KPI Analysis'!$EW$7:$EW$123,FALSE),MATCH(R$8,'KPI Analysis'!$EW$7:$HC$7,FALSE)) -> 0 | T11: =IF( OR( INDEX('KPI Analysis'!$AH$7:$CM$123, MATCH($A11,'KPI Analysis'!$AH$7:$AH$123,FALSE), MATCH(T$8,'KPI Analysis'!$AH$7:$CM$7,FALSE) )="R", INDEX('KPI Analysis'!$AH$7:$CM$123, MATCH($A11,'KPI Analysis'!$AH$7:$AH$123,FALSE), MATCH(T$8,'KPI Analysis'!$AH$7:$CM$7,FALSE) )="G", INDEX('KPI Analysis'!$AH$7:$CM$123, MATCH($A11,'KPI Analysis'!$AH$7:$AH$123,FALSE), MATCH(T$8,'KPI Analysis'!$AH$7:$CM$7,FALSE) )="A"), INDEX('KPI Analysis'!$AH$7:$CM$123,MATCH($A11,'KPI Analysis'!$AH$7:$AH$123,FALSE),MATCH(T$8,'KPI Analysis'!$AH$7:$CM$7,FALSE)),"") -> G | U11: =INDEX('KPI Analysis'!$EW$7:$HC$123,MATCH($A11,'KPI Analysis'!$EW$7:$EW$123,FALSE),MATCH(T$8,'KPI Analysis'!$EW$7:$HC$7,FALSE)) -> 0 | V11: =IF( OR( INDEX('KPI Analysis'!$AH$7:$CM$123, MATCH($A11,'KPI Analysis'!$AH$7:$AH$123,FALSE), MATCH(V$8,'KPI Analysis'!$AH$7:$CM$7,FALSE) )="R", INDEX('KPI Analysis'!$AH$7:$CM$123, MATCH($A11,'KPI Analysis'!$AH$7:$AH$123,FALSE), MATCH(V$8,'KPI Analysis'!$AH$7:$CM$7,FALSE) )="G", INDEX('KPI Analysis'!$AH$7:$CM$123, MATCH($A11,'KPI Analysis'!$AH$7:$AH$123,FALSE), MATCH(V$8,'KPI Analysis'!$AH$7:$CM$7,FALSE) )="A"), INDEX('KPI Analysis'!$AH$7:$CM$123,MATCH($A11,'KPI Analysis'!$AH$7:$AH$123,FALSE),MATCH(V$8,'KPI Analysis'!$AH$7:$CM$7,FALSE)),"") -> G | W11: =INDEX('KPI Analysis'!$EW$7:$HC$123,MATCH($A11,'KPI Analysis'!$EW$7:$EW$123,FALSE),MATCH(V$8,'KPI Analysis'!$EW$7:$HC$7,FALSE)) -> 0 | X11: =IF( OR( INDEX('KPI Analysis'!$AH$7:$CM$123, MATCH($A11,'KPI Analysis'!$AH$7:$AH$123,FALSE), MATCH(X$8,'KPI Analysis'!$AH$7:$CM$7,FALSE) )="R", INDEX('KPI Analysis'!$AH$7:$CM$123, MATCH($A11,'KPI Analysis'!$AH$7:$AH$123,FALSE), MATCH(X$8,'KPI Analysis'!$AH$7:$CM$7,FALSE) )="G", INDEX('KPI Analysis'!$AH$7:$CM$123, MATCH($A11,'KPI Analysis'!$AH$7:$AH$123,FALSE), MATCH(X$8,'KPI Analysis'!$AH$7:$CM$7,FALSE) )="A"), INDEX('KPI Analysis'!$AH$7:$CM$123,MATCH($A11,'KPI Analysis'!$AH$7:$AH$123,FALSE),MATCH(X$8,'KPI Analysis'!$AH$7:$CM$7,FALSE)),"") -> G | Y11: =IF(INDEX('KPI Analysis'!$CO$7:$EU$123,MATCH($A11,'KPI Analysis'!$CO$7:$CO$123,FALSE),MATCH(X$8,'KPI Analysis'!$CO$7:$EU$7,FALSE))="OD","OD",INDEX('KPI Analysis'!$EW$7:$HC$123,MATCH($A11,'KPI Analysis'!$EW$7:$EW$123,FALSE),MATCH(X$8,'KPI Analysis'!$EW$7:$HC$7,FALSE))) -> 0 | Z11: FYTD 27 days lost (details on last pg) | AC11: EW HC | AE11: =INDEX('KPI Analysis'!$CO$7:$EU$123,MATCH($A11,'KPI Analysis'!$CO$7:$CO$123,FALSE),MATCH(AE$8,'KPI Analysis'!$CO$7:$EU$7,FALSE)) -> 0 | AF11: =INDEX('KPI Analysis'!$CO$7:$EU$123,MATCH($A11,'KPI Analysis'!$CO$7:$CO$123,FALSE),MATCH(AF$8,'KPI Analysis'!$CO$7:$EU$7,FALSE)) -> 0 | AG11: =INDEX('KPI Analysis'!$CO$7:$EU$123,MATCH($A11,'KPI Analysis'!$CO$7:$CO$123,FALSE),MATCH(AG$8,'KPI Analysis'!$CO$7:$EU$7,FALSE)) -> 0 | AH11: =INDEX('KPI Analysis'!$CO$7:$EU$123,MATCH($A11,'KPI Analysis'!$CO$7:$CO$123,FALSE),MATCH(AH$8,'KPI Analysis'!$CO$7:$EU$7,FALSE)) -> 0 | AI11: =INDEX('KPI Analysis'!$CO$7:$EU$123,MATCH($A11,'KPI Analysis'!$CO$7:$CO$123,FALSE),MATCH(AI$8,'KPI Analysis'!$CO$7:$EU$7,FALSE)) -> 0
A12: =F11&"-"&C12 -> EHS-KPI D1 | B12: =+'KPI Stats'!G11 -> Under | C12: =+'KPI Stats'!C11 -> KPI D1 | H12: W | I12: =+'KPI Stats'!F9 -> 42 | J12: =+'KPI Stats'!D11 -> Delivery | K12: =+'KPI Stats'!E11 -> Visual Inspection Count | L12: =+'KPI Stats'!F11 -> Count | M12: % of target | P12: =IF( OR( INDEX('KPI Analysis'!$AH$7:$CM$123, MATCH($A12,'KPI Analysis'!$AH$7:$AH$123,FALSE), MATCH(P$8,'KPI Analysis'!$AH$7:$CM$7,FALSE) )="R", INDEX('KPI Analysis'!$AH$7:$CM$123, MATCH($A12,'KPI Analysis'!$AH$7:$AH$123,FALSE), MATCH(P$8,'KPI Analysis'!$AH$7:$CM$7,FALSE) )="G", INDEX('KPI Analysis'!$AH$7:$CM$123, MATCH($A12,'KPI Analysis'!$AH$7:$AH$123,FALSE), MATCH(P$8,'KPI Analysis'!$AH$7:$CM$7,FALSE) )="A"), INDEX('KPI Analysis'!$AH$7:$CM$123,MATCH($A12,'KPI Analysis'!$AH$7:$AH$123,FALSE),MATCH(P$8,'KPI Analysis'!$AH$7:$CM$7,FALSE)),"") -> G | Q12: =INDEX('KPI Analysis'!$CO$7:$EU$123,MATCH($A12,'KPI Analysis'!$CO$7:$CO$123,FALSE),MATCH(P$8,'KPI Analysis'!$CO$7:$EU$7,FALSE)) -> 1.4428571 | R12: =IF( OR( INDEX('KPI Analysis'!$AH$7:$CM$123, MATCH($A12,'KPI Analysis'!$AH$7:$AH$123,FALSE), MATCH(R$8,'KPI Analysis'!$AH$7:$CM$7,FALSE) )="R", INDEX('KPI Analysis'!$AH$7:$CM$123, MATCH($A12,'KPI Analysis'!$AH$7:$AH$123,FALSE), MATCH(R$8,'KPI Analysis'!$AH$7:$CM$7,FALSE) )="G", INDEX('KPI Analysis'!$AH$7:$CM$123, MATCH($A12,'KPI Analysis'!$AH$7:$AH$123,FALSE), MATCH(R$8,'KPI Analysis'!$AH$7:$CM$7,FALSE) )="A"), INDEX('KPI Analysis'!$AH$7:$CM$123,MATCH($A12,'KPI Analysis'!$AH$7:$AH$123,FALSE),MATCH(R$8,'KPI Analysis'!$AH$7:$CM$7,FALSE)),"") -> G | S12: =INDEX('KPI Analysis'!$CO$7:$EU$123,MATCH($A12,'KPI Analysis'!$CO$7:$CO$123,FALSE),MATCH(R$8,'KPI Analysis'!$CO$7:$EU$7,FALSE)) -> 1.4142857 | T12: =IF( OR( INDEX('KPI Analysis'!$AH$7:$CM$123, MATCH($A12,'KPI Analysis'!$AH$7:$AH$123,FALSE), MATCH(T$8,'KPI Analysis'!$AH$7:$CM$7,FALSE) )="R", INDEX('KPI Analysis'!$AH$7:$CM$123, MATCH($A12,'KPI Analysis'!$AH$7:$AH$123,FALSE), MATCH(T$8,'KPI Analysis'!$AH$7:$CM$7,FALSE) )="G", INDEX('KPI Analysis'!$AH$7:$CM$123, MATCH($A12,'KPI Analysis'!$AH$7:$AH$123,FALSE), MATCH(T$8,'KPI Analysis'!$AH$7:$CM$7,FALSE) )="A"), INDEX('KPI Analysis'!$AH$7:$CM$123,MATCH($A12,'KPI Analysis'!$AH$7:$AH$123,FALSE),MATCH(T$8,'KPI Analysis'!$AH$7:$CM$7,FALSE)),"") -> G | U12: =INDEX('KPI Analysis'!$CO$7:$EU$123,MATCH($A12,'KPI Analysis'!$CO$7:$CO$123,FALSE),MATCH(T$8,'KPI Analysis'!$CO$7:$EU$7,FALSE)) -> 1.12 | V12: =IF( OR( INDEX('KPI Analysis'!$AH$7:$CM$123, MATCH($A12,'KPI Analysis'!$AH$7:$AH$123,FALSE), MATCH(V$8,'KPI Analysis'!$AH$7:$CM$7,FALSE) )="R", INDEX('KPI Analysis'!$AH$7:$CM$123, MATCH($A12,'KPI Analysis'!$AH$7:$AH$123,FALSE), MATCH(V$8,'KPI Analysis'!$AH$7:$CM$7,FALSE) )="G", INDEX('KPI Analysis'!$AH$7:$CM$123, MATCH($A12,'KPI Analysis'!$AH$7:$AH$123,FALSE), MATCH(V$8,'KPI Analysis'!$AH$7:$CM$7,FALSE) )="A"), INDEX('KPI Analysis'!$AH$7:$CM$123,MATCH($A12,'KPI Analysis'!$AH$7:$AH$123,FALSE),MATCH(V$8,'KPI Analysis'!$AH$7:$CM$7,FALSE)),"") -> G | W12: =INDEX('KPI Analysis'!$CO$7:$EU$123,MATCH($A12,'KPI Analysis'!$CO$7:$CO$123,FALSE),MATCH(V$8,'KPI Analysis'!$CO$7:$EU$7,FALSE)) -> 1.04 | X12: =IF( OR( INDEX('KPI Analysis'!$AH$7:$CM$123, MATCH($A12,'KPI Analysis'!$AH$7:$AH$123,FALSE), MATCH(X$8,'KPI Analysis'!$AH$7:$CM$7,FALSE) )="R", INDEX('KPI Analysis'!$AH$7:$CM$123, MATCH($A12,'KPI Analysis'!$AH$7:$AH$123,FALSE), MATCH(X$8,'KPI Analysis'!$AH$7:$CM$7,FALSE) )="G", INDEX('KPI Analysis'!$AH$7:$CM$123, MATCH($A12,'KPI Analysis'!$AH$7:$AH$123,FALSE), MATCH(X$8,'KPI Analysis'!$AH$7:$CM$7,FALSE) )="A"), INDEX('KPI Analysis'!$AH$7:$CM$123,MATCH($A12,'KPI Analysis'!$AH$7:$AH$123,FALSE),MATCH(X$8,'KPI Analysis'!$AH$7:$CM$7,FALSE)),"") -> G | Y12: =INDEX('KPI Analysis'!$CO$7:$EU$123,MATCH($A12,'KPI Analysis'!$CO$7:$CO$123,FALSE),MATCH(X$8,'KPI Analysis'!$CO$7:$EU$7,FALSE)) -> 1.03 | AC12: Co EU | AE12: =INDEX('KPI Analysis'!$CO$7:$EU$123,MATCH($A12,'KPI Analysis'!$CO$7:$CO$123,FALSE),MATCH(AE$8,'KPI Analysis'!$CO$7:$EU$7,FALSE)) -> 1.4428571 | AF12: =INDEX('KPI Analysis'!$CO$7:$EU$123,MATCH($A12,'KPI Analysis'!$CO$7:$CO$123,FALSE),MATCH(AF$8,'KPI Analysis'!$CO$7:$EU$7,FALSE)) -> 1.4142857 | AG12: =INDEX('KPI Analysis'!$CO$7:$EU$123,MATCH($A12,'KPI Analysis'!$CO$7:$CO$123,FALSE),MATCH(AG$8,'KPI Analysis'!$CO$7:$EU$7,FALSE)) -> 1.12 | AH12: =INDEX('KPI Analysis'!$CO$7:$EU$123,MATCH($A12,'KPI Analysis'!$CO$7:$CO$123,FALSE),MATCH(AH$8,'KPI Analysis'!$CO$7:$EU$7,FALSE)) -> 1.04 | AI12: =INDEX('KPI Analysis'!$CO$7:$EU$123,MATCH($A12,'KPI Analysis'!$CO$7:$CO$123,FALSE),MATCH(AI$8,'KPI Analysis'!$CO$7:$EU$7,FALSE)) -> 1.03
A13: =F11&"-"&C13 -> EHS-KPI Q1 | B13: =+'KPI Stats'!G12 -> Under | C13: =+'KPI Stats'!C12 -> KPI Q1 | H13: W | I13: =+'KPI Stats'!F9 -> 42 | J13: =+'KPI Stats'!D12 -> Quality | K13: =+'KPI Stats'!E12 -> Visual Inspection Pass Rate | L13: =+'KPI Stats'!F12 -> Percentage | M13: Act Result | P13: =IF( OR( INDEX('KPI Analysis'!$AH$7:$CM$123, MATCH($A13,'KPI Analysis'!$AH$7:$AH$123,FALSE), MATCH(P$8,'KPI Analysis'!$AH$7:$CM$7,FALSE) )="R", INDEX('KPI Analysis'!$AH$7:$CM$123, MATCH($A13,'KPI Analysis'!$AH$7:$AH$123,FALSE), MATCH(P$8,'KPI Analysis'!$AH$7:$CM$7,FALSE) )="G", INDEX('KPI Analysis'!$AH$7:$CM$123, MATCH($A13,'KPI Analysis'!$AH$7:$AH$123,FALSE), MATCH(P$8,'KPI Analysis'!$AH$7:$CM$7,FALSE) )="A"), INDEX('KPI Analysis'!$AH$7:$CM$123,MATCH($A13,'KPI Analysis'!$AH$7:$AH$123,FALSE),MATCH(P$8,'KPI Analysis'!$AH$7:$CM$7,FALSE)),"") -> A | Q13: =INDEX('KPI Analysis'!$EW$7:$HC$123,MATCH($A13,'KPI Analysis'!$EW$7:$EW$123,FALSE),MATCH(P$8,'KPI Analysis'!$EW$7:$HC$7,FALSE))/100 -> 0.86 | R13: =IF( OR( INDEX('KPI Analysis'!$AH$7:$CM$123, MATCH($A13,'KPI Analysis'!$AH$7:$AH$123,FALSE), MATCH(R$8,'KPI Analysis'!$AH$7:$CM$7,FALSE) )="R", INDEX('KPI Analysis'!$AH$7:$CM$123, MATCH($A13,'KPI Analysis'!$AH$7:$AH$123,FALSE), MATCH(R$8,'KPI Analysis'!$AH$7:$CM$7,FALSE) )="G", INDEX('KPI Analysis'!$AH$7:$CM$123, MATCH($A13,'KPI Analysis'!$AH$7:$AH$123,FALSE), MATCH(R$8,'KPI Analysis'!$AH$7:$CM$7,FALSE) )="A"), INDEX('KPI Analysis'!$AH$7:$CM$123,MATCH($A13,'KPI Analysis'!$AH$7:$AH$123,FALSE),MATCH(R$8,'KPI Analysis'!$AH$7:$CM$7,FALSE)),"") -> A | S13: =INDEX('KPI Analysis'!$EW$7:$HC$123,MATCH($A13,'KPI Analysis'!$EW$7:$EW$123,FALSE),MATCH(R$8,'KPI Analysis'!$EW$7:$HC$7,FALSE))/100 -> 0.86 | T13: =IF( OR( INDEX('KPI Analysis'!$AH$7:$CM$123, MATCH($A13,'KPI Analysis'!$AH$7:$AH$123,FALSE), MATCH(T$8,'KPI Analysis'!$AH$7:$CM$7,FALSE) )="R", INDEX('KPI Analysis'!$AH$7:$CM$123, MATCH($A13,'KPI Analysis'!$AH$7:$AH$123,FALSE), MATCH(T$8,'KPI Analysis'!$AH$7:$CM$7,FALSE) )="G", INDEX('KPI Analysis'!$AH$7:$CM$123, MATCH($A13,'KPI Analysis'!$AH$7:$AH$123,FALSE), MATCH(T$8,'KPI Analysis'!$AH$7:$CM$7,FALSE) )="A"), INDEX('KPI Analysis'!$AH$7:$CM$123,MATCH($A13,'KPI Analysis'!$AH$7:$AH$123,FALSE),MATCH(T$8,'KPI Analysis'!$AH$7:$CM$7,FALSE)),"") -> G | U13: =INDEX('KPI Analysis'!$EW$7:$HC$123,MATCH($A13,'KPI Analysis'!$EW$7:$EW$123,FALSE),MATCH(T$8,'KPI Analysis'!$EW$7:$HC$7,FALSE))/100 -> 0.91 | V13: =IF( OR( INDEX('KPI Analysis'!$AH$7:$CM$123, MATCH($A13,'KPI Analysis'!$AH$7:$AH$123,FALSE), MATCH(V$8,'KPI Analysis'!$AH$7:$CM$7,FALSE) )="R", INDEX('KPI Analysis'!$AH$7:$CM$123, MATCH($A13,'KPI Analysis'!$AH$7:$AH$123,FALSE), MATCH(V$8,'KPI Analysis'!$AH$7:$CM$7,FALSE) )="G", INDEX('KPI Analysis'!$AH$7:$CM$123, MATCH($A13,'KPI Analysis'!$AH$7:$AH$123,FALSE), MATCH(V$8,'KPI Analysis'!$AH$7:$CM$7,FALSE) )="A"), INDEX('KPI Analysis'!$AH$7:$CM$123,MATCH($A13,'KPI Analysis'!$AH$7:$AH$123,FALSE),MATCH(V$8,'KPI Analysis'!$AH$7:$CM$7,FALSE)),"") -> G | W13: =INDEX('KPI Analysis'!$EW$7:$HC$123,MATCH($A13,'KPI Analysis'!$EW$7:$EW$123,FALSE),MATCH(V$8,'KPI Analysis'!$EW$7:$HC$7,FALSE))/100 -> 0.9 | X13: =IF( OR( INDEX('KPI Analysis'!$AH$7:$CM$123, MATCH($A13,'KPI Analysis'!$AH$7:$AH$123,FALSE), MATCH(X$8,'KPI Analysis'!$AH$7:$CM$7,FALSE) )="R", INDEX('KPI Analysis'!$AH$7:$CM$123, MATCH($A13,'KPI Analysis'!$AH$7:$AH$123,FALSE), MATCH(X$8,'KPI Analysis'!$AH$7:$CM$7,FALSE) )="G", INDEX('KPI Analysis'!$AH$7:$CM$123, MATCH($A13,'KPI Analysis'!$AH$7:$AH$123,FALSE), MATCH(X$8,'KPI Analysis'!$AH$7:$CM$7,FALSE) )="A"), INDEX('KPI Analysis'!$AH$7:$CM$123,MATCH($A13,'KPI Analysis'!$AH$7:$AH$123,FALSE),MATCH(X$8,'KPI Analysis'!$AH$7:$CM$7,FALSE)),"") -> G | Y13: =IF(INDEX('KPI Analysis'!$CO$7:$EU$123,MATCH($A13,'KPI Analysis'!$CO$7:$CO$123,FALSE),MATCH(X$8,'KPI Analysis'!$CO$7:$EU$7,FALSE))="OD","OD",INDEX('KPI Analysis'!$EW$7:$HC$123,MATCH($A13,'KPI Analysis'!$EW$7:$EW$123,FALSE),MATCH(X$8,'KPI Analysis'!$EW$7:$HC$7,FALSE))/100) -> 0.92 | Z13: (Target 90%) 6S project should help | AC13: EW HC | AE13: =INDEX('KPI Analysis'!$CO$7:$EU$123,MATCH($A13,'KPI Analysis'!$CO$7:$CO$123,FALSE),MATCH(AE$8,'KPI Analysis'!$CO$7:$EU$7,FALSE)) -> 0.95555556 | AF13: =INDEX('KPI Analysis'!$CO$7:$EU$123,MATCH($A13,'KPI Analysis'!$CO$7:$CO$123,FALSE),MATCH(AF$8,'KPI Analysis'!$CO$7:$EU$7,FALSE)) -> 0.95555556 | AG13: =INDEX('KPI Analysis'!$CO$7:$EU$123,MATCH($A13,'KPI Analysis'!$CO$7:$CO$123,FALSE),MATCH(AG$8,'KPI Analysis'!$CO$7:$EU$7,FALSE)) -> 1.0111111 | AH13: =INDEX('KPI Analysis'!$CO$7:$EU$123,MATCH($A13,'KPI Analysis'!$CO$7:$CO$123,FALSE),MATCH(AH$8,'KPI Analysis'!$CO$7:$EU$7,FALSE)) -> 1 | AI13: =INDEX('KPI Analysis'!$CO$7:$EU$123,MATCH($A13,'KPI Analysis'!$CO$7:$CO$123,FALSE),MATCH(AI$8,'KPI Analysis'!$CO$7:$EU$7,FALSE)) -> 1.0222222
A14: =F11&"-"&C14 -> EHS-KPI C1 | B14: =+'KPI Stats'!G13 -> Over | C14: =+'KPI Stats'!C13 -> KPI C1 | H14: W | I14: =+'KPI Stats'!F9 -> 42 | J14: =+'KPI Stats'!D13 -> Cost | K14: =+'KPI Stats'!E13 -> Ratio of Gas / Elec emissions to prod Quantity | L14: =+'KPI Stats'!F13 -> Ratio | M14: % of target | P14: =IF( OR( INDEX('KPI Analysis'!$AH$7:$CM$123, MATCH($A14,'KPI Analysis'!$AH$7:$AH$123,FALSE), MATCH(P$8,'KPI Analysis'!$AH$7:$CM$7,FALSE) )="R", INDEX('KPI Analysis'!$AH$7:$CM$123, MATCH($A14,'KPI Analysis'!$AH$7:$AH$123,FALSE), MATCH(P$8,'KPI Analysis'!$AH$7:$CM$7,FALSE) )="G", INDEX('KPI Analysis'!$AH$7:$CM$123, MATCH($A14,'KPI Analysis'!$AH$7:$AH$123,FALSE), MATCH(P$8,'KPI Analysis'!$AH$7:$CM$7,FALSE) )="A"), INDEX('KPI Analysis'!$AH$7:$CM$123,MATCH($A14,'KPI Analysis'!$AH$7:$AH$123,FALSE),MATCH(P$8,'KPI Analysis'!$AH$7:$CM$7,FALSE)),"") -> G | Q14: =INDEX('KPI Analysis'!$CO$7:$EU$123,MATCH($A14,'KPI Analysis'!$CO$7:$CO$123,FALSE),MATCH(P$8,'KPI Analysis'!$CO$7:$EU$7,FALSE)) -> 1.3513514 | R14: =IF( OR( INDEX('KPI Analysis'!$AH$7:$CM$123, MATCH($A14,'KPI Analysis'!$AH$7:$AH$123,FALSE), MATCH(R$8,'KPI Analysis'!$AH$7:$CM$7,FALSE) )="R", INDEX('KPI Analysis'!$AH$7:$CM$123, MATCH($A14,'KPI Analysis'!$AH$7:$AH$123,FALSE), MATCH(R$8,'KPI Analysis'!$AH$7:$CM$7,FALSE) )="G", INDEX('KPI Analysis'!$AH$7:$CM$123, MATCH($A14,'KPI Analysis'!$AH$7:$AH$123,FALSE), MATCH(R$8,'KPI Analysis'!$AH$7:$CM$7,FALSE) )="A"), INDEX('KPI Analysis'!$AH$7:$CM$123,MATCH($A14,'KPI Analysis'!$AH$7:$AH$123,FALSE),MATCH(R$8,'KPI Analysis'!$AH$7:$CM$7,FALSE)),"") -> G | S14: =INDEX('KPI Analysis'!$CO$7:$EU$123,MATCH($A14,'KPI Analysis'!$CO$7:$CO$123,FALSE),MATCH(R$8,'KPI Analysis'!$CO$7:$EU$7,FALSE)) -> 1.0204082 | T14: =IF( OR( INDEX('KPI Analysis'!$AH$7:$CM$123, MATCH($A14,'KPI Analysis'!$AH$7:$AH$123,FALSE), MATCH(T$8,'KPI Analysis'!$AH$7:$CM$7,FALSE) )="R", INDEX('KPI Analysis'!$AH$7:$CM$123, MATCH($A14,'KPI Analysis'!$AH$7:$AH$123,FALSE), MATCH(T$8,'KPI Analysis'!$AH$7:$CM$7,FALSE) )="G", INDEX('KPI Analysis'!$AH$7:$CM$123, MATCH($A14,'KPI Analysis'!$AH$7:$AH$123,FALSE), MATCH(T$8,'KPI Analysis'!$AH$7:$CM$7,FALSE) )="A"), INDEX('KPI Analysis'!$AH$7:$CM$123,MATCH($A14,'KPI Analysis'!$AH$7:$AH$123,FALSE),MATCH(T$8,'KPI Analysis'!$AH$7:$CM$7,FALSE)),"") -> G | U14: =INDEX('KPI Analysis'!$CO$7:$EU$123,MATCH($A14,'KPI Analysis'!$CO$7:$CO$123,FALSE),MATCH(T$8,'KPI Analysis'!$CO$7:$EU$7,FALSE)) -> 1.2048193 | V14: =IF( OR( INDEX('KPI Analysis'!$AH$7:$CM$123, MATCH($A14,'KPI Analysis'!$AH$7:$AH$123,FALSE), MATCH(V$8,'KPI Analysis'!$AH$7:$CM$7,FALSE) )="R", INDEX('KPI Analysis'!$AH$7:$CM$123, MATCH($A14,'KPI Analysis'!$AH$7:$AH$123,FALSE), MATCH(V$8,'KPI Analysis'!$AH$7:$CM$7,FALSE) )="G", INDEX('KPI Analysis'!$AH$7:$CM$123, MATCH($A14,'KPI Analysis'!$AH$7:$AH$123,FALSE), MATCH(V$8,'KPI Analysis'!$AH$7:$CM$7,FALSE) )="A"), INDEX('KPI Analysis'!$AH$7:$CM$123,MATCH($A14,'KPI Analysis'!$AH$7:$AH$123,FALSE),MATCH(V$8,'KPI Analysis'!$AH$7:$CM$7,FALSE)),"") -> G | W14: =INDEX('KPI Analysis'!$CO$7:$EU$123,MATCH($A14,'KPI Analysis'!$CO$7:$CO$123,FALSE),MATCH(V$8,'KPI Analysis'!$CO$7:$EU$7,FALSE)) -> 1.0526316 | X14: =IF( OR( INDEX('KPI Analysis'!$AH$7:$CM$123, MATCH($A14,'KPI Analysis'!$AH$7:$AH$123,FALSE), MATCH(X$8,'KPI Analysis'!$AH$7:$CM$7,FALSE) )="R", INDEX('KPI Analysis'!$AH$7:$CM$123, MATCH($A14,'KPI Analysis'!$AH$7:$AH$123,FALSE), MATCH(X$8,'KPI Analysis'!$AH$7:$CM$7,FALSE) )="G", INDEX('KPI Analysis'!$AH$7:$CM$123, MATCH($A14,'KPI Analysis'!$AH$7:$AH$123,FALSE), MATCH(X$8,'KPI Analysis'!$AH$7:$CM$7,FALSE) )="A"), INDEX('KPI Analysis'!$AH$7:$CM$123,MATCH($A14,'KPI Analysis'!$AH$7:$AH$123,FALSE),MATCH(X$8,'KPI Analysis'!$AH$7:$CM$7,FALSE)),"") | Y14: =INDEX('KPI Analysis'!$CO$7:$EU$123,MATCH($A14,'KPI Analysis'!$CO$7:$CO$123,FALSE),MATCH(X$8,'KPI Analysis'!$CO$7:$EU$7,FALSE)) -> OD | Z14: Reported 1 Wk in arrears (Target 1) | AC14: Co EU | AE14: =INDEX('KPI Analysis'!$CO$7:$EU$123,MATCH($A14,'KPI Analysis'!$CO$7:$CO$123,FALSE),MATCH(AE$8,'KPI Analysis'!$CO$7:$EU$7,FALSE)) -> 1.3513514 | AF14: =INDEX('KPI Analysis'!$CO$7:$EU$123,MATCH($A14,'KPI Analysis'!$CO$7:$CO$123,FALSE),MATCH(AF$8,'KPI Analysis'!$CO$7:$EU$7,FALSE)) -> 1.0204082 | AG14: =INDEX('KPI Analysis'!$CO$7:$EU$123,MATCH($A14,'KPI Analysis'!$CO$7:$CO$123,FALSE),MATCH(AG$8,'KPI Analysis'!$CO$7:$EU$7,FALSE)) -> 1.2048193 | AH14: =INDEX('KPI Analysis'!$CO$7:$EU$123,MATCH($A14,'KPI Analysis'!$CO$7:$CO$123,FALSE),MATCH(AH$8,'KPI Analysis'!$CO$7:$EU$7,FALSE)) -> 1.0526316 | AI14: =INDEX('KPI Analysis'!$CO$7:$EU$123,MATCH($A14,'KPI Analysis'!$CO$7:$CO$123,FALSE),MATCH(AI$8,'KPI Analysis'!$CO$7:$EU$7,FALSE)) -> OD
A15: =F11&"-"&C15 -> EHS-KPI C2 | B15: =+'KPI Stats'!G14 -> Over | C15: =+'KPI Stats'!C14 -> KPI C2 | H15: W | I15: =+'KPI Stats'!F9 -> 42 | J15: =+'KPI Stats'!D14 -> Cost | K15: =+'KPI Stats'!E14 -> Ratio of Gas / Elec emissions to prod Volume M2 | L15: =+'KPI Stats'!F14 -> Ratio | M15: % of target | P15: =IF( OR( INDEX('KPI Analysis'!$AH$7:$CM$123, MATCH($A15,'KPI Analysis'!$AH$7:$AH$123,FALSE), MATCH(P$8,'KPI Analysis'!$AH$7:$CM$7,FALSE) )="R", INDEX('KPI Analysis'!$AH$7:$CM$123, MATCH($A15,'KPI Analysis'!$AH$7:$AH$123,FALSE), MATCH(P$8,'KPI Analysis'!$AH$7:$CM$7,FALSE) )="G", INDEX('KPI Analysis'!$AH$7:$CM$123, MATCH($A15,'KPI Analysis'!$AH$7:$AH$123,FALSE), MATCH(P$8,'KPI Analysis'!$AH$7:$CM$7,FALSE) )="A"), INDEX('KPI Analysis'!$AH$7:$CM$123,MATCH($A15,'KPI Analysis'!$AH$7:$AH$123,FALSE),MATCH(P$8,'KPI Analysis'!$AH$7:$CM$7,FALSE)),"") -> G | Q15: =INDEX('KPI Analysis'!$CO$7:$EU$123,MATCH($A15,'KPI Analysis'!$CO$7:$CO$123,FALSE),MATCH(P$8,'KPI Analysis'!$CO$7:$EU$7,FALSE)) -> 1.122449 | R15: =IF( OR( INDEX('KPI Analysis'!$AH$7:$CM$123, MATCH($A15,'KPI Analysis'!$AH$7:$AH$123,FALSE), MATCH(R$8,'KPI Analysis'!$AH$7:$CM$7,FALSE) )="R", INDEX('KPI Analysis'!$AH$7:$CM$123, MATCH($A15,'KPI Analysis'!$AH$7:$AH$123,FALSE), MATCH(R$8,'KPI Analysis'!$AH$7:$CM$7,FALSE) )="G", INDEX('KPI Analysis'!$AH$7:$CM$123, MATCH($A15,'KPI Analysis'!$AH$7:$AH$123,FALSE), MATCH(R$8,'KPI Analysis'!$AH$7:$CM$7,FALSE) )="A"), INDEX('KPI Analysis'!$AH$7:$CM$123,MATCH($A15,'KPI Analysis'!$AH$7:$AH$123,FALSE),MATCH(R$8,'KPI Analysis'!$AH$7:$CM$7,FALSE)),"") -> G | S15: =INDEX('KPI Analysis'!$CO$7:$EU$123,MATCH($A15,'KPI Analysis'!$CO$7:$CO$123,FALSE),MATCH(R$8,'KPI Analysis'!$CO$7:$EU$7,FALSE)) -> 1.0338346 | T15: =IF( OR( INDEX('KPI Analysis'!$AH$7:$CM$123, MATCH($A15,'KPI Analysis'!$AH$7:$AH$123,FALSE), MATCH(T$8,'KPI Analysis'!$AH$7:$CM$7,FALSE) )="R", INDEX('KPI Analysis'!$AH$7:$CM$123, MATCH($A15,'KPI Analysis'!$AH$7:$AH$123,FALSE), MATCH(T$8,'KPI Analysis'!$AH$7:$CM$7,FALSE) )="G", INDEX('KPI Analysis'!$AH$7:$CM$123, MATCH($A15,'KPI Analysis'!$AH$7:$AH$123,FALSE), MATCH(T$8,'KPI Analysis'!$AH$7:$CM$7,FALSE) )="A"), INDEX('KPI Analysis'!$AH$7:$CM$123,MATCH($A15,'KPI Analysis'!$AH$7:$AH$123,FALSE),MATCH(T$8,'KPI Analysis'!$AH$7:$CM$7,FALSE)),"") -> G | U15: =INDEX('KPI Analysis'!$CO$7:$EU$123,MATCH($A15,'KPI Analysis'!$CO$7:$CO$123,FALSE),MATCH(T$8,'KPI Analysis'!$CO$7:$EU$7,FALSE)) -> 1.0742188 | V15: =IF( OR( INDEX('KPI Analysis'!$AH$7:$CM$123, MATCH($A15,'KPI Analysis'!$AH$7:$AH$123,FALSE), MATCH(V$8,'KPI Analysis'!$AH$7:$CM$7,FALSE) )="R", INDEX('KPI Analysis'!$AH$7:$CM$123, MATCH($A15,'KPI Analysis'!$AH$7:$AH$123,FALSE), MATCH(V$8,'KPI Analysis'!$AH$7:$CM$7,FALSE) )="G", INDEX('KPI Analysis'!$AH$7:$CM$123, MATCH($A15,'KPI Analysis'!$AH$7:$AH$123,FALSE), MATCH(V$8,'KPI Analysis'!$AH$7:$CM$7,FALSE) )="A"), INDEX('KPI Analysis'!$AH$7:$CM$123,MATCH($A15,'KPI Analysis'!$AH$7:$AH$123,FALSE),MATCH(V$8,'KPI Analysis'!$AH$7:$CM$7,FALSE)),"") -> G | W15: =INDEX('KPI Analysis'!$CO$7:$EU$123,MATCH($A15,'KPI Analysis'!$CO$7:$CO$123,FALSE),MATCH(V$8,'KPI Analysis'!$CO$7:$EU$7,FALSE)) -> 1.0456274 | X15: =IF( OR( INDEX('KPI Analysis'!$AH$7:$CM$123, MATCH($A15,'KPI Analysis'!$AH$7:$AH$123,FALSE), MATCH(X$8,'KPI Analysis'!$AH$7:$CM$7,FALSE) )="R", INDEX('KPI Analysis'!$AH$7:$CM$123, MATCH($A15,'KPI Analysis'!$AH$7:$AH$123,FALSE), MATCH(X$8,'KPI Analysis'!$AH$7:$CM$7,FALSE) )="G", INDEX('KPI Analysis'!$AH$7:$CM$123, MATCH($A15,'KPI Analysis'!$AH$7:$AH$123,FALSE), MATCH(X$8,'KPI Analysis'!$AH$7:$CM$7,FALSE) )="A"), INDEX('KPI Analysis'!$AH$7:$CM$123,MATCH($A15,'KPI Analysis'!$AH$7:$AH$123,FALSE),MATCH(X$8,'KPI Analysis'!$AH$7:$CM$7,FALSE)),"") | Y15: =INDEX('KPI Analysis'!$CO$7:$EU$123,MATCH($A15,'KPI Analysis'!$CO$7:$CO$123,FALSE),MATCH(X$8,'KPI Analysis'!$CO$7:$EU$7,FALSE)) -> OD | Z15: Reported 1 Wk in arrears (Target 2.75) | AC15: Co EU | AE15: =INDEX('KPI Analysis'!$CO$7:$EU$123,MATCH($A15,'KPI Analysis'!$CO$7:$CO$123,FALSE),MATCH(AE$8,'KPI Analysis'!$CO$7:$EU$7,FALSE)) -> 1.122449 | AF15: =INDEX('KPI Analysis'!$CO$7:$EU$123,MATCH($A15,'KPI Analysis'!$CO$7:$CO$123,FALSE),MATCH(AF$8,'KPI Analysis'!$CO$7:$EU$7,FALSE)) -> 1.0338346 | AG15: =INDEX('KPI Analysis'!$CO$7:$EU$123,MATCH($A15,'KPI Analysis'!$CO$7:$CO$123,FALSE),MATCH(AG$8,'KPI Analysis'!$CO$7:$EU$7,FALSE)) -> 1.0742188 | AH15: =INDEX('KPI Analysis'!$CO$7:$EU$123,MATCH($A15,'KPI Analysis'!$CO$7:$CO$123,FALSE),MATCH(AH$8,'KPI Analysis'!$CO$7:$EU$7,FALSE)) -> 1.0456274 | AI15: =INDEX('KPI Analysis'!$CO$7:$EU$123,MATCH($A15,'KPI Analysis'!$CO$7:$CO$123,FALSE),MATCH(AI$8,'KPI Analysis'!$CO$7:$EU$7,FALSE)) -> OD
A18: =F18&"-"&C18 -> Estimating-KPI P1 | B18: =+'KPI Stats'!G17 -> Under | C18: =+'KPI Stats'!C17 -> KPI P1 | F18: =+'KPI Stats'!$B$16 -> Estimating | G18: Julian Sparrow | H18: W | I18: =+'KPI Stats'!$F$16 -> 42 | J18: =+'KPI Stats'!D17 -> Productivity | K18: =+'KPI Stats'!E17 -> Quotes Issued | L18: =+'KPI Stats'!F17 -> Count | M18: =INDEX('KPI Analysis'!$CO$7:$EU$123,MATCH($A18,'KPI Analysis'!$CO$7:$CO$123,FALSE),MATCH(M$8,'KPI Analysis'!$CO$7:$EU$7,FALSE)) -> % of target | P18: =IF( OR( INDEX('KPI Analysis'!$AH$7:$CM$123, MATCH($A18,'KPI Analysis'!$AH$7:$AH$123,FALSE), MATCH(P$8,'KPI Analysis'!$AH$7:$CM$7,FALSE) )="R", INDEX('KPI Analysis'!$AH$7:$CM$123, MATCH($A18,'KPI Analysis'!$AH$7:$AH$123,FALSE), MATCH(P$8,'KPI Analysis'!$AH$7:$CM$7,FALSE) )="G", INDEX('KPI Analysis'!$AH$7:$CM$123, MATCH($A18,'KPI Analysis'!$AH$7:$AH$123,FALSE), MATCH(P$8,'KPI Analysis'!$AH$7:$CM$7,FALSE) )="A"), INDEX('KPI Analysis'!$AH$7:$CM$123,MATCH($A18,'KPI Analysis'!$AH$7:$AH$123,FALSE),MATCH(P$8,'KPI Analysis'!$AH$7:$CM$7,FALSE)),"") -> R | Q18: =INDEX('KPI Analysis'!$CO$7:$EU$123,MATCH($A18,'KPI Analysis'!$CO$7:$CO$123,FALSE),MATCH(P$8,'KPI Analysis'!$CO$7:$EU$7,FALSE)) -> 0.91269841 | R18: =IF( OR( INDEX('KPI Analysis'!$AH$7:$CM$123, MATCH($A18,'KPI Analysis'!$AH$7:$AH$123,FALSE), MATCH(R$8,'KPI Analysis'!$AH$7:$CM$7,FALSE) )="R", INDEX('KPI Analysis'!$AH$7:$CM$123, MATCH($A18,'KPI Analysis'!$AH$7:$AH$123,FALSE), MATCH(R$8,'KPI Analysis'!$AH$7:$CM$7,FALSE) )="G", INDEX('KPI Analysis'!$AH$7:$CM$123, MATCH($A18,'KPI Analysis'!$AH$7:$AH$123,FALSE), MATCH(R$8,'KPI Analysis'!$AH$7:$CM$7,FALSE) )="A"), INDEX('KPI Analysis'!$AH$7:$CM$123,MATCH($A18,'KPI Analysis'!$AH$7:$AH$123,FALSE),MATCH(R$8,'KPI Analysis'!$AH$7:$CM$7,FALSE)),"") -> R | S18: =INDEX('KPI Analysis'!$CO$7:$EU$123,MATCH($A18,'KPI Analysis'!$CO$7:$CO$123,FALSE),MATCH(R$8,'KPI Analysis'!$CO$7:$EU$7,FALSE)) -> 0.86507937 | T18: =IF( OR( INDEX('KPI Analysis'!$AH$7:$CM$123, MATCH($A18,'KPI Analysis'!$AH$7:$AH$123,FALSE), MATCH(T$8,'KPI Analysis'!$AH$7:$CM$7,FALSE) )="R", INDEX('KPI Analysis'!$AH$7:$CM$123, MATCH($A18,'KPI Analysis'!$AH$7:$AH$123,FALSE), MATCH(T$8,'KPI Analysis'!$AH$7:$CM$7,FALSE) )="G", INDEX('KPI Analysis'!$AH$7:$CM$123, MATCH($A18,'KPI Analysis'!$AH$7:$AH$123,FALSE), MATCH(T$8,'KPI Analysis'!$AH$7:$CM$7,FALSE) )="A"), INDEX('KPI Analysis'!$AH$7:$CM$123,MATCH($A18,'KPI Analysis'!$AH$7:$AH$123,FALSE),MATCH(T$8,'KPI Analysis'!$AH$7:$CM$7,FALSE)),"") -> R | U18: =INDEX('KPI Analysis'!$CO$7:$EU$123,MATCH($A18,'KPI Analysis'!$CO$7:$CO$123,FALSE),MATCH(T$8,'KPI Analysis'!$CO$7:$EU$7,FALSE)) -> 0.73809524 | V18: =IF( OR( INDEX('KPI Analysis'!$AH$7:$CM$123, MATCH($A18,'KPI Analysis'!$AH$7:$AH$123,FALSE), MATCH(V$8,'KPI Analysis'!$AH$7:$CM$7,FALSE) )="R", INDEX('KPI Analysis'!$AH$7:$CM$123, MATCH($A18,'KPI Analysis'!$AH$7:$AH$123,FALSE), MATCH(V$8,'KPI Analysis'!$AH$7:$CM$7,FALSE) )="G", INDEX('KPI Analysis'!$AH$7:$CM$123, MATCH($A18,'KPI Analysis'!$AH$7:$AH$123,FALSE), MATCH(V$8,'KPI Analysis'!$AH$7:$CM$7,FALSE) )="A"), INDEX('KPI Analysis'!$AH$7:$CM$123,MATCH($A18,'KPI Analysis'!$AH$7:$AH$123,FALSE),MATCH(V$8,'KPI Analysis'!$AH$7:$CM$7,FALSE)),"") -> A | W18: =INDEX('KPI Analysis'!$CO$7:$EU$123,MATCH($A18,'KPI Analysis'!$CO$7:$CO$123,FALSE),MATCH(V$8,'KPI Analysis'!$CO$7:$EU$7,FALSE)) -> 0.98412698 | X18: =IF( OR( INDEX('KPI Analysis'!$AH$7:$CM$123, MATCH($A18,'KPI Analysis'!$AH$7:$AH$123,FALSE), MATCH(X$8,'KPI Analysis'!$AH$7:$CM$7,FALSE) )="R", INDEX('KPI Analysis'!$AH$7:$CM$123, MATCH($A18,'KPI Analysis'!$AH$7:$AH$123,FALSE), MATCH(X$8,'KPI Analysis'!$AH$7:$CM$7,FALSE) )="G", INDEX('KPI Analysis'!$AH$7:$CM$123, MATCH($A18,'KPI Analysis'!$AH$7:$AH$123,FALSE), MATCH(X$8,'KPI Analysis'!$AH$7:$CM$7,FALSE) )="A"), INDEX('KPI Analysis'!$AH$7:$CM$123,MATCH($A18,'KPI Analysis'!$AH$7:$AH$123,FALSE),MATCH(X$8,'KPI Analysis'!$AH$7:$CM$7,FALSE)),"") -> A | Y18: =INDEX('KPI Analysis'!$CO$7:$EU$123,MATCH($A18,'KPI Analysis'!$CO$7:$CO$123,FALSE),MATCH(X$8,'KPI Analysis'!$CO$7:$EU$7,FALSE)) -> 0.97619048 | AC18: Co EU | AE18: =INDEX('KPI Analysis'!$CO$7:$EU$123,MATCH($A18,'KPI Analysis'!$CO$7:$CO$123,FALSE),MATCH(AE$8,'KPI Analysis'!$CO$7:$EU$7,FALSE)) -> 0.91269841 | AF18: =INDEX('KPI Analysis'!$CO$7:$EU$123,MATCH($A18,'KPI Analysis'!$CO$7:$CO$123,FALSE),MATCH(AF$8,'KPI Analysis'!$CO$7:$EU$7,FALSE)) -> 0.86507937 | AG18: =INDEX('KPI Analysis'!$CO$7:$EU$123,MATCH($A18,'KPI Analysis'!$CO$7:$CO$123,FALSE),MATCH(AG$8,'KPI Analysis'!$CO$7:$EU$7,FALSE)) -> 0.73809524 | AH18: =INDEX('KPI Analysis'!$CO$7:$EU$123,MATCH($A18,'KPI Analysis'!$CO$7:$CO$123,FALSE),MATCH(AH$8,'KPI Analysis'!$CO$7:$EU$7,FALSE)) -> 0.98412698 | AI18: =INDEX('KPI Analysis'!$CO$7:$EU$123,MATCH($A18,'KPI Analysis'!$CO$7:$CO$123,FALSE),MATCH(AI$8,'KPI Analysis'!$CO$7:$EU$7,FALSE)) -> 0.97619048
A19: =F19&"-"&C19 -> Estimating-KPI D1 | B19: =+'KPI Stats'!G18 -> Under | C19: =+'KPI Stats'!C18 -> KPI D1 | F19: =+'KPI Stats'!$B$16 -> Estimating | G19: =+'KPI Stats'!$B$16 -> Estimating | H19: W | I19: =+'KPI Stats'!$F$16 -> 42 | J19: =+'KPI Stats'!D18 -> Delivery | K19: =+'KPI Stats'!E18 -> Quotes issued on time | L19: =+'KPI Stats'!F18 -> Percentage | M19: =INDEX('KPI Analysis'!$CO$7:$EU$123,MATCH($A19,'KPI Analysis'!$CO$7:$CO$123,FALSE),MATCH(M$8,'KPI Analysis'!$CO$7:$EU$7,FALSE)) -> % of target | P19: =IF( OR( INDEX('KPI Analysis'!$AH$7:$CM$123, MATCH($A19,'KPI Analysis'!$AH$7:$AH$123,FALSE), MATCH(P$8,'KPI Analysis'!$AH$7:$CM$7,FALSE) )="R", INDEX('KPI Analysis'!$AH$7:$CM$123, MATCH($A19,'KPI Analysis'!$AH$7:$AH$123,FALSE), MATCH(P$8,'KPI Analysis'!$AH$7:$CM$7,FALSE) )="G", INDEX('KPI Analysis'!$AH$7:$CM$123, MATCH($A19,'KPI Analysis'!$AH$7:$AH$123,FALSE), MATCH(P$8,'KPI Analysis'!$AH$7:$CM$7,FALSE) )="A"), INDEX('KPI Analysis'!$AH$7:$CM$123,MATCH($A19,'KPI Analysis'!$AH$7:$AH$123,FALSE),MATCH(P$8,'KPI Analysis'!$AH$7:$CM$7,FALSE)),"") -> R | Q19: =INDEX('KPI Analysis'!$CO$7:$EU$123,MATCH($A19,'KPI Analysis'!$CO$7:$CO$123,FALSE),MATCH(P$8,'KPI Analysis'!$CO$7:$EU$7,FALSE)) -> 0.80818414 | R19: =IF( OR( INDEX('KPI Analysis'!$AH$7:$CM$123, MATCH($A19,'KPI Analysis'!$AH$7:$AH$123,FALSE), MATCH(R$8,'KPI Analysis'!$AH$7:$CM$7,FALSE) )="R", INDEX('KPI Analysis'!$AH$7:$CM$123, MATCH($A19,'KPI Analysis'!$AH$7:$AH$123,FALSE), MATCH(R$8,'KPI Analysis'!$AH$7:$CM$7,FALSE) )="G", INDEX('KPI Analysis'!$AH$7:$CM$123, MATCH($A19,'KPI Analysis'!$AH$7:$AH$123,FALSE), MATCH(R$8,'KPI Analysis'!$AH$7:$CM$7,FALSE) )="A"), INDEX('KPI Analysis'!$AH$7:$CM$123,MATCH($A19,'KPI Analysis'!$AH$7:$AH$123,FALSE),MATCH(R$8,'KPI Analysis'!$AH$7:$CM$7,FALSE)),"") -> R | S19: =INDEX('KPI Analysis'!$CO$7:$EU$123,MATCH($A19,'KPI Analysis'!$CO$7:$CO$123,FALSE),MATCH(R$8,'KPI Analysis'!$CO$7:$EU$7,FALSE)) -> 0.91743119 | T19: =IF( OR( INDEX('KPI Analysis'!$AH$7:$CM$123, MATCH($A19,'KPI Analysis'!$AH$7:$AH$123,FALSE), MATCH(T$8,'KPI Analysis'!$AH$7:$CM$7,FALSE) )="R", INDEX('KPI Analysis'!$AH$7:$CM$123, MATCH($A19,'KPI Analysis'!$AH$7:$AH$123,FALSE), MATCH(T$8,'KPI Analysis'!$AH$7:$CM$7,FALSE) )="G", INDEX('KPI Analysis'!$AH$7:$CM$123, MATCH($A19,'KPI Analysis'!$AH$7:$AH$123,FALSE), MATCH(T$8,'KPI Analysis'!$AH$7:$CM$7,FALSE) )="A"), INDEX('KPI Analysis'!$AH$7:$CM$123,MATCH($A19,'KPI Analysis'!$AH$7:$AH$123,FALSE),MATCH(T$8,'KPI Analysis'!$AH$7:$CM$7,FALSE)),"") -> A | U19: =INDEX('KPI Analysis'!$CO$7:$EU$123,MATCH($A19,'KPI Analysis'!$CO$7:$CO$123,FALSE),MATCH(T$8,'KPI Analysis'!$CO$7:$EU$7,FALSE)) -> 0.97406705 | V19: =IF( OR( INDEX('KPI Analysis'!$AH$7:$CM$123, MATCH($A19,'KPI Analysis'!$AH$7:$AH$123,FALSE), MATCH(V$8,'KPI Analysis'!$AH$7:$CM$7,FALSE) )="R", INDEX('KPI Analysis'!$AH$7:$CM$123, MATCH($A19,'KPI Analysis'!$AH$7:$AH$123,FALSE), MATCH(V$8,'KPI Analysis'!$AH$7:$CM$7,FALSE) )="G", INDEX('KPI Analysis'!$AH$7:$CM$123, MATCH($A19,'KPI Analysis'!$AH$7:$AH$123,FALSE), MATCH(V$8,'KPI Analysis'!$AH$7:$CM$7,FALSE) )="A"), INDEX('KPI Analysis'!$AH$7:$CM$123,MATCH($A19,'KPI Analysis'!$AH$7:$AH$123,FALSE),MATCH(V$8,'KPI Analysis'!$AH$7:$CM$7,FALSE)),"") -> R | W19: =INDEX('KPI Analysis'!$CO$7:$EU$123,MATCH($A19,'KPI Analysis'!$CO$7:$CO$123,FALSE),MATCH(V$8,'KPI Analysis'!$CO$7:$EU$7,FALSE)) -> 0.88235294 | X19: =IF( OR( INDEX('KPI Analysis'!$AH$7:$CM$123, MATCH($A19,'KPI Analysis'!$AH$7:$AH$123,FALSE), MATCH(X$8,'KPI Analysis'!$AH$7:$CM$7,FALSE) )="R", INDEX('KPI Analysis'!$AH$7:$CM$123, MATCH($A19,'KPI Analysis'!$AH$7:$AH$123,FALSE), MATCH(X$8,'KPI Analysis'!$AH$7:$CM$7,FALSE) )="G", INDEX('KPI Analysis'!$AH$7:$CM$123, MATCH($A19,'KPI Analysis'!$AH$7:$AH$123,FALSE), MATCH(X$8,'KPI Analysis'!$AH$7:$CM$7,FALSE) )="A"), INDEX('KPI Analysis'!$AH$7:$CM$123,MATCH($A19,'KPI Analysis'!$AH$7:$AH$123,FALSE),MATCH(X$8,'KPI Analysis'!$AH$7:$CM$7,FALSE)),"") -> A | Y19: =INDEX('KPI Analysis'!$CO$7:$EU$123,MATCH($A19,'KPI Analysis'!$CO$7:$CO$123,FALSE),MATCH(X$8,'KPI Analysis'!$CO$7:$EU$7,FALSE)) -> 0.96588235 | AC19: Co EU | AE19: =INDEX('KPI Analysis'!$CO$7:$EU$123,MATCH($A19,'KPI Analysis'!$CO$7:$CO$123,FALSE),MATCH(AE$8,'KPI Analysis'!$CO$7:$EU$7,FALSE)) -> 0.80818414 | AF19: =INDEX('KPI Analysis'!$CO$7:$EU$123,MATCH($A19,'KPI Analysis'!$CO$7:$CO$123,FALSE),MATCH(AF$8,'KPI Analysis'!$CO$7:$EU$7,FALSE)) -> 0.91743119 | AG19: =INDEX('KPI Analysis'!$CO$7:$EU$123,MATCH($A19,'KPI Analysis'!$CO$7:$CO$123,FALSE),MATCH(AG$8,'KPI Analysis'!$CO$7:$EU$7,FALSE)) -> 0.97406705 | AH19: =INDEX('KPI Analysis'!$CO$7:$EU$123,MATCH($A19,'KPI Analysis'!$CO$7:$CO$123,FALSE),MATCH(AH$8,'KPI Analysis'!$CO$7:$EU$7,FALSE)) -> 0.88235294 | AI19: =INDEX('KPI Analysis'!$CO$7:$EU$123,MATCH($A19,'KPI Analysis'!$CO$7:$CO$123,FALSE),MATCH(AI$8,'KPI Analysis'!$CO$7:$EU$7,FALSE)) -> 0.96588235
A20: =F20&"-"&C20 -> Estimating-KPI Q1 | B20: =+'KPI Stats'!G19 -> Over | C20: =+'KPI Stats'!C19 -> KPI Q1 | F20: =+'KPI Stats'!$B$16 -> Estimating | G20: =+'KPI Stats'!$B$16 -> Estimating | H20: W | I20: =+'KPI Stats'!$F$16 -> 42 | J20: =+'KPI Stats'!D19 -> Quality | K20: =+'KPI Stats'!E19 -> Hours on each Estimate | L20: =+'KPI Stats'!F19 -> Hours | M20: =INDEX('KPI Analysis'!$CO$7:$EU$123,MATCH($A20,'KPI Analysis'!$CO$7:$CO$123,FALSE),MATCH(M$8,'KPI Analysis'!$CO$7:$EU$7,FALSE)) -> % of target | P20: =IF( OR( INDEX('KPI Analysis'!$AH$7:$CM$123, MATCH($A20,'KPI Analysis'!$AH$7:$AH$123,FALSE), MATCH(P$8,'KPI Analysis'!$AH$7:$CM$7,FALSE) )="R", INDEX('KPI Analysis'!$AH$7:$CM$123, MATCH($A20,'KPI Analysis'!$AH$7:$AH$123,FALSE), MATCH(P$8,'KPI Analysis'!$AH$7:$CM$7,FALSE) )="G", INDEX('KPI Analysis'!$AH$7:$CM$123, MATCH($A20,'KPI Analysis'!$AH$7:$AH$123,FALSE), MATCH(P$8,'KPI Analysis'!$AH$7:$CM$7,FALSE) )="A"), INDEX('KPI Analysis'!$AH$7:$CM$123,MATCH($A20,'KPI Analysis'!$AH$7:$AH$123,FALSE),MATCH(P$8,'KPI Analysis'!$AH$7:$CM$7,FALSE)),"") -> R | Q20: =INDEX('KPI Analysis'!$CO$7:$EU$123,MATCH($A20,'KPI Analysis'!$CO$7:$CO$123,FALSE),MATCH(P$8,'KPI Analysis'!$CO$7:$EU$7,FALSE)) -> 0.525 | R20: =IF( OR( INDEX('KPI Analysis'!$AH$7:$CM$123, MATCH($A20,'KPI Analysis'!$AH$7:$AH$123,FALSE), MATCH(R$8,'KPI Analysis'!$AH$7:$CM$7,FALSE) )="R", INDEX('KPI Analysis'!$AH$7:$CM$123, MATCH($A20,'KPI Analysis'!$AH$7:$AH$123,FALSE), MATCH(R$8,'KPI Analysis'!$AH$7:$CM$7,FALSE) )="G", INDEX('KPI Analysis'!$AH$7:$CM$123, MATCH($A20,'KPI Analysis'!$AH$7:$AH$123,FALSE), MATCH(R$8,'KPI Analysis'!$AH$7:$CM$7,FALSE) )="A"), INDEX('KPI Analysis'!$AH$7:$CM$123,MATCH($A20,'KPI Analysis'!$AH$7:$AH$123,FALSE),MATCH(R$8,'KPI Analysis'!$AH$7:$CM$7,FALSE)),"") -> R | S20: =INDEX('KPI Analysis'!$CO$7:$EU$123,MATCH($A20,'KPI Analysis'!$CO$7:$CO$123,FALSE),MATCH(R$8,'KPI Analysis'!$CO$7:$EU$7,FALSE)) -> 0.94164194 | T20: =IF( OR( INDEX('KPI Analysis'!$AH$7:$CM$123, MATCH($A20,'KPI Analysis'!$AH$7:$AH$123,FALSE), MATCH(T$8,'KPI Analysis'!$AH$7:$CM$7,FALSE) )="R", INDEX('KPI Analysis'!$AH$7:$CM$123, MATCH($A20,'KPI Analysis'!$AH$7:$AH$123,FALSE), MATCH(T$8,'KPI Analysis'!$AH$7:$CM$7,FALSE) )="G", INDEX('KPI Analysis'!$AH$7:$CM$123, MATCH($A20,'KPI Analysis'!$AH$7:$AH$123,FALSE), MATCH(T$8,'KPI Analysis'!$AH$7:$CM$7,FALSE) )="A"), INDEX('KPI Analysis'!$AH$7:$CM$123,MATCH($A20,'KPI Analysis'!$AH$7:$AH$123,FALSE),MATCH(T$8,'KPI Analysis'!$AH$7:$CM$7,FALSE)),"") -> R | U20: =INDEX('KPI Analysis'!$CO$7:$EU$123,MATCH($A20,'KPI Analysis'!$CO$7:$CO$123,FALSE),MATCH(T$8,'KPI Analysis'!$CO$7:$EU$7,FALSE)) -> 0.82608696 | V20: =IF( OR( INDEX('KPI Analysis'!$AH$7:$CM$123, MATCH($A20,'KPI Analysis'!$AH$7:$AH$123,FALSE), MATCH(V$8,'KPI Analysis'!$AH$7:$CM$7,FALSE) )="R", INDEX('KPI Analysis'!$AH$7:$CM$123, MATCH($A20,'KPI Analysis'!$AH$7:$AH$123,FALSE), MATCH(V$8,'KPI Analysis'!$AH$7:$CM$7,FALSE) )="G", INDEX('KPI Analysis'!$AH$7:$CM$123, MATCH($A20,'KPI Analysis'!$AH$7:$AH$123,FALSE), MATCH(V$8,'KPI Analysis'!$AH$7:$CM$7,FALSE) )="A"), INDEX('KPI Analysis'!$AH$7:$CM$123,MATCH($A20,'KPI Analysis'!$AH$7:$AH$123,FALSE),MATCH(V$8,'KPI Analysis'!$AH$7:$CM$7,FALSE)),"") -> R | W20: =INDEX('KPI Analysis'!$CO$7:$EU$123,MATCH($A20,'KPI Analysis'!$CO$7:$CO$123,FALSE),MATCH(V$8,'KPI Analysis'!$CO$7:$EU$7,FALSE)) -> 0.58355847 | X20: =IF( OR( INDEX('KPI Analysis'!$AH$7:$CM$123, MATCH($A20,'KPI Analysis'!$AH$7:$AH$123,FALSE), MATCH(X$8,'KPI Analysis'!$AH$7:$CM$7,FALSE) )="R", INDEX('KPI Analysis'!$AH$7:$CM$123, MATCH($A20,'KPI Analysis'!$AH$7:$AH$123,FALSE), MATCH(X$8,'KPI Analysis'!$AH$7:$CM$7,FALSE) )="G", INDEX('KPI Analysis'!$AH$7:$CM$123, MATCH($A20,'KPI Analysis'!$AH$7:$AH$123,FALSE), MATCH(X$8,'KPI Analysis'!$AH$7:$CM$7,FALSE) )="A"), INDEX('KPI Analysis'!$AH$7:$CM$123,MATCH($A20,'KPI Analysis'!$AH$7:$AH$123,FALSE),MATCH(X$8,'KPI Analysis'!$AH$7:$CM$7,FALSE)),"") -> G | Y20: =INDEX('KPI Analysis'!$CO$7:$EU$123,MATCH($A20,'KPI Analysis'!$CO$7:$CO$123,FALSE),MATCH(X$8,'KPI Analysis'!$CO$7:$EU$7,FALSE)) -> 1.0687023 | AC20: Co EU | AE20: =INDEX('KPI Analysis'!$CO$7:$EU$123,MATCH($A20,'KPI Analysis'!$CO$7:$CO$123,FALSE),MATCH(AE$8,'KPI Analysis'!$CO$7:$EU$7,FALSE)) -> 0.525 | AF20: =INDEX('KPI Analysis'!$CO$7:$EU$123,MATCH($A20,'KPI Analysis'!$CO$7:$CO$123,FALSE),MATCH(AF$8,'KPI Analysis'!$CO$7:$EU$7,FALSE)) -> 0.94164194 | AG20: =INDEX('KPI Analysis'!$CO$7:$EU$123,MATCH($A20,'KPI Analysis'!$CO$7:$CO$123,FALSE),MATCH(AG$8,'KPI Analysis'!$CO$7:$EU$7,FALSE)) -> 0.82608696 | AH20: =INDEX('KPI Analysis'!$CO$7:$EU$123,MATCH($A20,'KPI Analysis'!$CO$7:$CO$123,FALSE),MATCH(AH$8,'KPI Analysis'!$CO$7:$EU$7,FALSE)) -> 0.58355847 | AI20: =INDEX('KPI Analysis'!$CO$7:$EU$123,MATCH($A20,'KPI Analysis'!$CO$7:$CO$123,FALSE),MATCH(AI$8,'KPI Analysis'!$CO$7:$EU$7,FALSE)) -> 1.0687023
A21: =F21&"-"&C21 -> Estimating-KPI C1 | B21: =+'KPI Stats'!G20 -> Under | C21: =+'KPI Stats'!C20 -> KPI C1 | F21: =+'KPI Stats'!$B$16 -> Estimating | G21: =+'KPI Stats'!$B$16 -> Estimating | H21: W | I21: =+'KPI Stats'!$F$16 -> 42 | J21: =+'KPI Stats'!D20 -> Cost | K21: =+'KPI Stats'!E20 -> Rate of Sales per sq Meter | L21: =+'KPI Stats'!F20 -> £ | M21: =INDEX('KPI Analysis'!$CO$7:$EU$123,MATCH($A21,'KPI Analysis'!$CO$7:$CO$123,FALSE),MATCH(M$8,'KPI Analysis'!$CO$7:$EU$7,FALSE)) -> % of target | P21: =IF( OR( INDEX('KPI Analysis'!$AH$7:$CM$123, MATCH($A21,'KPI Analysis'!$AH$7:$AH$123,FALSE), MATCH(P$8,'KPI Analysis'!$AH$7:$CM$7,FALSE) )="R", INDEX('KPI Analysis'!$AH$7:$CM$123, MATCH($A21,'KPI Analysis'!$AH$7:$AH$123,FALSE), MATCH(P$8,'KPI Analysis'!$AH$7:$CM$7,FALSE) )="G", INDEX('KPI Analysis'!$AH$7:$CM$123, MATCH($A21,'KPI Analysis'!$AH$7:$AH$123,FALSE), MATCH(P$8,'KPI Analysis'!$AH$7:$CM$7,FALSE) )="A"), INDEX('KPI Analysis'!$AH$7:$CM$123,MATCH($A21,'KPI Analysis'!$AH$7:$AH$123,FALSE),MATCH(P$8,'KPI Analysis'!$AH$7:$CM$7,FALSE)),"") -> G | Q21: =INDEX('KPI Analysis'!$CO$7:$EU$123,MATCH($A21,'KPI Analysis'!$CO$7:$CO$123,FALSE),MATCH(P$8,'KPI Analysis'!$CO$7:$EU$7,FALSE)) -> 1.0661967 | R21: =IF( OR( INDEX('KPI Analysis'!$AH$7:$CM$123, MATCH($A21,'KPI Analysis'!$AH$7:$AH$123,FALSE), MATCH(R$8,'KPI Analysis'!$AH$7:$CM$7,FALSE) )="R", INDEX('KPI Analysis'!$AH$7:$CM$123, MATCH($A21,'KPI Analysis'!$AH$7:$AH$123,FALSE), MATCH(R$8,'KPI Analysis'!$AH$7:$CM$7,FALSE) )="G", INDEX('KPI Analysis'!$AH$7:$CM$123, MATCH($A21,'KPI Analysis'!$AH$7:$AH$123,FALSE), MATCH(R$8,'KPI Analysis'!$AH$7:$CM$7,FALSE) )="A"), INDEX('KPI Analysis'!$AH$7:$CM$123,MATCH($A21,'KPI Analysis'!$AH$7:$AH$123,FALSE),MATCH(R$8,'KPI Analysis'!$AH$7:$CM$7,FALSE)),"") -> G | S21: =INDEX('KPI Analysis'!$CO$7:$EU$123,MATCH($A21,'KPI Analysis'!$CO$7:$CO$123,FALSE),MATCH(R$8,'KPI Analysis'!$CO$7:$EU$7,FALSE)) -> 1.4345885 | T21: =IF( OR( INDEX('KPI Analysis'!$AH$7:$CM$123, MATCH($A21,'KPI Analysis'!$AH$7:$AH$123,FALSE), MATCH(T$8,'KPI Analysis'!$AH$7:$CM$7,FALSE) )="R", INDEX('KPI Analysis'!$AH$7:$CM$123, MATCH($A21,'KPI Analysis'!$AH$7:$AH$123,FALSE), MATCH(T$8,'KPI Analysis'!$AH$7:$CM$7,FALSE) )="G", INDEX('KPI Analysis'!$AH$7:$CM$123, MATCH($A21,'KPI Analysis'!$AH$7:$AH$123,FALSE), MATCH(T$8,'KPI Analysis'!$AH$7:$CM$7,FALSE) )="A"), INDEX('KPI Analysis'!$AH$7:$CM$123,MATCH($A21,'KPI Analysis'!$AH$7:$AH$123,FALSE),MATCH(T$8,'KPI Analysis'!$AH$7:$CM$7,FALSE)),"") -> G | U21: =INDEX('KPI Analysis'!$CO$7:$EU$123,MATCH($A21,'KPI Analysis'!$CO$7:$CO$123,FALSE),MATCH(T$8,'KPI Analysis'!$CO$7:$EU$7,FALSE)) -> 1.0694805 | V21: =IF( OR( INDEX('KPI Analysis'!$AH$7:$CM$123, MATCH($A21,'KPI Analysis'!$AH$7:$AH$123,FALSE), MATCH(V$8,'KPI Analysis'!$AH$7:$CM$7,FALSE) )="R", INDEX('KPI Analysis'!$AH$7:$CM$123, MATCH($A21,'KPI Analysis'!$AH$7:$AH$123,FALSE), MATCH(V$8,'KPI Analysis'!$AH$7:$CM$7,FALSE) )="G", INDEX('KPI Analysis'!$AH$7:$CM$123, MATCH($A21,'KPI Analysis'!$AH$7:$AH$123,FALSE), MATCH(V$8,'KPI Analysis'!$AH$7:$CM$7,FALSE) )="A"), INDEX('KPI Analysis'!$AH$7:$CM$123,MATCH($A21,'KPI Analysis'!$AH$7:$AH$123,FALSE),MATCH(V$8,'KPI Analysis'!$AH$7:$CM$7,FALSE)),"") -> G | W21: =INDEX('KPI Analysis'!$CO$7:$EU$123,MATCH($A21,'KPI Analysis'!$CO$7:$CO$123,FALSE),MATCH(V$8,'KPI Analysis'!$CO$7:$EU$7,FALSE)) -> 1.0598483 | X21: =IF( OR( INDEX('KPI Analysis'!$AH$7:$CM$123, MATCH($A21,'KPI Analysis'!$AH$7:$AH$123,FALSE), MATCH(X$8,'KPI Analysis'!$AH$7:$CM$7,FALSE) )="R", INDEX('KPI Analysis'!$AH$7:$CM$123, MATCH($A21,'KPI Analysis'!$AH$7:$AH$123,FALSE), MATCH(X$8,'KPI Analysis'!$AH$7:$CM$7,FALSE) )="G", INDEX('KPI Analysis'!$AH$7:$CM$123, MATCH($A21,'KPI Analysis'!$AH$7:$AH$123,FALSE), MATCH(X$8,'KPI Analysis'!$AH$7:$CM$7,FALSE) )="A"), INDEX('KPI Analysis'!$AH$7:$CM$123,MATCH($A21,'KPI Analysis'!$AH$7:$AH$123,FALSE),MATCH(X$8,'KPI Analysis'!$AH$7:$CM$7,FALSE)),"") -> G | Y21: =INDEX('KPI Analysis'!$CO$7:$EU$123,MATCH($A21,'KPI Analysis'!$CO$7:$CO$123,FALSE),MATCH(X$8,'KPI Analysis'!$CO$7:$EU$7,FALSE)) -> 1.0754667 | Z21: Test added but Target to be clarified | AC21: Co EU | AE21: =INDEX('KPI Analysis'!$CO$7:$EU$123,MATCH($A21,'KPI Analysis'!$CO$7:$CO$123,FALSE),MATCH(AE$8,'KPI Analysis'!$CO$7:$EU$7,FALSE)) -> 1.0661967 | AF21: =INDEX('KPI Analysis'!$CO$7:$EU$123,MATCH($A21,'KPI Analysis'!$CO$7:$CO$123,FALSE),MATCH(AF$8,'KPI Analysis'!$CO$7:$EU$7,FALSE)) -> 1.4345885 | AG21: =INDEX('KPI Analysis'!$CO$7:$EU$123,MATCH($A21,'KPI Analysis'!$CO$7:$CO$123,FALSE),MATCH(AG$8,'KPI Analysis'!$CO$7:$EU$7,FALSE)) -> 1.0694805 | AH21: =INDEX('KPI Analysis'!$CO$7:$EU$123,MATCH($A21,'KPI Analysis'!$CO$7:$CO$123,FALSE),MATCH(AH$8,'KPI Analysis'!$CO$7:$EU$7,FALSE)) -> 1.0598483 | AI21: =INDEX('KPI Analysis'!$CO$7:$EU$123,MATCH($A21,'KPI Analysis'!$CO$7:$CO$123,FALSE),MATCH(AI$8,'KPI Analysis'!$CO$7:$EU$7,FALSE)) -> 1.0754667
K22: Target avg of the actual results Q1
A24: =F24&"-"&C24 -> SOP-KPI P1 | B24: =+'KPI Stats'!G23 -> Under | C24: =+'KPI Stats'!C23 -> KPI P1 | F24: =+'KPI Stats'!B22 -> SOP | G24: =+'KPI Stats'!C22 -> Sam Westwood | H24: W | I24: =+'KPI Stats'!F22 -> 42 | J24: =+'KPI Stats'!D23 -> Productivity | K24: =+'KPI Stats'!E23 -> Order Lines Released | L24: =+'KPI Stats'!F23 -> Count | M24: =INDEX('KPI Analysis'!$CO$7:$EU$123,MATCH($A24,'KPI Analysis'!$CO$7:$CO$123,FALSE),MATCH(M$8,'KPI Analysis'!$CO$7:$EU$7,FALSE)) -> % of target | P24: =IF( OR( INDEX('KPI Analysis'!$AH$7:$CM$123, MATCH($A24,'KPI Analysis'!$AH$7:$AH$123,FALSE), MATCH(P$8,'KPI Analysis'!$AH$7:$CM$7,FALSE) )="R", INDEX('KPI Analysis'!$AH$7:$CM$123, MATCH($A24,'KPI Analysis'!$AH$7:$AH$123,FALSE), MATCH(P$8,'KPI Analysis'!$AH$7:$CM$7,FALSE) )="G", INDEX('KPI Analysis'!$AH$7:$CM$123, MATCH($A24,'KPI Analysis'!$AH$7:$AH$123,FALSE), MATCH(P$8,'KPI Analysis'!$AH$7:$CM$7,FALSE) )="A"), INDEX('KPI Analysis'!$AH$7:$CM$123,MATCH($A24,'KPI Analysis'!$AH$7:$AH$123,FALSE),MATCH(P$8,'KPI Analysis'!$AH$7:$CM$7,FALSE)),"") -> G | Q24: =INDEX('KPI Analysis'!$CO$7:$EU$123,MATCH($A24,'KPI Analysis'!$CO$7:$CO$123,FALSE),MATCH(P$8,'KPI Analysis'!$CO$7:$EU$7,FALSE)) -> 1.2124864 | R24: =IF( OR( INDEX('KPI Analysis'!$AH$7:$CM$123, MATCH($A24,'KPI Analysis'!$AH$7:$AH$123,FALSE), MATCH(R$8,'KPI Analysis'!$AH$7:$CM$7,FALSE) )="R", INDEX('KPI Analysis'!$AH$7:$CM$123, MATCH($A24,'KPI Analysis'!$AH$7:$AH$123,FALSE), MATCH(R$8,'KPI Analysis'!$AH$7:$CM$7,FALSE) )="G", INDEX('KPI Analysis'!$AH$7:$CM$123, MATCH($A24,'KPI Analysis'!$AH$7:$AH$123,FALSE), MATCH(R$8,'KPI Analysis'!$AH$7:$CM$7,FALSE) )="A"), INDEX('KPI Analysis'!$AH$7:$CM$123,MATCH($A24,'KPI Analysis'!$AH$7:$AH$123,FALSE),MATCH(R$8,'KPI Analysis'!$AH$7:$CM$7,FALSE)),"") -> G | S24: =INDEX('KPI Analysis'!$CO$7:$EU$123,MATCH($A24,'KPI Analysis'!$CO$7:$CO$123,FALSE),MATCH(R$8,'KPI Analysis'!$CO$7:$EU$7,FALSE)) -> 1.3772879 | T24: =IF( OR( INDEX('KPI Analysis'!$AH$7:$CM$123, MATCH($A24,'KPI Analysis'!$AH$7:$AH$123,FALSE), MATCH(T$8,'KPI Analysis'!$AH$7:$CM$7,FALSE) )="R", INDEX('KPI Analysis'!$AH$7:$CM$123, MATCH($A24,'KPI Analysis'!$AH$7:$AH$123,FALSE), MATCH(T$8,'KPI Analysis'!$AH$7:$CM$7,FALSE) )="G", INDEX('KPI Analysis'!$AH$7:$CM$123, MATCH($A24,'KPI Analysis'!$AH$7:$AH$123,FALSE), MATCH(T$8,'KPI Analysis'!$AH$7:$CM$7,FALSE) )="A"), INDEX('KPI Analysis'!$AH$7:$CM$123,MATCH($A24,'KPI Analysis'!$AH$7:$AH$123,FALSE),MATCH(T$8,'KPI Analysis'!$AH$7:$CM$7,FALSE)),"") -> A | U24: =INDEX('KPI Analysis'!$CO$7:$EU$123,MATCH($A24,'KPI Analysis'!$CO$7:$CO$123,FALSE),MATCH(T$8,'KPI Analysis'!$CO$7:$EU$7,FALSE)) -> 0.98372381 | V24: =IF( OR( INDEX('KPI Analysis'!$AH$7:$CM$123, MATCH($A24,'KPI Analysis'!$AH$7:$AH$123,FALSE), MATCH(V$8,'KPI Analysis'!$AH$7:$CM$7,FALSE) )="R", INDEX('KPI Analysis'!$AH$7:$CM$123, MATCH($A24,'KPI Analysis'!$AH$7:$AH$123,FALSE), MATCH(V$8,'KPI Analysis'!$AH$7:$CM$7,FALSE) )="G", INDEX('KPI Analysis'!$AH$7:$CM$123, MATCH($A24,'KPI Analysis'!$AH$7:$AH$123,FALSE), MATCH(V$8,'KPI Analysis'!$AH$7:$CM$7,FALSE) )="A"), INDEX('KPI Analysis'!$AH$7:$CM$123,MATCH($A24,'KPI Analysis'!$AH$7:$AH$123,FALSE),MATCH(V$8,'KPI Analysis'!$AH$7:$CM$7,FALSE)),"") -> R | W24: =INDEX('KPI Analysis'!$CO$7:$EU$123,MATCH($A24,'KPI Analysis'!$CO$7:$CO$123,FALSE),MATCH(V$8,'KPI Analysis'!$CO$7:$EU$7,FALSE)) -> 0.90159064 | X24: =IF( OR( INDEX('KPI Analysis'!$AH$7:$CM$123, MATCH($A24,'KPI Analysis'!$AH$7:$AH$123,FALSE), MATCH(X$8,'KPI Analysis'!$AH$7:$CM$7,FALSE) )="R", INDEX('KPI Analysis'!$AH$7:$CM$123, MATCH($A24,'KPI Analysis'!$AH$7:$AH$123,FALSE), MATCH(X$8,'KPI Analysis'!$AH$7:$CM$7,FALSE) )="G", INDEX('KPI Analysis'!$AH$7:$CM$123, MATCH($A24,'KPI Analysis'!$AH$7:$AH$123,FALSE), MATCH(X$8,'KPI Analysis'!$AH$7:$CM$7,FALSE) )="A"), INDEX('KPI Analysis'!$AH$7:$CM$123,MATCH($A24,'KPI Analysis'!$AH$7:$AH$123,FALSE),MATCH(X$8,'KPI Analysis'!$AH$7:$CM$7,FALSE)),"") -> R | Y24: =INDEX('KPI Analysis'!$CO$7:$EU$123,MATCH($A24,'KPI Analysis'!$CO$7:$CO$123,FALSE),MATCH(X$8,'KPI Analysis'!$CO$7:$EU$7,FALSE)) -> 0.82391137 | AC24: Co EU | AE24: =INDEX('KPI Analysis'!$CO$7:$EU$123,MATCH($A24,'KPI Analysis'!$CO$7:$CO$123,FALSE),MATCH(AE$8,'KPI Analysis'!$CO$7:$EU$7,FALSE)) -> 1.2124864 | AF24: =INDEX('KPI Analysis'!$CO$7:$EU$123,MATCH($A24,'KPI Analysis'!$CO$7:$CO$123,FALSE),MATCH(AF$8,'KPI Analysis'!$CO$7:$EU$7,FALSE)) -> 1.3772879 | AG24: =INDEX('KPI Analysis'!$CO$7:$EU$123,MATCH($A24,'KPI Analysis'!$CO$7:$CO$123,FALSE),MATCH(AG$8,'KPI Analysis'!$CO$7:$EU$7,FALSE)) -> 0.98372381 | AH24: =INDEX('KPI Analysis'!$CO$7:$EU$123,MATCH($A24,'KPI Analysis'!$CO$7:$CO$123,FALSE),MATCH(AH$8,'KPI Analysis'!$CO$7:$EU$7,FALSE)) -> 0.90159064 | AI24: =INDEX('KPI Analysis'!$CO$7:$EU$123,MATCH($A24,'KPI Analysis'!$CO$7:$CO$123,FALSE),MATCH(AI$8,'KPI Analysis'!$CO$7:$EU$7,FALSE)) -> 0.82391137
A25: =F25&"-"&C25 -> SOP-KPI D1 | B25: =+'KPI Stats'!G24 -> Under | C25: =+'KPI Stats'!C24 -> KPI D1 | F25: =+'KPI Stats'!B22 -> SOP | G25: =+'KPI Stats'!C22 -> Sam Westwood | H25: W | I25: =+'KPI Stats'!F22 -> 42 | J25: =+'KPI Stats'!D24 -> Delivery | K25: =+'KPI Stats'!E24 -> Order Cleansing On Target / In Full (OTIF) days to complete | L25: =+'KPI Stats'!F24 -> Percentage | M25: Act Result | P25: =IF( OR( INDEX('KPI Analysis'!$AH$7:$CM$123, MATCH($A25,'KPI Analysis'!$AH$7:$AH$123,FALSE), MATCH(P$8,'KPI Analysis'!$AH$7:$CM$7,FALSE) )="R", INDEX('KPI Analysis'!$AH$7:$CM$123, MATCH($A25,'KPI Analysis'!$AH$7:$AH$123,FALSE), MATCH(P$8,'KPI Analysis'!$AH$7:$CM$7,FALSE) )="G", INDEX('KPI Analysis'!$AH$7:$CM$123, MATCH($A25,'KPI Analysis'!$AH$7:$AH$123,FALSE), MATCH(P$8,'KPI Analysis'!$AH$7:$CM$7,FALSE) )="A"), INDEX('KPI Analysis'!$AH$7:$CM$123,MATCH($A25,'KPI Analysis'!$AH$7:$AH$123,FALSE),MATCH(P$8,'KPI Analysis'!$AH$7:$CM$7,FALSE)),"") -> R | Q25: =INDEX('KPI Analysis'!$EW$7:$HC$123,MATCH($A25,'KPI Analysis'!$EW$7:$EW$123,FALSE),MATCH(P$8,'KPI Analysis'!$EW$7:$HC$7,FALSE)) -> 0.38709677 | R25: =IF( OR( INDEX('KPI Analysis'!$AH$7:$CM$123, MATCH($A25,'KPI Analysis'!$AH$7:$AH$123,FALSE), MATCH(R$8,'KPI Analysis'!$AH$7:$CM$7,FALSE) )="R", INDEX('KPI Analysis'!$AH$7:$CM$123, MATCH($A25,'KPI Analysis'!$AH$7:$AH$123,FALSE), MATCH(R$8,'KPI Analysis'!$AH$7:$CM$7,FALSE) )="G", INDEX('KPI Analysis'!$AH$7:$CM$123, MATCH($A25,'KPI Analysis'!$AH$7:$AH$123,FALSE), MATCH(R$8,'KPI Analysis'!$AH$7:$CM$7,FALSE) )="A"), INDEX('KPI Analysis'!$AH$7:$CM$123,MATCH($A25,'KPI Analysis'!$AH$7:$AH$123,FALSE),MATCH(R$8,'KPI Analysis'!$AH$7:$CM$7,FALSE)),"") -> R | S25: =INDEX('KPI Analysis'!$EW$7:$HC$123,MATCH($A25,'KPI Analysis'!$EW$7:$EW$123,FALSE),MATCH(R$8,'KPI Analysis'!$EW$7:$HC$7,FALSE)) -> 0.57692308 | T25: =IF( OR( INDEX('KPI Analysis'!$AH$7:$CM$123, MATCH($A25,'KPI Analysis'!$AH$7:$AH$123,FALSE), MATCH(T$8,'KPI Analysis'!$AH$7:$CM$7,FALSE) )="R", INDEX('KPI Analysis'!$AH$7:$CM$123, MATCH($A25,'KPI Analysis'!$AH$7:$AH$123,FALSE), MATCH(T$8,'KPI Analysis'!$AH$7:$CM$7,FALSE) )="G", INDEX('KPI Analysis'!$AH$7:$CM$123, MATCH($A25,'KPI Analysis'!$AH$7:$AH$123,FALSE), MATCH(T$8,'KPI Analysis'!$AH$7:$CM$7,FALSE) )="A"), INDEX('KPI Analysis'!$AH$7:$CM$123,MATCH($A25,'KPI Analysis'!$AH$7:$AH$123,FALSE),MATCH(T$8,'KPI Analysis'!$AH$7:$CM$7,FALSE)),"") -> G | U25: =INDEX('KPI Analysis'!$EW$7:$HC$123,MATCH($A25,'KPI Analysis'!$EW$7:$EW$123,FALSE),MATCH(T$8,'KPI Analysis'!$EW$7:$HC$7,FALSE)) -> 1 | V25: =IF( OR( INDEX('KPI Analysis'!$AH$7:$CM$123, MATCH($A25,'KPI Analysis'!$AH$7:$AH$123,FALSE), MATCH(V$8,'KPI Analysis'!$AH$7:$CM$7,FALSE) )="R", INDEX('KPI Analysis'!$AH$7:$CM$123, MATCH($A25,'KPI Analysis'!$AH$7:$AH$123,FALSE), MATCH(V$8,'KPI Analysis'!$AH$7:$CM$7,FALSE) )="G", INDEX('KPI Analysis'!$AH$7:$CM$123, MATCH($A25,'KPI Analysis'!$AH$7:$AH$123,FALSE), MATCH(V$8,'KPI Analysis'!$AH$7:$CM$7,FALSE) )="A"), INDEX('KPI Analysis'!$AH$7:$CM$123,MATCH($A25,'KPI Analysis'!$AH$7:$AH$123,FALSE),MATCH(V$8,'KPI Analysis'!$AH$7:$CM$7,FALSE)),"") -> G | W25: =INDEX('KPI Analysis'!$EW$7:$HC$123,MATCH($A25,'KPI Analysis'!$EW$7:$EW$123,FALSE),MATCH(V$8,'KPI Analysis'!$EW$7:$HC$7,FALSE)) -> 1 | X25: =IF( OR( INDEX('KPI Analysis'!$AH$7:$CM$123, MATCH($A25,'KPI Analysis'!$AH$7:$AH$123,FALSE), MATCH(X$8,'KPI Analysis'!$AH$7:$CM$7,FALSE) )="R", INDEX('KPI Analysis'!$AH$7:$CM$123, MATCH($A25,'KPI Analysis'!$AH$7:$AH$123,FALSE), MATCH(X$8,'KPI Analysis'!$AH$7:$CM$7,FALSE) )="G", INDEX('KPI Analysis'!$AH$7:$CM$123, MATCH($A25,'KPI Analysis'!$AH$7:$AH$123,FALSE), MATCH(X$8,'KPI Analysis'!$AH$7:$CM$7,FALSE) )="A"), INDEX('KPI Analysis'!$AH$7:$CM$123,MATCH($A25,'KPI Analysis'!$AH$7:$AH$123,FALSE),MATCH(X$8,'KPI Analysis'!$AH$7:$CM$7,FALSE)),"") -> G | Y25: =IF(INDEX('KPI Analysis'!$CO$7:$EU$123,MATCH($A25,'KPI Analysis'!$CO$7:$CO$123,FALSE),MATCH(X$8,'KPI Analysis'!$CO$7:$EU$7,FALSE))="OD","OD",INDEX('KPI Analysis'!$EW$7:$HC$123,MATCH($A25,'KPI Analysis'!$EW$7:$EW$123,FALSE),MATCH(X$8,'KPI Analysis'!$EW$7:$HC$7,FALSE))) -> 1 | Z25: Target 1 day | AC25: EW HC | AE25: =INDEX('KPI Analysis'!$CO$7:$EU$123,MATCH($A25,'KPI Analysis'!$CO$7:$CO$123,FALSE),MATCH(AE$8,'KPI Analysis'!$CO$7:$EU$7,FALSE)) -> 0.40747029 | AF25: =INDEX('KPI Analysis'!$CO$7:$EU$123,MATCH($A25,'KPI Analysis'!$CO$7:$CO$123,FALSE),MATCH(AF$8,'KPI Analysis'!$CO$7:$EU$7,FALSE)) -> 0.60728745 | AG25: =INDEX('KPI Analysis'!$CO$7:$EU$123,MATCH($A25,'KPI Analysis'!$CO$7:$CO$123,FALSE),MATCH(AG$8,'KPI Analysis'!$CO$7:$EU$7,FALSE)) -> 1.0526316 | AH25: =INDEX('KPI Analysis'!$CO$7:$EU$123,MATCH($A25,'KPI Analysis'!$CO$7:$CO$123,FALSE),MATCH(AH$8,'KPI Analysis'!$CO$7:$EU$7,FALSE)) -> 1.0526316 | AI25: =INDEX('KPI Analysis'!$CO$7:$EU$123,MATCH($A25,'KPI Analysis'!$CO$7:$CO$123,FALSE),MATCH(AI$8,'KPI Analysis'!$CO$7:$EU$7,FALSE)) -> 1.0526316
